Workbook

Sheet Europe
B1: OECD | E1: PMI US | G1: CFNAI Index | I1: Bloomberg Euro-Zone Financial Conditions Index | L1: BNP Positioning | O1: Citi Surprise Eco | U1: Seuil (incrément) | W1: 0.3 | Y1: Centile | Z1: 0.4 | AA1: =PERCENTILE(AD:AD,0.5) -> 0.18950033 | AB1: Seuil (MD) | AC1: 0.1 | AG1: =TODAY() -> 46296 | AH1: =TEXT(AH3,"mmm-aaaa") -> avr-2026 | AI1: =TEXT(AI3,"mmm-aaaa") -> mai-2026 | AJ1: =TEXT(AJ3,"mmm-aaaa") -> juin-2026 | AK1: =TEXT(AK3,"mmm-aaaa") -> juil-2026 | AL1: =TEXT(AL3,"mmm-aaaa") -> août-2026 | AM1: =TEXT(AM3,"mmm-aaaa") -> sept-2026 | AN1: =TEXT(AN3,"mmm-aaaa") -> oct-2026 | BP1: Smoothing parameter | BQ1: 0.8 | BR1: Volatilité
B2: OE4EKLAC Index | E2: NAPMPMI Index | G2: CFNAI Index | I2: BFCIEU Index | L2: BNPEPEU Index | O2: CESIEUR Index | AG2: Cycle macro | AH2: =VLOOKUP(AH$3,$A:$AB,28,1) -> SD | AI2: =VLOOKUP(AI$3,$A:$AB,28,1) -> SD | AJ2: =VLOOKUP(AJ$3,$A:$AB,28,1) -> C | AK2: =VLOOKUP(AK$3,$A:$AB,28,1) -> C | AL2: =VLOOKUP(AL$3,$A:$AB,28,1) -> R | AM2: =VLOOKUP(AM$3,$A:$AB,28,1) -> R | AN2: =VLOOKUP(AN$3,$A:$AB,28,1) -> E | BP2: OECD | BQ2: 0.95 | BR2: =AVEDEV(D23:D305) -> 1.6289664
A3: Date | B3: OECD Europe CLI | C3: OECD Europe CLI EWMA -100 | D3: OECD norm | E3: PMI US | F3: PMI US EWMA -50 | G3: CFNAI Index (R2) | H3: CFNAI Index Cap EWMA | I3: BFCIEU Index | J3: BFCIEU Index EWMA | K3: Bloomberg Euro-Zone | L3: BNPEPEU Index | N3: BNP Positioning | O3: CESIEUR Index | Q3: Citi Surprise Eco | U3: Signal multi quantitatif | AH3: =EDATE($AG$1,-6) -> 46113 | AI3: =EDATE($AG$1,-5) -> 46143 | AJ3: =EDATE($AG$1,-4) -> 46174 | AK3: =EDATE($AG$1,-3) -> 46204 | AL3: =EDATE($AG$1,-2) -> 46235 | AM3: =EDATE($AG$1,-1) -> 46266 | AN3: =EDATE($AG$1,0) -> 46296 | BG3: SXXP Index | BL3: Strat | BM3: Bench | BP3: BFCIEU Index | BQ3: 0.95 | BR3: =AVEDEV(K23:K305) -> 1.6287358
A4: 36981 | B4: =_xll.BDH(B$2,"PX_LAST",$A4,$A4,"Days=A","Fill=P") -> 100.7163 | C4: =B4 -> 100.7163 | E4: 43.1 | F4: =E4-50 -> -6.9 | G4: -0.68 | H4: =G4 -> -0.68 | I4: {=_xll.BDH(I$2,"PX_LAST",$A4,$A4,"Days=A","Fill=P")} -> -0.566 | J4: =I4 -> -0.566 | T4: ANCIEN cycle | U4: Moyenne | V4: Cycle | Z4: Cycle avec Seuil | AB4: New Cycle | AC4: Signal Quanti/Quali | AK4: E | AL4: SD | AM4: C | AN4: R | AT4: Check avec et sans seuil | BG4: {=_xll.BDH($BG$3,"PX_LAST",$A4,$A4,"Days=A","Fill=P")} -> 321.7 | BP4: BNP Positioning | BQ4: 0.95 | BR4: =AVEDEV(N202:N305) -> 1.4349164
A5: 37011 | B5: =_xll.BDH(B$2,"PX_LAST",$A5,$A5,"Days=A","Fill=P") -> 100.4533 | C5: =$BQ$2*C4 + (1-$BQ$2)*B5 -> 100.70315 | E5: 42.7 | F5: =$BQ$1*F4+(1-$BQ$1)*(E5-50) -> -6.98 | G5: -0.85 | H5: =$BQ$1*H4+(1-$BQ$1) * MAX(AVERAGE($G$4:$G$256)-3*STDEVA($G$4:$G$256),MIN(G5,AVERAGE($G$4:$G$256)+3*STDEVA($G$4:$G$256))) -> -0.714 | I5: {=_xll.BDH(I$2,"PX_LAST",$A5,$A5,"Days=A","Fill=P")} -> -0.617 | J5: =$BQ$3*J4+(1-$BQ$3)*I5 -> -0.56855 | AC5: Quanti | AK5: Expansion | AL5: Slowdown | AM5: Contraction | AN5: Recovery | AO5: E | AP5: SD | AQ5: C | AR5: R | BG5: {=_xll.BDH($BG$3,"PX_LAST",$A5,$A5,"Days=A","Fill=P")} -> 342.02 | BH5: =BG5/BG4-1 -> 0.063164439 | BP5: Citi Surprise Eco | BQ5: 0.9 | BR5: =AVEDEV(Q46:Q305) -> 1.4821033
A6: 37042 | B6: =_xll.BDH(B$2,"PX_LAST",$A6,$A6,"Days=A","Fill=P") -> 100.1963 | C6: =$BQ$2*C5 + (1-$BQ$2)*B6 -> 100.67781 | E6: 41.3 | F6: =$BQ$1*F5+(1-$BQ$1)*(E6-50) -> -7.324 | G6: -0.46 | H6: =$BQ$1*H5+(1-$BQ$1) * MAX(AVERAGE($G$4:$G$256)-3*STDEVA($G$4:$G$256),MIN(G6,AVERAGE($G$4:$G$256)+3*STDEVA($G$4:$G$256))) -> -0.6632 | I6: {=_xll.BDH(I$2,"PX_LAST",$A6,$A6,"Days=A","Fill=P")} -> 0.127 | J6: =$BQ$3*J5+(1-$BQ$3)*I6 -> -0.5337725 | AC6: Quanti | AI6: 0 | AK6: =IF(OR($AB6=AK$4,$AB7=AK$4),$U6,NA()) -> #N/A | AL6: =IF(OR($AB6=AL$4,$AB7=AL$4),$U6,NA()) -> #N/A | AM6: =IF(OR($AB6=AM$4,$AB7=AM$4),$U6,NA()) -> #N/A | AN6: =IF(OR($AB6=AN$4,$AB7=AN$4),$U6,NA()) -> #N/A | AO6: =IF(OR($AB6=AO$5,$AB7=AO$5),$BG6,NA()) -> #N/A | AP6: =IF(OR($AB6=AP$5,$AB7=AP$5),$BG6,NA()) -> #N/A | AQ6: =IF(OR($AB6=AQ$5,$AB7=AQ$5),$BG6,NA()) -> #N/A | AR6: =IF(OR($AB6=AN$5,$AB7=AN$5),$BG6,NA()) -> #N/A | AU6: sans seuil | AV6: avec seuil | BG6: {=_xll.BDH($BG$3,"PX_LAST",$A6,$A6,"Days=A","Fill=P")} -> 341.97 | BH6: =BG6/BG5-1 -> -0.00014619028
A7: 37072 | B7: =_xll.BDH(B$2,"PX_LAST",$A7,$A7,"Days=A","Fill=P") -> 99.9304 | C7: =$BQ$2*C6 + (1-$BQ$2)*B7 -> 100.64044 | E7: 43.2 | F7: =$BQ$1*F6+(1-$BQ$1)*(E7-50) -> -7.2192 | G7: -0.9 | H7: =$BQ$1*H6+(1-$BQ$1) * MAX(AVERAGE($G$4:$G$256)-3*STDEVA($G$4:$G$256),MIN(G7,AVERAGE($G$4:$G$256)+3*STDEVA($G$4:$G$256))) -> -0.71056 | I7: {=_xll.BDH(I$2,"PX_LAST",$A7,$A7,"Days=A","Fill=P")} -> 0.021 | J7: =$BQ$3*J6+(1-$BQ$3)*I7 -> -0.50603387 | AC7: Quanti | AI7: 0 | AK7: =IF(OR($AB7=AK$4,$AB8=AK$4),$U7,NA()) -> #N/A | AL7: =IF(OR($AB7=AL$4,$AB8=AL$4),$U7,NA()) -> #N/A | AM7: =IF(OR($AB7=AM$4,$AB8=AM$4),$U7,NA()) -> #N/A | AN7: =IF(OR($AB7=AN$4,$AB8=AN$4),$U7,NA()) -> #N/A | AO7: =IF(OR($AB7=AO$5,$AB8=AO$5),$BG7,NA()) -> #N/A | AP7: =IF(OR($AB7=AP$5,$AB8=AP$5),$BG7,NA()) -> #N/A | AQ7: =IF(OR($AB7=AQ$5,$AB8=AQ$5),$BG7,NA()) -> #N/A | AR7: =IF(OR($AB7=AN$5,$AB8=AN$5),$BG7,NA()) -> #N/A | AT7: =A7 -> 37072 | AU7: =IF($V7="E",4,IF($V7="R",2,IF($V7="SD",3,1))) -> 1 | AV7: =IF($Z7="E",4,IF($Z7="R",2,IF($Z7="SD",3,1))) -> 1 | BG7: {=_xll.BDH($BG$3,"PX_LAST",$A7,$A7,"Days=A","Fill=P")} -> 329.35 | BH7: =BG7/BG6-1 -> -0.036903822
A8: 37103 | B8: =_xll.BDH(B$2,"PX_LAST",$A8,$A8,"Days=A","Fill=P") -> 99.6546 | C8: =$BQ$2*C7 + (1-$BQ$2)*B8 -> 100.59115 | E8: 43.5 | F8: =$BQ$1*F7+(1-$BQ$1)*(E8-50) -> -7.07536 | G8: -0.5 | H8: =$BQ$1*H7+(1-$BQ$1) * MAX(AVERAGE($G$4:$G$256)-3*STDEVA($G$4:$G$256),MIN(G8,AVERAGE($G$4:$G$256)+3*STDEVA($G$4:$G$256))) -> -0.668448 | I8: {=_xll.BDH(I$2,"PX_LAST",$A8,$A8,"Days=A","Fill=P")} -> -0.529 | J8: =$BQ$3*J7+(1-$BQ$3)*I8 -> -0.50718218 | AC8: Quanti | AI8: 0 | AK8: =IF(OR($AB8=AK$4,$AB9=AK$4),$U8,NA()) -> #N/A | AL8: =IF(OR($AB8=AL$4,$AB9=AL$4),$U8,NA()) -> #N/A | AM8: =IF(OR($AB8=AM$4,$AB9=AM$4),$U8,NA()) -> #N/A | AN8: =IF(OR($AB8=AN$4,$AB9=AN$4),$U8,NA()) -> #N/A | AO8: =IF(OR($AB8=AO$5,$AB9=AO$5),$BG8,NA()) -> #N/A | AP8: =IF(OR($AB8=AP$5,$AB9=AP$5),$BG8,NA()) -> #N/A | AQ8: =IF(OR($AB8=AQ$5,$AB9=AQ$5),$BG8,NA()) -> #N/A | AR8: =IF(OR($AB8=AN$5,$AB9=AN$5),$BG8,NA()) -> #N/A | AT8: =A8 -> 37103 | AU8: =IF($V8="E",4,IF($V8="R",2,IF($V8="SD",3,1))) -> 1 | AV8: =IF($Z8="E",4,IF($Z8="R",2,IF($Z8="SD",3,1))) -> 1 | BG8: {=_xll.BDH($BG$3,"PX_LAST",$A8,$A8,"Days=A","Fill=P")} -> 316.95 | BH8: =BG8/BG7-1 -> -0.037649917
A9: 37134 | B9: =_xll.BDH(B$2,"PX_LAST",$A9,$A9,"Days=A","Fill=P") -> 99.3836 | C9: =$BQ$2*C8 + (1-$BQ$2)*B9 -> 100.53077 | E9: 46.3 | F9: =$BQ$1*F8+(1-$BQ$1)*(E9-50) -> -6.400288 | G9: -0.44 | H9: =$BQ$1*H8+(1-$BQ$1) * MAX(AVERAGE($G$4:$G$256)-3*STDEVA($G$4:$G$256),MIN(G9,AVERAGE($G$4:$G$256)+3*STDEVA($G$4:$G$256))) -> -0.6227584 | I9: {=_xll.BDH(I$2,"PX_LAST",$A9,$A9,"Days=A","Fill=P")} -> -0.957 | J9: =$BQ$3*J8+(1-$BQ$3)*I9 -> -0.52967307 | AC9: Quanti | AI9: 0 | AK9: =IF(OR($AB9=AK$4,$AB10=AK$4),$U9,NA()) -> #N/A | AL9: =IF(OR($AB9=AL$4,$AB10=AL$4),$U9,NA()) -> #N/A | AM9: =IF(OR($AB9=AM$4,$AB10=AM$4),$U9,NA()) -> #N/A | AN9: =IF(OR($AB9=AN$4,$AB10=AN$4),$U9,NA()) -> #N/A | AO9: =IF(OR($AB9=AO$5,$AB10=AO$5),$BG9,NA()) -> #N/A | AP9: =IF(OR($AB9=AP$5,$AB10=AP$5),$BG9,NA()) -> #N/A | AQ9: =IF(OR($AB9=AQ$5,$AB10=AQ$5),$BG9,NA()) -> #N/A | AR9: =IF(OR($AB9=AN$5,$AB10=AN$5),$BG9,NA()) -> #N/A | AT9: =A9 -> 37134 | AU9: =IF($V9="E",4,IF($V9="R",2,IF($V9="SD",3,1))) -> 1 | AV9: =IF($Z9="E",4,IF($Z9="R",2,IF($Z9="SD",3,1))) -> 1 | BG9: {=_xll.BDH($BG$3,"PX_LAST",$A9,$A9,"Days=A","Fill=P")} -> 297.66 | BH9: =BG9/BG8-1 -> -0.060861335
A10: 37164 | B10: =_xll.BDH(B$2,"PX_LAST",$A10,$A10,"Days=A","Fill=P") -> 99.1465 | C10: =$BQ$2*C9 + (1-$BQ$2)*B10 -> 100.46155 | E10: 46.2 | F10: =$BQ$1*F9+(1-$BQ$1)*(E10-50) -> -5.8802304 | G10: -1.04 | H10: =$BQ$1*H9+(1-$BQ$1) * MAX(AVERAGE($G$4:$G$256)-3*STDEVA($G$4:$G$256),MIN(G10,AVERAGE($G$4:$G$256)+3*STDEVA($G$4:$G$256))) -> -0.70620672 | I10: {=_xll.BDH(I$2,"PX_LAST",$A10,$A10,"Days=A","Fill=P")} -> -1.602 | J10: =$BQ$3*J9+(1-$BQ$3)*I10 -> -0.58328942 | AC10: Quanti | AI10: 0 | AK10: =IF(OR($AB10=AK$4,$AB11=AK$4),$U10,NA()) -> #N/A | AL10: =IF(OR($AB10=AL$4,$AB11=AL$4),$U10,NA()) -> #N/A | AM10: =IF(OR($AB10=AM$4,$AB11=AM$4),$U10,NA()) -> #N/A | AN10: =IF(OR($AB10=AN$4,$AB11=AN$4),$U10,NA()) -> #N/A | AO10: =IF(OR($AB10=AO$5,$AB11=AO$5),$BG10,NA()) -> #N/A | AP10: =IF(OR($AB10=AP$5,$AB11=AP$5),$BG10,NA()) -> #N/A | AQ10: =IF(OR($AB10=AQ$5,$AB11=AQ$5),$BG10,NA()) -> #N/A | AR10: =IF(OR($AB10=AN$5,$AB11=AN$5),$BG10,NA()) -> #N/A | AT10: =A10 -> 37164 | AU10: =IF($V10="E",4,IF($V10="R",2,IF($V10="SD",3,1))) -> 1 | AV10: =IF($Z10="E",4,IF($Z10="R",2,IF($Z10="SD",3,1))) -> 1 | BG10: {=_xll.BDH($BG$3,"PX_LAST",$A10,$A10,"Days=A","Fill=P")} -> 266.29 | BH10: =BG10/BG9-1 -> -0.1053887
A11: 37195 | B11: =_xll.BDH(B$2,"PX_LAST",$A11,$A11,"Days=A","Fill=P") -> 98.9939 | C11: =$BQ$2*C10 + (1-$BQ$2)*B11 -> 100.38817 | E11: 40.8 | F11: =$BQ$1*F10+(1-$BQ$1)*(E11-50) -> -6.5441843 | G11: -0.22 | H11: =$BQ$1*H10+(1-$BQ$1) * MAX(AVERAGE($G$4:$G$256)-3*STDEVA($G$4:$G$256),MIN(G11,AVERAGE($G$4:$G$256)+3*STDEVA($G$4:$G$256))) -> -0.60896538 | I11: {=_xll.BDH(I$2,"PX_LAST",$A11,$A11,"Days=A","Fill=P")} -> -1.575 | J11: =$BQ$3*J10+(1-$BQ$3)*I11 -> -0.63287495 | AC11: Quanti | AI11: 0 | AK11: =IF(OR($AB11=AK$4,$AB12=AK$4),$U11,NA()) -> #N/A | AL11: =IF(OR($AB11=AL$4,$AB12=AL$4),$U11,NA()) -> #N/A | AM11: =IF(OR($AB11=AM$4,$AB12=AM$4),$U11,NA()) -> #N/A | AN11: =IF(OR($AB11=AN$4,$AB12=AN$4),$U11,NA()) -> #N/A | AO11: =IF(OR($AB11=AO$5,$AB12=AO$5),$BG11,NA()) -> #N/A | AP11: =IF(OR($AB11=AP$5,$AB12=AP$5),$BG11,NA()) -> #N/A | AQ11: =IF(OR($AB11=AQ$5,$AB12=AQ$5),$BG11,NA()) -> #N/A | AR11: =IF(OR($AB11=AN$5,$AB12=AN$5),$BG11,NA()) -> #N/A | AT11: =A11 -> 37195 | AU11: =IF($V11="E",4,IF($V11="R",2,IF($V11="SD",3,1))) -> 1 | AV11: =IF($Z11="E",4,IF($Z11="R",2,IF($Z11="SD",3,1))) -> 1 | BG11: {=_xll.BDH($BG$3,"PX_LAST",$A11,$A11,"Days=A","Fill=P")} -> 277.41 | BH11: =BG11/BG10-1 -> 0.041758985
A12: 37225 | B12: =_xll.BDH(B$2,"PX_LAST",$A12,$A12,"Days=A","Fill=P") -> 98.9606 | C12: =$BQ$2*C11 + (1-$BQ$2)*B12 -> 100.31679 | E12: 44.1 | F12: =$BQ$1*F11+(1-$BQ$1)*(E12-50) -> -6.4153475 | G12: -0.77 | H12: =$BQ$1*H11+(1-$BQ$1) * MAX(AVERAGE($G$4:$G$256)-3*STDEVA($G$4:$G$256),MIN(G12,AVERAGE($G$4:$G$256)+3*STDEVA($G$4:$G$256))) -> -0.6411723 | I12: {=_xll.BDH(I$2,"PX_LAST",$A12,$A12,"Days=A","Fill=P")} -> -1.133 | J12: =$BQ$3*J11+(1-$BQ$3)*I12 -> -0.6578812 | AC12: Quanti | AI12: 0 | AK12: =IF(OR($AB12=AK$4,$AB13=AK$4),$U12,NA()) -> #N/A | AL12: =IF(OR($AB12=AL$4,$AB13=AL$4),$U12,NA()) -> #N/A | AM12: =IF(OR($AB12=AM$4,$AB13=AM$4),$U12,NA()) -> #N/A | AN12: =IF(OR($AB12=AN$4,$AB13=AN$4),$U12,NA()) -> #N/A | AO12: =IF(OR($AB12=AO$5,$AB13=AO$5),$BG12,NA()) -> #N/A | AP12: =IF(OR($AB12=AP$5,$AB13=AP$5),$BG12,NA()) -> #N/A | AQ12: =IF(OR($AB12=AQ$5,$AB13=AQ$5),$BG12,NA()) -> #N/A | AR12: =IF(OR($AB12=AN$5,$AB13=AN$5),$BG12,NA()) -> #N/A | AT12: =A12 -> 37225 | AU12: =IF($V12="E",4,IF($V12="R",2,IF($V12="SD",3,1))) -> 1 | AV12: =IF($Z12="E",4,IF($Z12="R",2,IF($Z12="SD",3,1))) -> 1 | BG12: {=_xll.BDH($BG$3,"PX_LAST",$A12,$A12,"Days=A","Fill=P")} -> 288.95 | BH12: =BG12/BG11-1 -> 0.041599077
A13: 37256 | B13: =_xll.BDH(B$2,"PX_LAST",$A13,$A13,"Days=A","Fill=P") -> 99.043 | C13: =$BQ$2*C12 + (1-$BQ$2)*B13 -> 100.2531 | E13: 45.3 | F13: =$BQ$1*F12+(1-$BQ$1)*(E13-50) -> -6.072278 | G13: -0.3 | H13: =$BQ$1*H12+(1-$BQ$1) * MAX(AVERAGE($G$4:$G$256)-3*STDEVA($G$4:$G$256),MIN(G13,AVERAGE($G$4:$G$256)+3*STDEVA($G$4:$G$256))) -> -0.57293784 | I13: {=_xll.BDH(I$2,"PX_LAST",$A13,$A13,"Days=A","Fill=P")} -> -0.561 | J13: =$BQ$3*J12+(1-$BQ$3)*I13 -> -0.65303714 | AC13: Quanti | AI13: 0 | AK13: =IF(OR($AB13=AK$4,$AB14=AK$4),$U13,NA()) -> #N/A | AL13: =IF(OR($AB13=AL$4,$AB14=AL$4),$U13,NA()) -> #N/A | AM13: =IF(OR($AB13=AM$4,$AB14=AM$4),$U13,NA()) -> #N/A | AN13: =IF(OR($AB13=AN$4,$AB14=AN$4),$U13,NA()) -> #N/A | AO13: =IF(OR($AB13=AO$5,$AB14=AO$5),$BG13,NA()) -> #N/A | AP13: =IF(OR($AB13=AP$5,$AB14=AP$5),$BG13,NA()) -> #N/A | AQ13: =IF(OR($AB13=AQ$5,$AB14=AQ$5),$BG13,NA()) -> #N/A | AR13: =IF(OR($AB13=AN$5,$AB14=AN$5),$BG13,NA()) -> #N/A | AT13: =A13 -> 37256 | AU13: =IF($V13="E",4,IF($V13="R",2,IF($V13="SD",3,1))) -> 1 | AV13: =IF($Z13="E",4,IF($Z13="R",2,IF($Z13="SD",3,1))) -> 1 | BG13: {=_xll.BDH($BG$3,"PX_LAST",$A13,$A13,"Days=A","Fill=P")} -> 298.73 | BH13: =BG13/BG12-1 -> 0.033846686
A14: 37287 | B14: =_xll.BDH(B$2,"PX_LAST",$A14,$A14,"Days=A","Fill=P") -> 99.2033 | C14: =$BQ$2*C13 + (1-$BQ$2)*B14 -> 100.20061 | E14: 47.5 | F14: =$BQ$1*F13+(1-$BQ$1)*(E14-50) -> -5.3578224 | G14: -0.07 | H14: =$BQ$1*H13+(1-$BQ$1) * MAX(AVERAGE($G$4:$G$256)-3*STDEVA($G$4:$G$256),MIN(G14,AVERAGE($G$4:$G$256)+3*STDEVA($G$4:$G$256))) -> -0.47235027 | I14: {=_xll.BDH(I$2,"PX_LAST",$A14,$A14,"Days=A","Fill=P")} -> -0.805 | J14: =$BQ$3*J13+(1-$BQ$3)*I14 -> -0.66063528 | AC14: Quanti | AI14: 0 | AK14: =IF(OR($AB14=AK$4,$AB15=AK$4),$U14,NA()) -> #N/A | AL14: =IF(OR($AB14=AL$4,$AB15=AL$4),$U14,NA()) -> #N/A | AM14: =IF(OR($AB14=AM$4,$AB15=AM$4),$U14,NA()) -> #N/A | AN14: =IF(OR($AB14=AN$4,$AB15=AN$4),$U14,NA()) -> #N/A | AO14: =IF(OR($AB14=AO$5,$AB15=AO$5),$BG14,NA()) -> #N/A | AP14: =IF(OR($AB14=AP$5,$AB15=AP$5),$BG14,NA()) -> #N/A | AQ14: =IF(OR($AB14=AQ$5,$AB15=AQ$5),$BG14,NA()) -> #N/A | AR14: =IF(OR($AB14=AN$5,$AB15=AN$5),$BG14,NA()) -> #N/A | AT14: =A14 -> 37287 | AU14: =IF($V14="E",4,IF($V14="R",2,IF($V14="SD",3,1))) -> 1 | AV14: =IF($Z14="E",4,IF($Z14="R",2,IF($Z14="SD",3,1))) -> 1 | BG14: {=_xll.BDH($BG$3,"PX_LAST",$A14,$A14,"Days=A","Fill=P")} -> 292.45 | BH14: =BG14/BG13-1 -> -0.021022328
A15: 37315 | B15: =_xll.BDH(B$2,"PX_LAST",$A15,$A15,"Days=A","Fill=P") -> 99.3953 | C15: =$BQ$2*C14 + (1-$BQ$2)*B15 -> 100.16035 | E15: 50.7 | F15: =$BQ$1*F14+(1-$BQ$1)*(E15-50) -> -4.1462579 | G15: -0.11 | H15: =$BQ$1*H14+(1-$BQ$1) * MAX(AVERAGE($G$4:$G$256)-3*STDEVA($G$4:$G$256),MIN(G15,AVERAGE($G$4:$G$256)+3*STDEVA($G$4:$G$256))) -> -0.39988022 | I15: {=_xll.BDH(I$2,"PX_LAST",$A15,$A15,"Days=A","Fill=P")} -> -0.84 | J15: =$BQ$3*J14+(1-$BQ$3)*I15 -> -0.66960352 | AC15: Quanti | AI15: 0 | AK15: =IF(OR($AB15=AK$4,$AB16=AK$4),$U15,NA()) -> #N/A | AL15: =IF(OR($AB15=AL$4,$AB16=AL$4),$U15,NA()) -> #N/A | AM15: =IF(OR($AB15=AM$4,$AB16=AM$4),$U15,NA()) -> #N/A | AN15: =IF(OR($AB15=AN$4,$AB16=AN$4),$U15,NA()) -> #N/A | AO15: =IF(OR($AB15=AO$5,$AB16=AO$5),$BG15,NA()) -> #N/A | AP15: =IF(OR($AB15=AP$5,$AB16=AP$5),$BG15,NA()) -> #N/A | AQ15: =IF(OR($AB15=AQ$5,$AB16=AQ$5),$BG15,NA()) -> #N/A | AR15: =IF(OR($AB15=AN$5,$AB16=AN$5),$BG15,NA()) -> #N/A | AT15: =A15 -> 37315 | AU15: =IF($V15="E",4,IF($V15="R",2,IF($V15="SD",3,1))) -> 1 | AV15: =IF($Z15="E",4,IF($Z15="R",2,IF($Z15="SD",3,1))) -> 1 | BG15: {=_xll.BDH($BG$3,"PX_LAST",$A15,$A15,"Days=A","Fill=P")} -> 289.84 | BH15: =BG15/BG14-1 -> -0.0089246025
A16: 37344 | B16: =_xll.BDH(B$2,"PX_LAST",$A16,$A16,"Days=A","Fill=P") -> 99.3953 | C16: =$BQ$2*C15 + (1-$BQ$2)*B16 -> 100.1221 | E16: 52.4 | F16: =$BQ$1*F15+(1-$BQ$1)*(E16-50) -> -2.8370063 | G16: -0.01 | H16: =$BQ$1*H15+(1-$BQ$1) * MAX(AVERAGE($G$4:$G$256)-3*STDEVA($G$4:$G$256),MIN(G16,AVERAGE($G$4:$G$256)+3*STDEVA($G$4:$G$256))) -> -0.32190417 | I16: {=_xll.BDH(I$2,"PX_LAST",$A16,$A16,"Days=A","Fill=P")} -> -0.742 | J16: =$BQ$3*J15+(1-$BQ$3)*I16 -> -0.67322334 | AC16: Quanti | AI16: 0 | AK16: =IF(OR($AB16=AK$4,$AB17=AK$4),$U16,NA()) -> #N/A | AL16: =IF(OR($AB16=AL$4,$AB17=AL$4),$U16,NA()) -> #N/A | AM16: =IF(OR($AB16=AM$4,$AB17=AM$4),$U16,NA()) -> #N/A | AN16: =IF(OR($AB16=AN$4,$AB17=AN$4),$U16,NA()) -> #N/A | AO16: =IF(OR($AB16=AO$5,$AB17=AO$5),$BG16,NA()) -> #N/A | AP16: =IF(OR($AB16=AP$5,$AB17=AP$5),$BG16,NA()) -> #N/A | AQ16: =IF(OR($AB16=AQ$5,$AB17=AQ$5),$BG16,NA()) -> #N/A | AR16: =IF(OR($AB16=AN$5,$AB17=AN$5),$BG16,NA()) -> #N/A | AT16: =A16 -> 37344 | AU16: =IF($V16="E",4,IF($V16="R",2,IF($V16="SD",3,1))) -> 1 | AV16: =IF($Z16="E",4,IF($Z16="R",2,IF($Z16="SD",3,1))) -> 1 | BG16: {=_xll.BDH($BG$3,"PX_LAST",$A16,$A16,"Days=A","Fill=P")} -> 303.04 | BH16: =BG16/BG15-1 -> 0.045542368
A17: 37376 | B17: =_xll.BDH(B$2,"PX_LAST",$A17,$A17,"Days=A","Fill=P") -> 99.6812 | C17: =$BQ$2*C16 + (1-$BQ$2)*B17 -> 100.10005 | E17: 52.4 | F17: =$BQ$1*F16+(1-$BQ$1)*(E17-50) -> -1.7896051 | G17: 0.17 | H17: =$BQ$1*H16+(1-$BQ$1) * MAX(AVERAGE($G$4:$G$256)-3*STDEVA($G$4:$G$256),MIN(G17,AVERAGE($G$4:$G$256)+3*STDEVA($G$4:$G$256))) -> -0.22352334 | I17: {=_xll.BDH(I$2,"PX_LAST",$A17,$A17,"Days=A","Fill=P")} -> -0.63 | J17: =$BQ$3*J16+(1-$BQ$3)*I17 -> -0.67106218 | AC17: Quanti | AI17: 0 | AK17: =IF(OR($AB17=AK$4,$AB18=AK$4),$U17,NA()) -> #N/A | AL17: =IF(OR($AB17=AL$4,$AB18=AL$4),$U17,NA()) -> #N/A | AM17: =IF(OR($AB17=AM$4,$AB18=AM$4),$U17,NA()) -> #N/A | AN17: =IF(OR($AB17=AN$4,$AB18=AN$4),$U17,NA()) -> #N/A | AO17: =IF(OR($AB17=AO$5,$AB18=AO$5),$BG17,NA()) -> #N/A | AP17: =IF(OR($AB17=AP$5,$AB18=AP$5),$BG17,NA()) -> #N/A | AQ17: =IF(OR($AB17=AQ$5,$AB18=AQ$5),$BG17,NA()) -> #N/A | AR17: =IF(OR($AB17=AN$5,$AB18=AN$5),$BG17,NA()) -> #N/A | AT17: =A17 -> 37376 | AU17: =IF($V17="E",4,IF($V17="R",2,IF($V17="SD",3,1))) -> 1 | AV17: =IF($Z17="E",4,IF($Z17="R",2,IF($Z17="SD",3,1))) -> 1 | BG17: {=_xll.BDH($BG$3,"PX_LAST",$A17,$A17,"Days=A","Fill=P")} -> 290.64 | BH17: =BG17/BG16-1 -> -0.040918691
A18: 37407 | B18: =_xll.BDH(B$2,"PX_LAST",$A18,$A18,"Days=A","Fill=P") -> 99.7132 | C18: =$BQ$2*C17 + (1-$BQ$2)*B18 -> 100.08071 | E18: 53.1 | F18: =$BQ$1*F17+(1-$BQ$1)*(E18-50) -> -0.81168404 | G18: 0.03 | H18: =$BQ$1*H17+(1-$BQ$1) * MAX(AVERAGE($G$4:$G$256)-3*STDEVA($G$4:$G$256),MIN(G18,AVERAGE($G$4:$G$256)+3*STDEVA($G$4:$G$256))) -> -0.17281867 | I18: {=_xll.BDH(I$2,"PX_LAST",$A18,$A18,"Days=A","Fill=P")} -> -0.707 | J18: =$BQ$3*J17+(1-$BQ$3)*I18 -> -0.67285907 | AC18: Quanti | AI18: 0 | AK18: =IF(OR($AB18=AK$4,$AB19=AK$4),$U18,NA()) -> #N/A | AL18: =IF(OR($AB18=AL$4,$AB19=AL$4),$U18,NA()) -> #N/A | AM18: =IF(OR($AB18=AM$4,$AB19=AM$4),$U18,NA()) -> #N/A | AN18: =IF(OR($AB18=AN$4,$AB19=AN$4),$U18,NA()) -> #N/A | AO18: =IF(OR($AB18=AO$5,$AB19=AO$5),$BG18,NA()) -> #N/A | AP18: =IF(OR($AB18=AP$5,$AB19=AP$5),$BG18,NA()) -> #N/A | AQ18: =IF(OR($AB18=AQ$5,$AB19=AQ$5),$BG18,NA()) -> #N/A | AR18: =IF(OR($AB18=AN$5,$AB19=AN$5),$BG18,NA()) -> #N/A | AT18: =A18 -> 37407 | AU18: =IF($V18="E",4,IF($V18="R",2,IF($V18="SD",3,1))) -> 1 | AV18: =IF($Z18="E",4,IF($Z18="R",2,IF($Z18="SD",3,1))) -> 1 | BG18: {=_xll.BDH($BG$3,"PX_LAST",$A18,$A18,"Days=A","Fill=P")} -> 279.03 | BH18: =BG18/BG17-1 -> -0.039946325
... A21: 37498 | B21: =_xll.BDH(B$2,"PX_LAST",$A21,$A21,"Days=A","Fill=P") -> 99.5678 | C21: =$BQ$2*C20 + (1-$BQ$2)*B21 -> 100.01412 | E21: 50.3 | F21: =$BQ$1*F20+(1-$BQ$1)*(E21-50) -> 0.13721777 | G21: -0.06 | H21: =$BQ$1*H20+(1-$BQ$1) * MAX(AVERAGE($G$4:$G$256)-3*STDEVA($G$4:$G$256),MIN(G21,AVERAGE($G$4:$G$256)+3*STDEVA($G$4:$G$256))) -> -0.10816316 | I21: {=_xll.BDH(I$2,"PX_LAST",$A21,$A21,"Days=A","Fill=P")} -> -1.834 | J21: =$BQ$3*J20+(1-$BQ$3)*I21 -> -0.81524879 | AC21: Quanti | AI21: 0 | AK21: =IF(OR($AB21=AK$4,$AB22=AK$4),$U21,NA()) -> #N/A | AL21: =IF(OR($AB21=AL$4,$AB22=AL$4),$U21,NA()) -> #N/A | AM21: =IF(OR($AB21=AM$4,$AB22=AM$4),$U21,NA()) -> #N/A | AN21: =IF(OR($AB21=AN$4,$AB22=AN$4),$U21,NA()) -> #N/A | AO21: =IF(OR($AB21=AO$5,$AB22=AO$5),$BG21,NA()) -> #N/A | AP21: =IF(OR($AB21=AP$5,$AB22=AP$5),$BG21,NA()) -> #N/A | AQ21: =IF(OR($AB21=AQ$5,$AB22=AQ$5),$BG21,NA()) -> #N/A | AR21: =IF(OR($AB21=AN$5,$AB22=AN$5),$BG21,NA()) -> #N/A | AT21: =A21 -> 37498 | AU21: =IF($V21="E",4,IF($V21="R",2,IF($V21="SD",3,1))) -> 1 | AV21: =IF($Z21="E",4,IF($Z21="R",2,IF($Z21="SD",3,1))) -> 1 | BG21: {=_xll.BDH($BG$3,"PX_LAST",$A21,$A21,"Days=A","Fill=P")} -> 226.82 | BH21: =BG21/BG20-1 -> -0.0035584062
A22: 37529 | B22: =_xll.BDH(B$2,"PX_LAST",$A22,$A22,"Days=A","Fill=P") -> 99.2716 | C22: =$BQ$2*C21 + (1-$BQ$2)*B22 -> 99.97699 | E22: 50.5 | F22: =$BQ$1*F21+(1-$BQ$1)*(E22-50) -> 0.20977422 | G22: -0.32 | H22: =$BQ$1*H21+(1-$BQ$1) * MAX(AVERAGE($G$4:$G$256)-3*STDEVA($G$4:$G$256),MIN(G22,AVERAGE($G$4:$G$256)+3*STDEVA($G$4:$G$256))) -> -0.15053053 | I22: {=_xll.BDH(I$2,"PX_LAST",$A22,$A22,"Days=A","Fill=P")} -> -2.551 | J22: =$BQ$3*J21+(1-$BQ$3)*I22 -> -0.90203635 | Z22: C | AC22: Quanti | AI22: 0 | AK22: =IF(OR($AB22=AK$4,$AB23=AK$4),$U22,NA()) -> #N/A | AL22: =IF(OR($AB22=AL$4,$AB23=AL$4),$U22,NA()) -> #N/A | AM22: =IF(OR($AB22=AM$4,$AB23=AM$4),$U22,NA()) -> 0 | AN22: =IF(OR($AB22=AN$4,$AB23=AN$4),$U22,NA()) -> #N/A | AO22: =IF(OR($AB22=AO$5,$AB23=AO$5),$BG22,NA()) -> #N/A | AP22: =IF(OR($AB22=AP$5,$AB23=AP$5),$BG22,NA()) -> #N/A | AQ22: =IF(OR($AB22=AQ$5,$AB23=AQ$5),$BG22,NA()) -> 194.76 | AR22: =IF(OR($AB22=AN$5,$AB23=AN$5),$BG22,NA()) -> #N/A | AT22: =A22 -> 37529 | AU22: =IF($V22="E",4,IF($V22="R",2,IF($V22="SD",3,1))) -> 1 | AV22: =IF($Z22="E",4,IF($Z22="R",2,IF($Z22="SD",3,1))) -> 1 | BG22: {=_xll.BDH($BG$3,"PX_LAST",$A22,$A22,"Days=A","Fill=P")} -> 194.76 | BH22: =BG22/BG21-1 -> -0.14134556
A23: 37560 | B23: =_xll.BDH(B$2,"PX_LAST",$A23,$A23,"Days=A","Fill=P") -> 99.1027 | C23: =$BQ$2*C22 + (1-$BQ$2)*B23 -> 99.933275 | D23: =(C23-AVERAGE(C4:C23))/AVEDEV(C4:C23) -> -1.5596842 | E23: 49 | F23: =$BQ$1*F22+(1-$BQ$1)*(E23-50) -> -0.032180627 | G23: -0.39 | H23: =$BQ$1*H22+(1-$BQ$1) * MAX(AVERAGE($G$4:$G$256)-3*STDEVA($G$4:$G$256),MIN(G23,AVERAGE($G$4:$G$256)+3*STDEVA($G$4:$G$256))) -> -0.19842442 | I23: {=_xll.BDH(I$2,"PX_LAST",$A23,$A23,"Days=A","Fill=P")} -> -1.896 | J23: =$BQ$3*J22+(1-$BQ$3)*I23 -> -0.95173454 | K23: =(J23-MEDIAN(J4:J23))/AVEDEV(J4:J23) -> -3.3725437 | T23: C | U23: =AVERAGE(D22,K23,N23,Q23) -> -3.3725437 | V23: =IF(U23-U22>0,IF(U23>=0,"E","R"),IF(U23>=0,"SD","C")) -> C | X23: =IF(OR(ABS($U23-$U22)>$W$1),1,0) -> 1 | Y23: =$U23-$U22 -> -3.3725437 | Z23: =IF(ABS($U23-$U22)>AE23,IF(Z22="SD",IF(U23*U22>0,Z22,V23),V23),Z22) -> C | AA23: =IF(Z23<>V22,U23,AA22) -> -3.3725437 | AB23: C | AC23: Quanti | AI23: 0 | AK23: =IF(OR($AB23=AK$4,$AB24=AK$4),$U23,NA()) -> #N/A | AL23: =IF(OR($AB23=AL$4,$AB24=AL$4),$U23,NA()) -> #N/A | AM23: =IF(OR($AB23=AM$4,$AB24=AM$4),$U23,NA()) -> -3.3725437 | AN23: =IF(OR($AB23=AN$4,$AB24=AN$4),$U23,NA()) -> -3.3725437 | AO23: =IF(OR($AB23=AO$5,$AB24=AO$5),$BG23,NA()) -> #N/A | AP23: =IF(OR($AB23=AP$5,$AB24=AP$5),$BG23,NA()) -> #N/A | AQ23: =IF(OR($AB23=AQ$5,$AB24=AQ$5),$BG23,NA()) -> 213.01 | AR23: =IF(OR($AB23=AN$5,$AB24=AN$5),$BG23,NA()) -> #N/A | AT23: =A23 -> 37560 | AU23: =IF($V23="E",4,IF($V23="R",2,IF($V23="SD",3,1))) -> 1 | AV23: =IF($Z23="E",4,IF($Z23="R",2,IF($Z23="SD",3,1))) -> 1 | BG23: {=_xll.BDH($BG$3,"PX_LAST",$A23,$A23,"Days=A","Fill=P")} -> 213.01 | BH23: =BG23/BG22-1 -> 0.093705073 | BP23: E | BQ23: 1
A24: 37589 | B24: =_xll.BDH(B$2,"PX_LAST",$A24,$A24,"Days=A","Fill=P") -> 99.1027 | C24: =$BQ$2*C23 + (1-$BQ$2)*B24 -> 99.891747 | D24: =(C24-AVERAGE(C5:C24))/AVEDEV(C5:C24) -> -1.622025 | E24: 48.5 | F24: =$BQ$1*F23+(1-$BQ$1)*(E24-50) -> -0.3257445 | G24: 0.14 | H24: =$BQ$1*H23+(1-$BQ$1) * MAX(AVERAGE($G$4:$G$256)-3*STDEVA($G$4:$G$256),MIN(G24,AVERAGE($G$4:$G$256)+3*STDEVA($G$4:$G$256))) -> -0.13073954 | I24: {=_xll.BDH(I$2,"PX_LAST",$A24,$A24,"Days=A","Fill=P")} -> -0.817 | J24: =$BQ$3*J23+(1-$BQ$3)*I24 -> -0.94499781 | K24: =(J24-MEDIAN(J5:J24))/AVEDEV(J5:J24) -> -2.8175166 | T24: R | U24: =AVERAGE(D23,K24,N24,Q24) -> -2.1886004 | V24: =IF(U24-U23>0,IF(U24>=0,"E","R"),IF(U24>=0,"SD","C")) -> R | W24: =U24-U23 -> 1.1839434 | X24: =IF(OR(ABS($U24-$U23)>$W$1),1,0) -> 1 | Y24: =$U24-$U23 -> 1.1839434 | Z24: =IF(ABS($U24-$U23)>AE24,V24,Z23) -> R | AA24: =IF(Z24<>V23,U24,AA23) -> -2.1886004 | AB24: =Z24 -> R | AC24: Quanti | AD24: =ABS(W24) -> 1.1839434 | AE24: 0.15 | AI24: 0 | AK24: =IF(OR($AB24=AK$4,$AB25=AK$4),$U24,NA()) -> #N/A | AL24: =IF(OR($AB24=AL$4,$AB25=AL$4),$U24,NA()) -> #N/A | AM24: =IF(OR($AB24=AM$4,$AB25=AM$4),$U24,NA()) -> #N/A | AN24: =IF(OR($AB24=AN$4,$AB25=AN$4),$U24,NA()) -> -2.1886004 | AO24: =IF(OR($AB24=AO$5,$AB25=AO$5),$BG24,NA()) -> #N/A | AP24: =IF(OR($AB24=AP$5,$AB25=AP$5),$BG24,NA()) -> #N/A | AQ24: =IF(OR($AB24=AQ$5,$AB25=AQ$5),$BG24,NA()) -> #N/A | AR24: =IF(OR($AB24=AN$5,$AB25=AN$5),$BG24,NA()) -> #N/A | AT24: =A24 -> 37589 | AU24: =IF($V24="E",4,IF($V24="R",2,IF($V24="SD",3,1))) -> 2 | AV24: =IF($Z24="E",4,IF($Z24="R",2,IF($Z24="SD",3,1))) -> 2 | BG24: {=_xll.BDH($BG$3,"PX_LAST",$A24,$A24,"Days=A","Fill=P")} -> 222.47 | BH24: =BG24/BG23-1 -> 0.044411061 | BI24: =AB24 -> R | BJ24: =_xlfn.XLOOKUP(BI24,$BP$23:$BP$26,$BQ$23:$BQ$26) -> 1 | BK24: =BJ24*BH25 -> -0.086393671 | BL24: 100 | BM24: 100 | BN24: =BL24/BM24 -> 1 | BP24: SD | BQ24: 0
A25: 37621 | B25: =_xll.BDH(B$2,"PX_LAST",$A25,$A25,"Days=A","Fill=P") -> 98.7679 | C25: =$BQ$2*C24 + (1-$BQ$2)*B25 -> 99.835554 | D25: =(C25-AVERAGE(C6:C25))/AVEDEV(C6:C25) -> -1.7593503 | E25: 51.6 | F25: =$BQ$1*F24+(1-$BQ$1)*(E25-50) -> 0.059404398 | G25: -0.59 | H25: =$BQ$1*H24+(1-$BQ$1) * MAX(AVERAGE($G$4:$G$256)-3*STDEVA($G$4:$G$256),MIN(G25,AVERAGE($G$4:$G$256)+3*STDEVA($G$4:$G$256))) -> -0.22259163 | I25: {=_xll.BDH(I$2,"PX_LAST",$A25,$A25,"Days=A","Fill=P")} -> -0.929 | J25: =$BQ$3*J24+(1-$BQ$3)*I25 -> -0.94419792 | K25: =(J25-MEDIAN(J6:J25))/AVEDEV(J6:J25) -> -2.4232869 | T25: C | U25: =AVERAGE(D24,K25,N25,Q25) -> -2.022656 | V25: =IF(U25-U24>0,IF(U25>=0,"E","R"),IF(U25>=0,"SD","C")) -> R | W25: =U25-U24 -> 0.16594439 | X25: =IF(OR(ABS($U25-$U24)>$W$1),1,0) -> 0 | Y25: =$U25-$U24 -> 0.16594439 | Z25: =IF(ABS($U25-$U24)>AE25,V25,Z24) -> R | AA25: =IF(Z25<>V24,U25,AA24) -> -2.1886004 | AB25: =Z25 -> R | AC25: Quanti | AD25: =ABS(W25) -> 0.16594439 | AE25: 0.15 | AI25: 0 | AK25: =IF(OR($AB25=AK$4,$AB26=AK$4),$U25,NA()) -> #N/A | AL25: =IF(OR($AB25=AL$4,$AB26=AL$4),$U25,NA()) -> #N/A | AM25: =IF(OR($AB25=AM$4,$AB26=AM$4),$U25,NA()) -> #N/A | AN25: =IF(OR($AB25=AN$4,$AB26=AN$4),$U25,NA()) -> -2.022656 | AO25: =IF(OR($AB25=AO$5,$AB26=AO$5),$BG25,NA()) -> #N/A | AP25: =IF(OR($AB25=AP$5,$AB26=AP$5),$BG25,NA()) -> #N/A | AQ25: =IF(OR($AB25=AQ$5,$AB26=AQ$5),$BG25,NA()) -> #N/A | AR25: =IF(OR($AB25=AN$5,$AB26=AN$5),$BG25,NA()) -> #N/A | AT25: =A25 -> 37621 | AU25: =IF($V25="E",4,IF($V25="R",2,IF($V25="SD",3,1))) -> 2 | AV25: =IF($Z25="E",4,IF($Z25="R",2,IF($Z25="SD",3,1))) -> 2 | BG25: {=_xll.BDH($BG$3,"PX_LAST",$A25,$A25,"Days=A","Fill=P")} -> 203.25 | BH25: =BG25/BG24-1 -> -0.086393671 | BI25: =AB25 -> R | BJ25: =_xlfn.XLOOKUP(BI25,$BP$23:$BP$26,$BQ$23:$BQ$26) -> 1 | BK25: =BJ25*BH26 -> -0.070110701 | BL25: =BL24*(1+BK24) -> 91.360633 | BM25: =BM24*(1+BH25) -> 91.360633 | BN25: =BL25/BM25 -> 1 | BP25: C | BQ25: 0
A26: 37652 | B26: =_xll.BDH(B$2,"PX_LAST",$A26,$A26,"Days=A","Fill=P") -> 98.6135 | C26: =$BQ$2*C25 + (1-$BQ$2)*B26 -> 99.774452 | D26: =(C26-AVERAGE(C7:C26))/AVEDEV(C7:C26) -> -1.9379152 | E26: 51.3 | F26: =$BQ$1*F25+(1-$BQ$1)*(E26-50) -> 0.30752352 | G26: 0.35 | H26: =$BQ$1*H25+(1-$BQ$1) * MAX(AVERAGE($G$4:$G$256)-3*STDEVA($G$4:$G$256),MIN(G26,AVERAGE($G$4:$G$256)+3*STDEVA($G$4:$G$256))) -> -0.1080733 | I26: {=_xll.BDH(I$2,"PX_LAST",$A26,$A26,"Days=A","Fill=P")} -> -0.972 | J26: =$BQ$3*J25+(1-$BQ$3)*I26 -> -0.94558802 | K26: =(J26-MEDIAN(J7:J26))/AVEDEV(J7:J26) -> -2.218648 | O26: {=_xll.BDH(O$3,"PX_LAST",$A26,$A26,"Days=A","Fill=P")} -> 29.9 | P26: =O26 -> 29.9 | T26: R | U26: =AVERAGE(D25,K26,N26,Q26) -> -1.9889991 | V26: =IF(U26-U25>0,IF(U26>=0,"E","R"),IF(U26>=0,"SD","C")) -> R | W26: =U26-U25 -> 0.033656858 | X26: =IF(OR(ABS($U26-$U25)>$W$1),1,0) -> 0 | Y26: =$U26-$U25 -> 0.033656858 | Z26: =IF(ABS($U26-$U25)>AE26,V26,Z25) -> R | AA26: =IF(Z26<>V25,U26,AA25) -> -2.1886004 | AB26: =Z26 -> R | AC26: Quanti | AD26: =ABS(W26) -> 0.033656858 | AE26: 0.15 | AI26: 0 | AK26: =IF(OR($AB26=AK$4,$AB27=AK$4),$U26,NA()) -> #N/A | AL26: =IF(OR($AB26=AL$4,$AB27=AL$4),$U26,NA()) -> #N/A | AM26: =IF(OR($AB26=AM$4,$AB27=AM$4),$U26,NA()) -> #N/A | AN26: =IF(OR($AB26=AN$4,$AB27=AN$4),$U26,NA()) -> -1.9889991 | AO26: =IF(OR($AB26=AO$5,$AB27=AO$5),$BG26,NA()) -> #N/A | AP26: =IF(OR($AB26=AP$5,$AB27=AP$5),$BG26,NA()) -> #N/A | AQ26: =IF(OR($AB26=AQ$5,$AB27=AQ$5),$BG26,NA()) -> #N/A | AR26: =IF(OR($AB26=AN$5,$AB27=AN$5),$BG26,NA()) -> #N/A | AT26: =A26 -> 37652 | AU26: =IF($V26="E",4,IF($V26="R",2,IF($V26="SD",3,1))) -> 2 | AV26: =IF($Z26="E",4,IF($Z26="R",2,IF($Z26="SD",3,1))) -> 2 | BG26: {=_xll.BDH($BG$3,"PX_LAST",$A26,$A26,"Days=A","Fill=P")} -> 189 | BH26: =BG26/BG25-1 -> -0.070110701 | BI26: =AB26 -> R | BJ26: =_xlfn.XLOOKUP(BI26,$BP$23:$BP$26,$BQ$23:$BQ$26) -> 1 | BK26: =BJ26*BH27 -> -0.038359788 | BL26: =BL25*(1+BK25) -> 84.955275 | BM26: =BM25*(1+BH26) -> 84.955275 | BN26: =BL26/BM26 -> 1 | BP26: R | BQ26: 1
A27: 37680 | B27: =_xll.BDH(B$2,"PX_LAST",$A27,$A27,"Days=A","Fill=P") -> 98.4868 | C27: =$BQ$2*C26 + (1-$BQ$2)*B27 -> 99.710069 | D27: =(C27-AVERAGE(C8:C27))/AVEDEV(C8:C27) -> -2.1392653 | E27: 48.8 | F27: =$BQ$1*F26+(1-$BQ$1)*(E27-50) -> 0.006018815 | G27: -0.46 | H27: =$BQ$1*H26+(1-$BQ$1) * MAX(AVERAGE($G$4:$G$256)-3*STDEVA($G$4:$G$256),MIN(G27,AVERAGE($G$4:$G$256)+3*STDEVA($G$4:$G$256))) -> -0.17845864 | I27: {=_xll.BDH(I$2,"PX_LAST",$A27,$A27,"Days=A","Fill=P")} -> -1.059 | J27: =$BQ$3*J26+(1-$BQ$3)*I27 -> -0.95125862 | K27: =(J27-MEDIAN(J8:J27))/AVEDEV(J8:J27) -> -2.1607434 | O27: {=_xll.BDH(O$3,"PX_LAST",$A27,$A27,"Days=A","Fill=P")} -> 56.3 | P27: =$BQ$5*P26+(1-$BQ$5)*O27 -> 32.54 | T27: C | U27: =AVERAGE(D26,K27,N27,Q27) -> -2.0493293 | V27: =IF(U27-U26>0,IF(U27>=0,"E","R"),IF(U27>=0,"SD","C")) -> C | W27: =U27-U26 -> -0.060330188 | X27: =IF(OR(ABS($U27-$U26)>$W$1),1,0) -> 0 | Y27: =$U27-$U26 -> -0.060330188 | Z27: =IF(ABS($U27-$U26)>AE27,V27,Z26) -> R | AA27: =IF(Z27<>V26,U27,AA26) -> -2.1886004 | AB27: =Z27 -> R | AC27: Quanti | AD27: =ABS(W27) -> 0.060330188 | AE27: 0.15 | AI27: 0 | AK27: =IF(OR($AB27=AK$4,$AB28=AK$4),$U27,NA()) -> #N/A | AL27: =IF(OR($AB27=AL$4,$AB28=AL$4),$U27,NA()) -> #N/A | AM27: =IF(OR($AB27=AM$4,$AB28=AM$4),$U27,NA()) -> #N/A | AN27: =IF(OR($AB27=AN$4,$AB28=AN$4),$U27,NA()) -> -2.0493293 | AO27: =IF(OR($AB27=AO$5,$AB28=AO$5),$BG27,NA()) -> #N/A | AP27: =IF(OR($AB27=AP$5,$AB28=AP$5),$BG27,NA()) -> #N/A | AQ27: =IF(OR($AB27=AQ$5,$AB28=AQ$5),$BG27,NA()) -> #N/A | AR27: =IF(OR($AB27=AN$5,$AB28=AN$5),$BG27,NA()) -> #N/A | AT27: =A27 -> 37680 | AU27: =IF($V27="E",4,IF($V27="R",2,IF($V27="SD",3,1))) -> 1 | AV27: =IF($Z27="E",4,IF($Z27="R",2,IF($Z27="SD",3,1))) -> 2 | BG27: {=_xll.BDH($BG$3,"PX_LAST",$A27,$A27,"Days=A","Fill=P")} -> 181.75 | BH27: =BG27/BG26-1 -> -0.038359788 | BI27: =AB27 -> R | BJ27: =_xlfn.XLOOKUP(BI27,$BP$23:$BP$26,$BQ$23:$BQ$26) -> 1 | BK27: =BJ27*BH28 -> -0.029381018 | BL27: =BL26*(1+BK26) -> 81.696409 | BM27: =BM26*(1+BH27) -> 81.696409 | BN27: =BL27/BM27 -> 1
A28: 37711 | B28: =_xll.BDH(B$2,"PX_LAST",$A28,$A28,"Days=A","Fill=P") -> 98.4106 | C28: =$BQ$2*C27 + (1-$BQ$2)*B28 -> 99.645096 | D28: =(C28-AVERAGE(C9:C28))/AVEDEV(C9:C28) -> -2.3020633 | E28: 46.3 | F28: =$BQ$1*F27+(1-$BQ$1)*(E28-50) -> -0.73518495 | G28: -0.19 | H28: =$BQ$1*H27+(1-$BQ$1) * MAX(AVERAGE($G$4:$G$256)-3*STDEVA($G$4:$G$256),MIN(G28,AVERAGE($G$4:$G$256)+3*STDEVA($G$4:$G$256))) -> -0.18076691 | I28: {=_xll.BDH(I$2,"PX_LAST",$A28,$A28,"Days=A","Fill=P")} -> -1.122 | J28: =$BQ$3*J27+(1-$BQ$3)*I28 -> -0.95979569 | K28: =(J28-MEDIAN(J9:J28))/AVEDEV(J9:J28) -> -2.1140618 | O28: {=_xll.BDH(O$3,"PX_LAST",$A28,$A28,"Days=A","Fill=P")} -> 44.6 | P28: =$BQ$5*P27+(1-$BQ$5)*O28 -> 33.746 | T28: C | U28: =AVERAGE(D27,K28,N28,Q28) -> -2.1266635 | V28: =IF(U28-U27>0,IF(U28>=0,"E","R"),IF(U28>=0,"SD","C")) -> C | W28: =U28-U27 -> -0.077334236 | X28: =IF(OR(ABS($U28-$U27)>$W$1),1,0) -> 0 | Y28: =$U28-$U27 -> -0.077334236 | Z28: =IF(ABS($U28-$U27)>AE28,V28,Z27) -> R | AA28: =IF(Z28<>V27,U28,AA27) -> -2.1266635 | AB28: =Z28 -> R | AC28: Quanti | AD28: =ABS(W28) -> 0.077334236 | AE28: 0.15 | AI28: 0 | AK28: =IF(OR($AB28=AK$4,$AB29=AK$4),$U28,NA()) -> #N/A | AL28: =IF(OR($AB28=AL$4,$AB29=AL$4),$U28,NA()) -> #N/A | AM28: =IF(OR($AB28=AM$4,$AB29=AM$4),$U28,NA()) -> #N/A | AN28: =IF(OR($AB28=AN$4,$AB29=AN$4),$U28,NA()) -> -2.1266635 | AO28: =IF(OR($AB28=AO$5,$AB29=AO$5),$BG28,NA()) -> #N/A | AP28: =IF(OR($AB28=AP$5,$AB29=AP$5),$BG28,NA()) -> #N/A | AQ28: =IF(OR($AB28=AQ$5,$AB29=AQ$5),$BG28,NA()) -> #N/A | AR28: =IF(OR($AB28=AN$5,$AB29=AN$5),$BG28,NA()) -> #N/A | AT28: =A28 -> 37711 | AU28: =IF($V28="E",4,IF($V28="R",2,IF($V28="SD",3,1))) -> 1 | AV28: =IF($Z28="E",4,IF($Z28="R",2,IF($Z28="SD",3,1))) -> 2 | BG28: {=_xll.BDH($BG$3,"PX_LAST",$A28,$A28,"Days=A","Fill=P")} -> 176.41 | BH28: =BG28/BG27-1 -> -0.029381018 | BI28: =AB28 -> R | BJ28: =_xlfn.XLOOKUP(BI28,$BP$23:$BP$26,$BQ$23:$BQ$26) -> 1 | BK28: =BJ28*BH29 -> 0.10469928 | BL28: =BL27*(1+BK27) -> 79.296085 | BM28: =BM27*(1+BH28) -> 79.296085 | BN28: =BL28/BM28 -> 1
A29: 37741 | B29: =_xll.BDH(B$2,"PX_LAST",$A29,$A29,"Days=A","Fill=P") -> 98.4043 | C29: =$BQ$2*C28 + (1-$BQ$2)*B29 -> 99.583056 | D29: =(C29-AVERAGE(C10:C29))/AVEDEV(C10:C29) -> -2.3607931 | E29: 46.1 | F29: =$BQ$1*F28+(1-$BQ$1)*(E29-50) -> -1.368148 | G29: -0.65 | H29: =$BQ$1*H28+(1-$BQ$1) * MAX(AVERAGE($G$4:$G$256)-3*STDEVA($G$4:$G$256),MIN(G29,AVERAGE($G$4:$G$256)+3*STDEVA($G$4:$G$256))) -> -0.27461353 | I29: {=_xll.BDH(I$2,"PX_LAST",$A29,$A29,"Days=A","Fill=P")} -> -0.355 | J29: =$BQ$3*J28+(1-$BQ$3)*I29 -> -0.92955591 | K29: =(J29-MEDIAN(J10:J29))/AVEDEV(J10:J29) -> -1.5604265 | O29: {=_xll.BDH(O$3,"PX_LAST",$A29,$A29,"Days=A","Fill=P")} -> -30.2 | P29: =$BQ$5*P28+(1-$BQ$5)*O29 -> 27.3514 | T29: R | U29: =AVERAGE(D28,K29,N29,Q29) -> -1.9312449 | V29: =IF(U29-U28>0,IF(U29>=0,"E","R"),IF(U29>=0,"SD","C")) -> R | W29: =U29-U28 -> 0.19541867 | X29: =IF(OR(ABS($U29-$U28)>$W$1),1,0) -> 0 | Y29: =$U29-$U28 -> 0.19541867 | Z29: =IF(ABS($U29-$U28)>AE29,V29,Z28) -> R | AA29: =IF(Z29<>V28,U29,AA28) -> -1.9312449 | AB29: =Z29 -> R | AC29: Quanti | AD29: =ABS(W29) -> 0.19541867 | AE29: 0.15 | AI29: 0 | AK29: =IF(OR($AB29=AK$4,$AB30=AK$4),$U29,NA()) -> #N/A | AL29: =IF(OR($AB29=AL$4,$AB30=AL$4),$U29,NA()) -> #N/A | AM29: =IF(OR($AB29=AM$4,$AB30=AM$4),$U29,NA()) -> #N/A | AN29: =IF(OR($AB29=AN$4,$AB30=AN$4),$U29,NA()) -> -1.9312449 | AO29: =IF(OR($AB29=AO$5,$AB30=AO$5),$BG29,NA()) -> #N/A | AP29: =IF(OR($AB29=AP$5,$AB30=AP$5),$BG29,NA()) -> #N/A | AQ29: =IF(OR($AB29=AQ$5,$AB30=AQ$5),$BG29,NA()) -> #N/A | AR29: =IF(OR($AB29=AN$5,$AB30=AN$5),$BG29,NA()) -> #N/A | AT29: =A29 -> 37741 | AU29: =IF($V29="E",4,IF($V29="R",2,IF($V29="SD",3,1))) -> 2 | AV29: =IF($Z29="E",4,IF($Z29="R",2,IF($Z29="SD",3,1))) -> 2 | BG29: {=_xll.BDH($BG$3,"PX_LAST",$A29,$A29,"Days=A","Fill=P")} -> 194.88 | BH29: =BG29/BG28-1 -> 0.10469928 | BI29: =AB29 -> R | BJ29: =_xlfn.XLOOKUP(BI29,$BP$23:$BP$26,$BQ$23:$BQ$26) -> 1 | BK29: =BJ29*BH30 -> 0.0085180624 | BL29: =BL28*(1+BK28) -> 87.598328 | BM29: =BM28*(1+BH29) -> 87.598328 | BN29: =BL29/BM29 -> 1
A30: 37771 | B30: =_xll.BDH(B$2,"PX_LAST",$A30,$A30,"Days=A","Fill=P") -> 98.4043 | C30: =$BQ$2*C29 + (1-$BQ$2)*B30 -> 99.524118 | D30: =(C30-AVERAGE(C11:C30))/AVEDEV(C11:C30) -> -2.3401645 | E30: 49 | F30: =$BQ$1*F29+(1-$BQ$1)*(E30-50) -> -1.2945184 | G30: 0 | H30: =$BQ$1*H29+(1-$BQ$1) * MAX(AVERAGE($G$4:$G$256)-3*STDEVA($G$4:$G$256),MIN(G30,AVERAGE($G$4:$G$256)+3*STDEVA($G$4:$G$256))) -> -0.21969083 | I30: {=_xll.BDH(I$2,"PX_LAST",$A30,$A30,"Days=A","Fill=P")} -> -0.197 | J30: =$BQ$3*J29+(1-$BQ$3)*I30 -> -0.89292811 | K30: =(J30-MEDIAN(J11:J30))/AVEDEV(J11:J30) -> -0.83932667 | O30: {=_xll.BDH(O$3,"PX_LAST",$A30,$A30,"Days=A","Fill=P")} -> -38.2 | P30: =$BQ$5*P29+(1-$BQ$5)*O30 -> 20.79626 | T30: R | U30: =AVERAGE(D29,K30,N30,Q30) -> -1.6000599 | V30: =IF(U30-U29>0,IF(U30>=0,"E","R"),IF(U30>=0,"SD","C")) -> R | W30: =U30-U29 -> 0.33118499 | X30: =IF(OR(ABS($U30-$U29)>$W$1),1,0) -> 1 | Y30: =$U30-$U29 -> 0.33118499 | Z30: =IF(ABS($U30-$U29)>AE30,V30,Z29) -> R | AA30: =IF(Z30<>V29,U30,AA29) -> -1.9312449 | AB30: =Z30 -> R | AC30: Quanti | AD30: =ABS(W30) -> 0.33118499 | AE30: 0.15 | AI30: 0 | AK30: =IF(OR($AB30=AK$4,$AB31=AK$4),$U30,NA()) -> #N/A | AL30: =IF(OR($AB30=AL$4,$AB31=AL$4),$U30,NA()) -> #N/A | AM30: =IF(OR($AB30=AM$4,$AB31=AM$4),$U30,NA()) -> #N/A | AN30: =IF(OR($AB30=AN$4,$AB31=AN$4),$U30,NA()) -> -1.6000599 | AO30: =IF(OR($AB30=AO$5,$AB31=AO$5),$BG30,NA()) -> #N/A | AP30: =IF(OR($AB30=AP$5,$AB31=AP$5),$BG30,NA()) -> #N/A | AQ30: =IF(OR($AB30=AQ$5,$AB31=AQ$5),$BG30,NA()) -> #N/A | AR30: =IF(OR($AB30=AN$5,$AB31=AN$5),$BG30,NA()) -> #N/A | AT30: =A30 -> 37771 | AU30: =IF($V30="E",4,IF($V30="R",2,IF($V30="SD",3,1))) -> 2 | AV30: =IF($Z30="E",4,IF($Z30="R",2,IF($Z30="SD",3,1))) -> 2 | BG30: {=_xll.BDH($BG$3,"PX_LAST",$A30,$A30,"Days=A","Fill=P")} -> 196.54 | BH30: =BG30/BG29-1 -> 0.0085180624 | BI30: =AB30 -> R | BJ30: =_xlfn.XLOOKUP(BI30,$BP$23:$BP$26,$BQ$23:$BQ$26) -> 1 | BK30: =BJ30*BH31 -> 0.032563346 | BL30: =BL29*(1+BK29) -> 88.344496 | BM30: =BM29*(1+BH30) -> 88.344496 | BN30: =BL30/BM30 -> 1
A31: 37802 | B31: =_xll.BDH(B$2,"PX_LAST",$A31,$A31,"Days=A","Fill=P") -> 98.5846 | C31: =$BQ$2*C30 + (1-$BQ$2)*B31 -> 99.477142 | D31: =(C31-AVERAGE(C12:C31))/AVEDEV(C12:C31) -> -2.2440445 | E31: 49 | F31: =$BQ$1*F30+(1-$BQ$1)*(E31-50) -> -1.2356147 | G31: 0.12 | H31: =$BQ$1*H30+(1-$BQ$1) * MAX(AVERAGE($G$4:$G$256)-3*STDEVA($G$4:$G$256),MIN(G31,AVERAGE($G$4:$G$256)+3*STDEVA($G$4:$G$256))) -> -0.15175266 | I31: {=_xll.BDH(I$2,"PX_LAST",$A31,$A31,"Days=A","Fill=P")} -> -0.125 | J31: =$BQ$3*J30+(1-$BQ$3)*I31 -> -0.8545317 | K31: =(J31-MEDIAN(J12:J31))/AVEDEV(J12:J31) -> -0.16669507 | O31: {=_xll.BDH(O$3,"PX_LAST",$A31,$A31,"Days=A","Fill=P")} -> -33.3 | P31: =$BQ$5*P30+(1-$BQ$5)*O31 -> 15.386634 | T31: R | U31: =AVERAGE(D30,K31,N31,Q31) -> -1.2534298 | V31: =IF(U31-U30>0,IF(U31>=0,"E","R"),IF(U31>=0,"SD","C")) -> R | W31: =U31-U30 -> 0.34663008 | X31: =IF(OR(ABS($U31-$U30)>$W$1),1,0) -> 1 | Y31: =$U31-$U30 -> 0.34663008 | Z31: =IF(ABS($U31-$U30)>AE31,V31,Z30) -> R | AA31: =IF(Z31<>V30,U31,AA30) -> -1.9312449 | AB31: =Z31 -> R | AC31: Quanti | AD31: =ABS(W31) -> 0.34663008 | AE31: 0.15 | AI31: 0 | AK31: =IF(OR($AB31=AK$4,$AB32=AK$4),$U31,NA()) -> #N/A | AL31: =IF(OR($AB31=AL$4,$AB32=AL$4),$U31,NA()) -> #N/A | AM31: =IF(OR($AB31=AM$4,$AB32=AM$4),$U31,NA()) -> #N/A | AN31: =IF(OR($AB31=AN$4,$AB32=AN$4),$U31,NA()) -> -1.2534298 | AO31: =IF(OR($AB31=AO$5,$AB32=AO$5),$BG31,NA()) -> #N/A | AP31: =IF(OR($AB31=AP$5,$AB32=AP$5),$BG31,NA()) -> #N/A | AQ31: =IF(OR($AB31=AQ$5,$AB32=AQ$5),$BG31,NA()) -> #N/A | AR31: =IF(OR($AB31=AN$5,$AB32=AN$5),$BG31,NA()) -> #N/A | AT31: =A31 -> 37802 | AU31: =IF($V31="E",4,IF($V31="R",2,IF($V31="SD",3,1))) -> 2 | AV31: =IF($Z31="E",4,IF($Z31="R",2,IF($Z31="SD",3,1))) -> 2 | BG31: {=_xll.BDH($BG$3,"PX_LAST",$A31,$A31,"Days=A","Fill=P")} -> 202.94 | BH31: =BG31/BG30-1 -> 0.032563346 | BI31: =AB31 -> R | BJ31: =_xlfn.XLOOKUP(BI31,$BP$23:$BP$26,$BQ$23:$BQ$26) -> 1 | BK31: =BJ31*BH32 -> 0.040258204 | BL31: =BL30*(1+BK30) -> 91.221288 | BM31: =BM30*(1+BH31) -> 91.221288 | BN31: =BL31/BM31 -> 1
A32: 37833 | B32: =_xll.BDH(B$2,"PX_LAST",$A32,$A32,"Days=A","Fill=P") -> 98.7496 | C32: =$BQ$2*C31 + (1-$BQ$2)*B32 -> 99.440765 | D32: =(C32-AVERAGE(C13:C32))/AVEDEV(C13:C32) -> -2.1055995 | E32: 51 | F32: =$BQ$1*F31+(1-$BQ$1)*(E32-50) -> -0.78849175 | G32: 0.1 | H32: =$BQ$1*H31+(1-$BQ$1) * MAX(AVERAGE($G$4:$G$256)-3*STDEVA($G$4:$G$256),MIN(G32,AVERAGE($G$4:$G$256)+3*STDEVA($G$4:$G$256))) -> -0.10140213 | I32: {=_xll.BDH(I$2,"PX_LAST",$A32,$A32,"Days=A","Fill=P")} -> 0.268 | J32: =$BQ$3*J31+(1-$BQ$3)*I32 -> -0.79840512 | K32: =(J32-MEDIAN(J13:J32))/AVEDEV(J13:J32) -> 0.33075031 | O32: {=_xll.BDH(O$3,"PX_LAST",$A32,$A32,"Days=A","Fill=P")} -> -1.6 | P32: =$BQ$5*P31+(1-$BQ$5)*O32 -> 13.687971 | T32: R | U32: =AVERAGE(D31,K32,N32,Q32) -> -0.95664712 | V32: =IF(U32-U31>0,IF(U32>=0,"E","R"),IF(U32>=0,"SD","C")) -> R | W32: =U32-U31 -> 0.29678269 | X32: =IF(OR(ABS($U32-$U31)>$W$1),1,0) -> 0 | Y32: =$U32-$U31 -> 0.29678269 | Z32: =IF(ABS($U32-$U31)>AE32,V32,Z31) -> R | AA32: =IF(Z32<>V31,U32,AA31) -> -1.9312449 | AB32: =Z32 -> R | AC32: Quanti | AD32: =ABS(W32) -> 0.29678269 | AE32: 0.15 | AI32: 0 | AK32: =IF(OR($AB32=AK$4,$AB33=AK$4),$U32,NA()) -> #N/A | AL32: =IF(OR($AB32=AL$4,$AB33=AL$4),$U32,NA()) -> #N/A | AM32: =IF(OR($AB32=AM$4,$AB33=AM$4),$U32,NA()) -> #N/A | AN32: =IF(OR($AB32=AN$4,$AB33=AN$4),$U32,NA()) -> -0.95664712 | AO32: =IF(OR($AB32=AO$5,$AB33=AO$5),$BG32,NA()) -> #N/A | AP32: =IF(OR($AB32=AP$5,$AB33=AP$5),$BG32,NA()) -> #N/A | AQ32: =IF(OR($AB32=AQ$5,$AB33=AQ$5),$BG32,NA()) -> #N/A | AR32: =IF(OR($AB32=AN$5,$AB33=AN$5),$BG32,NA()) -> #N/A | AT32: =A32 -> 37833 | AU32: =IF($V32="E",4,IF($V32="R",2,IF($V32="SD",3,1))) -> 2 | AV32: =IF($Z32="E",4,IF($Z32="R",2,IF($Z32="SD",3,1))) -> 2 | BG32: {=_xll.BDH($BG$3,"PX_LAST",$A32,$A32,"Days=A","Fill=P")} -> 211.11 | BH32: =BG32/BG31-1 -> 0.040258204 | BI32: =AB32 -> R | BJ32: =_xlfn.XLOOKUP(BI32,$BP$23:$BP$26,$BQ$23:$BQ$26) -> 1 | BK32: =BJ32*BH33 -> 0.017005353 | BL32: =BL31*(1+BK31) -> 94.893694 | BM32: =BM31*(1+BH32) -> 94.893694 | BN32: =BL32/BM32 -> 1
A33: 37862 | B33: =_xll.BDH(B$2,"PX_LAST",$A33,$A33,"Days=A","Fill=P") -> 98.7496 | C33: =$BQ$2*C32 + (1-$BQ$2)*B33 -> 99.406207 | D33: =(C33-AVERAGE(C14:C33))/AVEDEV(C14:C33) -> -1.9733884 | E33: 53.2 | F33: =$BQ$1*F32+(1-$BQ$1)*(E33-50) -> 0.0092065962 | G33: -0.15 | H33: =$BQ$1*H32+(1-$BQ$1) * MAX(AVERAGE($G$4:$G$256)-3*STDEVA($G$4:$G$256),MIN(G33,AVERAGE($G$4:$G$256)+3*STDEVA($G$4:$G$256))) -> -0.1111217 | I33: {=_xll.BDH(I$2,"PX_LAST",$A33,$A33,"Days=A","Fill=P")} -> 0.372 | J33: =$BQ$3*J32+(1-$BQ$3)*I33 -> -0.73988486 | K33: =(J33-MEDIAN(J14:J33))/AVEDEV(J14:J33) -> 0.89654953 | O33: {=_xll.BDH(O$3,"PX_LAST",$A33,$A33,"Days=A","Fill=P")} -> 20.9 | P33: =$BQ$5*P32+(1-$BQ$5)*O33 -> 14.409174 | T33: R | U33: =AVERAGE(D32,K33,N33,Q33) -> -0.60452499 | V33: =IF(U33-U32>0,IF(U33>=0,"E","R"),IF(U33>=0,"SD","C")) -> R | W33: =U33-U32 -> 0.35212213 | X33: =IF(OR(ABS($U33-$U32)>$W$1),1,0) -> 1 | Y33: =$U33-$U32 -> 0.35212213 | Z33: =IF(ABS($U33-$U32)>AE33,V33,Z32) -> R | AA33: =IF(Z33<>V32,U33,AA32) -> -1.9312449 | AB33: =Z33 -> R | AC33: Quanti | AD33: =ABS(W33) -> 0.35212213 | AE33: 0.15 | AI33: 0 | AK33: =IF(OR($AB33=AK$4,$AB34=AK$4),$U33,NA()) -> #N/A | AL33: =IF(OR($AB33=AL$4,$AB34=AL$4),$U33,NA()) -> #N/A | AM33: =IF(OR($AB33=AM$4,$AB34=AM$4),$U33,NA()) -> #N/A | AN33: =IF(OR($AB33=AN$4,$AB34=AN$4),$U33,NA()) -> -0.60452499 | AO33: =IF(OR($AB33=AO$5,$AB34=AO$5),$BG33,NA()) -> #N/A | AP33: =IF(OR($AB33=AP$5,$AB34=AP$5),$BG33,NA()) -> #N/A | AQ33: =IF(OR($AB33=AQ$5,$AB34=AQ$5),$BG33,NA()) -> #N/A | AR33: =IF(OR($AB33=AN$5,$AB34=AN$5),$BG33,NA()) -> #N/A | AT33: =A33 -> 37862 | AU33: =IF($V33="E",4,IF($V33="R",2,IF($V33="SD",3,1))) -> 2 | AV33: =IF($Z33="E",4,IF($Z33="R",2,IF($Z33="SD",3,1))) -> 2 | BG33: {=_xll.BDH($BG$3,"PX_LAST",$A33,$A33,"Days=A","Fill=P")} -> 214.7 | BH33: =BG33/BG32-1 -> 0.017005353 | BI33: =AB33 -> R | BJ33: =_xlfn.XLOOKUP(BI33,$BP$23:$BP$26,$BQ$23:$BQ$26) -> 1 | BK33: =BJ33*BH34 -> -0.036516069 | BL33: =BL32*(1+BK32) -> 96.507394 | BM33: =BM32*(1+BH33) -> 96.507394 | BN33: =BL33/BM33 -> 1
A34: 37894 | B34: =_xll.BDH(B$2,"PX_LAST",$A34,$A34,"Days=A","Fill=P") -> 99.1548 | C34: =$BQ$2*C33 + (1-$BQ$2)*B34 -> 99.393636 | D34: =(C34-AVERAGE(C15:C34))/AVEDEV(C15:C34) -> -1.7867793 | E34: 52.4 | F34: =$BQ$1*F33+(1-$BQ$1)*(E34-50) -> 0.48736528 | G34: 0.33 | H34: =$BQ$1*H33+(1-$BQ$1) * MAX(AVERAGE($G$4:$G$256)-3*STDEVA($G$4:$G$256),MIN(G34,AVERAGE($G$4:$G$256)+3*STDEVA($G$4:$G$256))) -> -0.022897362 | I34: {=_xll.BDH(I$2,"PX_LAST",$A34,$A34,"Days=A","Fill=P")} -> -0.081 | J34: =$BQ$3*J33+(1-$BQ$3)*I34 -> -0.70694062 | K34: =(J34-MEDIAN(J15:J34))/AVEDEV(J15:J34) -> 1.234409 | O34: {=_xll.BDH(O$3,"PX_LAST",$A34,$A34,"Days=A","Fill=P")} -> 50.5 | P34: =$BQ$5*P33+(1-$BQ$5)*O34 -> 18.018256 | T34: R | U34: =AVERAGE(D33,K34,N34,Q34) -> -0.36948969 | V34: =IF(U34-U33>0,IF(U34>=0,"E","R"),IF(U34>=0,"SD","C")) -> R | W34: =U34-U33 -> 0.2350353 | X34: =IF(OR(ABS($U34-$U33)>$W$1),1,0) -> 0 | Y34: =$U34-$U33 -> 0.2350353 | Z34: =IF(ABS($U34-$U33)>AE34,V34,Z33) -> R | AA34: =IF(Z34<>V33,U34,AA33) -> -1.9312449 | AB34: =Z34 -> R | AC34: Quanti | AD34: =ABS(W34) -> 0.2350353 | AE34: 0.15 | AI34: 0 | AK34: =IF(OR($AB34=AK$4,$AB35=AK$4),$U34,NA()) -> #N/A | AL34: =IF(OR($AB34=AL$4,$AB35=AL$4),$U34,NA()) -> #N/A | AM34: =IF(OR($AB34=AM$4,$AB35=AM$4),$U34,NA()) -> #N/A | AN34: =IF(OR($AB34=AN$4,$AB35=AN$4),$U34,NA()) -> -0.36948969 | AO34: =IF(OR($AB34=AO$5,$AB35=AO$5),$BG34,NA()) -> #N/A | AP34: =IF(OR($AB34=AP$5,$AB35=AP$5),$BG34,NA()) -> #N/A | AQ34: =IF(OR($AB34=AQ$5,$AB35=AQ$5),$BG34,NA()) -> #N/A | AR34: =IF(OR($AB34=AN$5,$AB35=AN$5),$BG34,NA()) -> #N/A | AT34: =A34 -> 37894 | AU34: =IF($V34="E",4,IF($V34="R",2,IF($V34="SD",3,1))) -> 2 | AV34: =IF($Z34="E",4,IF($Z34="R",2,IF($Z34="SD",3,1))) -> 2 | BG34: {=_xll.BDH($BG$3,"PX_LAST",$A34,$A34,"Days=A","Fill=P")} -> 206.86 | BH34: =BG34/BG33-1 -> -0.036516069 | BI34: =AB34 -> R | BJ34: =_xlfn.XLOOKUP(BI34,$BP$23:$BP$26,$BQ$23:$BQ$26) -> 1 | BK34: =BJ34*BH35 -> 0.070917529 | BL34: =BL33*(1+BK33) -> 92.983324 | BM34: =BM33*(1+BH34) -> 92.983324 | BN34: =BL34/BM34 -> 1
A35: 37925 | B35: =_xll.BDH(B$2,"PX_LAST",$A35,$A35,"Days=A","Fill=P") -> 99.3656 | C35: =$BQ$2*C34 + (1-$BQ$2)*B35 -> 99.392235 | D35: =(C35-AVERAGE(C16:C35))/AVEDEV(C16:C35) -> -1.6021611 | E35: 55.2 | F35: =$BQ$1*F34+(1-$BQ$1)*(E35-50) -> 1.4298922 | G35: 0.12 | H35: =$BQ$1*H34+(1-$BQ$1) * MAX(AVERAGE($G$4:$G$256)-3*STDEVA($G$4:$G$256),MIN(G35,AVERAGE($G$4:$G$256)+3*STDEVA($G$4:$G$256))) -> 0.0056821103 | I35: {=_xll.BDH(I$2,"PX_LAST",$A35,$A35,"Days=A","Fill=P")} -> 0.45 | J35: =$BQ$3*J34+(1-$BQ$3)*I35 -> -0.64909359 | K35: =(J35-MEDIAN(J16:J35))/AVEDEV(J16:J35) -> 1.7749346 | O35: {=_xll.BDH(O$3,"PX_LAST",$A35,$A35,"Days=A","Fill=P")} -> 71.4 | P35: =$BQ$5*P34+(1-$BQ$5)*O35 -> 23.356431 | T35: R | U35: =AVERAGE(D34,K35,N35,Q35) -> -0.0059223915 | V35: =IF(U35-U34>0,IF(U35>=0,"E","R"),IF(U35>=0,"SD","C")) -> R | W35: =U35-U34 -> 0.3635673 | X35: =IF(OR(ABS($U35-$U34)>$W$1),1,0) -> 1 | Y35: =$U35-$U34 -> 0.3635673 | Z35: =IF(ABS($U35-$U34)>AE35,V35,Z34) -> R | AA35: =IF(Z35<>V34,U35,AA34) -> -1.9312449 | AB35: =Z35 -> R | AC35: Quanti | AD35: =ABS(W35) -> 0.3635673 | AE35: 0.15 | AI35: 0 | AK35: =IF(OR($AB35=AK$4,$AB36=AK$4),$U35,NA()) -> -0.0059223915 | AL35: =IF(OR($AB35=AL$4,$AB36=AL$4),$U35,NA()) -> #N/A | AM35: =IF(OR($AB35=AM$4,$AB36=AM$4),$U35,NA()) -> #N/A | AN35: =IF(OR($AB35=AN$4,$AB36=AN$4),$U35,NA()) -> -0.0059223915 | AO35: =IF(OR($AB35=AO$5,$AB36=AO$5),$BG35,NA()) -> 221.53 | AP35: =IF(OR($AB35=AP$5,$AB36=AP$5),$BG35,NA()) -> #N/A | AQ35: =IF(OR($AB35=AQ$5,$AB36=AQ$5),$BG35,NA()) -> #N/A | AR35: =IF(OR($AB35=AN$5,$AB36=AN$5),$BG35,NA()) -> #N/A | AT35: =A35 -> 37925 | AU35: =IF($V35="E",4,IF($V35="R",2,IF($V35="SD",3,1))) -> 2 | AV35: =IF($Z35="E",4,IF($Z35="R",2,IF($Z35="SD",3,1))) -> 2 | BG35: {=_xll.BDH($BG$3,"PX_LAST",$A35,$A35,"Days=A","Fill=P")} -> 221.53 | BH35: =BG35/BG34-1 -> 0.070917529 | BI35: =AB35 -> R | BJ35: =_xlfn.XLOOKUP(BI35,$BP$23:$BP$26,$BQ$23:$BQ$26) -> 1 | BK35: =BJ35*BH36 -> 0.0079898885 | BL35: =BL34*(1+BK34) -> 99.577471 | BM35: =BM34*(1+BH35) -> 99.577471 | BN35: =BL35/BM35 -> 1
A36: 37953 | B36: =_xll.BDH(B$2,"PX_LAST",$A36,$A36,"Days=A","Fill=P") -> 99.3656 | C36: =$BQ$2*C35 + (1-$BQ$2)*B36 -> 99.390903 | D36: =(C36-AVERAGE(C17:C36))/AVEDEV(C17:C36) -> -1.4444711 | E36: 58.4 | F36: =$BQ$1*F35+(1-$BQ$1)*(E36-50) -> 2.8239138 | G36: 0.47 | H36: =$BQ$1*H35+(1-$BQ$1) * MAX(AVERAGE($G$4:$G$256)-3*STDEVA($G$4:$G$256),MIN(G36,AVERAGE($G$4:$G$256)+3*STDEVA($G$4:$G$256))) -> 0.098545688 | I36: {=_xll.BDH(I$2,"PX_LAST",$A36,$A36,"Days=A","Fill=P")} -> 0.514 | J36: =$BQ$3*J35+(1-$BQ$3)*I36 -> -0.59093891 | K36: =(J36-MEDIAN(J17:J36))/AVEDEV(J17:J36) -> 2.2423594 | O36: {=_xll.BDH(O$3,"PX_LAST",$A36,$A36,"Days=A","Fill=P")} -> 74.2 | P36: =$BQ$5*P35+(1-$BQ$5)*O36 -> 28.440788 | T36: E | U36: =AVERAGE(D35,K36,N36,Q36) -> 0.32009915 | V36: =IF(U36-U35>0,IF(U36>=0,"E","R"),IF(U36>=0,"SD","C")) -> E | W36: =U36-U35 -> 0.32602155 | X36: =IF(OR(ABS($U36-$U35)>$W$1),1,0) -> 1 | Y36: =$U36-$U35 -> 0.32602155 | Z36: =IF(ABS($U36-$U35)>AE36,V36,Z35) -> E | AA36: =IF(Z36<>V35,U36,AA35) -> 0.32009915 | AB36: =Z36 -> E | AC36: Quanti | AD36: =ABS(W36) -> 0.32602155 | AE36: 0.15 | AI36: 0 | AK36: =IF(OR($AB36=AK$4,$AB37=AK$4),$U36,NA()) -> 0.32009915 | AL36: =IF(OR($AB36=AL$4,$AB37=AL$4),$U36,NA()) -> #N/A | AM36: =IF(OR($AB36=AM$4,$AB37=AM$4),$U36,NA()) -> #N/A | AN36: =IF(OR($AB36=AN$4,$AB37=AN$4),$U36,NA()) -> #N/A | AO36: =IF(OR($AB36=AO$5,$AB37=AO$5),$BG36,NA()) -> 223.3 | AP36: =IF(OR($AB36=AP$5,$AB37=AP$5),$BG36,NA()) -> #N/A | AQ36: =IF(OR($AB36=AQ$5,$AB37=AQ$5),$BG36,NA()) -> #N/A | AR36: =IF(OR($AB36=AN$5,$AB37=AN$5),$BG36,NA()) -> #N/A | AT36: =A36 -> 37953 | AU36: =IF($V36="E",4,IF($V36="R",2,IF($V36="SD",3,1))) -> 4 | AV36: =IF($Z36="E",4,IF($Z36="R",2,IF($Z36="SD",3,1))) -> 4 | BG36: {=_xll.BDH($BG$3,"PX_LAST",$A36,$A36,"Days=A","Fill=P")} -> 223.3 | BH36: =BG36/BG35-1 -> 0.0079898885 | BI36: =AB36 -> E | BJ36: =_xlfn.XLOOKUP(BI36,$BP$23:$BP$26,$BQ$23:$BQ$26) -> 1 | BK36: =BJ36*BH37 -> 0.026914465 | BL36: =BL35*(1+BK35) -> 100.37308 | BM36: =BM35*(1+BH36) -> 100.37308 | BN36: =BL36/BM36 -> 1
A37: 37986 | B37: =_xll.BDH(B$2,"PX_LAST",$A37,$A37,"Days=A","Fill=P") -> 99.7013 | C37: =$BQ$2*C36 + (1-$BQ$2)*B37 -> 99.406423 | D37: =(C37-AVERAGE(C18:C37))/AVEDEV(C18:C37) -> -1.255666 | E37: 60.1 | F37: =$BQ$1*F36+(1-$BQ$1)*(E37-50) -> 4.279131 | G37: 0.02 | H37: =$BQ$1*H36+(1-$BQ$1) * MAX(AVERAGE($G$4:$G$256)-3*STDEVA($G$4:$G$256),MIN(G37,AVERAGE($G$4:$G$256)+3*STDEVA($G$4:$G$256))) -> 0.082836551 | I37: {=_xll.BDH(I$2,"PX_LAST",$A37,$A37,"Days=A","Fill=P")} -> 0.659 | J37: =$BQ$3*J36+(1-$BQ$3)*I37 -> -0.52844196 | K37: =(J37-MEDIAN(J18:J37))/AVEDEV(J18:J37) -> 2.6355651 | O37: {=_xll.BDH(O$3,"PX_LAST",$A37,$A37,"Days=A","Fill=P")} -> 54.1 | P37: =$BQ$5*P36+(1-$BQ$5)*O37 -> 31.006709 | T37: E | U37: =AVERAGE(D36,K37,N37,Q37) -> 0.595547 | V37: =IF(U37-U36>0,IF(U37>=0,"E","R"),IF(U37>=0,"SD","C")) -> E | W37: =U37-U36 -> 0.27544784 | X37: =IF(OR(ABS($U37-$U36)>$W$1),1,0) -> 0 | Y37: =$U37-$U36 -> 0.27544784 | Z37: =IF(ABS($U37-$U36)>AE37,V37,Z36) -> E | AA37: =IF(Z37<>V36,U37,AA36) -> 0.32009915 | AB37: =Z37 -> E | AC37: Quanti | AD37: =ABS(W37) -> 0.27544784 | AE37: 0.15 | AI37: 0 | AK37: =IF(OR($AB37=AK$4,$AB38=AK$4),$U37,NA()) -> 0.595547 | AL37: =IF(OR($AB37=AL$4,$AB38=AL$4),$U37,NA()) -> #N/A | AM37: =IF(OR($AB37=AM$4,$AB38=AM$4),$U37,NA()) -> #N/A | AN37: =IF(OR($AB37=AN$4,$AB38=AN$4),$U37,NA()) -> #N/A | AO37: =IF(OR($AB37=AO$5,$AB38=AO$5),$BG37,NA()) -> 229.31 | AP37: =IF(OR($AB37=AP$5,$AB38=AP$5),$BG37,NA()) -> #N/A | AQ37: =IF(OR($AB37=AQ$5,$AB38=AQ$5),$BG37,NA()) -> #N/A | AR37: =IF(OR($AB37=AN$5,$AB38=AN$5),$BG37,NA()) -> #N/A | AT37: =A37 -> 37986 | AU37: =IF($V37="E",4,IF($V37="R",2,IF($V37="SD",3,1))) -> 4 | AV37: =IF($Z37="E",4,IF($Z37="R",2,IF($Z37="SD",3,1))) -> 4 | BG37: {=_xll.BDH($BG$3,"PX_LAST",$A37,$A37,"Days=A","Fill=P")} -> 229.31 | BH37: =BG37/BG36-1 -> 0.026914465 | BI37: =AB37 -> E | BJ37: =_xlfn.XLOOKUP(BI37,$BP$23:$BP$26,$BQ$23:$BQ$26) -> 1 | BK37: =BJ37*BH38 -> 0.028345907 | BL37: =BL36*(1+BK36) -> 103.07457 | BM37: =BM36*(1+BH37) -> 103.07457 | BN37: =BL37/BM37 -> 1
A38: 38016 | B38: =_xll.BDH(B$2,"PX_LAST",$A38,$A38,"Days=A","Fill=P") -> 99.7013 | C38: =$BQ$2*C37 + (1-$BQ$2)*B38 -> 99.421167 | D38: =(C38-AVERAGE(C19:C38))/AVEDEV(C19:C38) -> -1.0905872 | E38: 60.8 | F38: =$BQ$1*F37+(1-$BQ$1)*(E38-50) -> 5.5833048 | G38: 0.05 | H38: =$BQ$1*H37+(1-$BQ$1) * MAX(AVERAGE($G$4:$G$256)-3*STDEVA($G$4:$G$256),MIN(G38,AVERAGE($G$4:$G$256)+3*STDEVA($G$4:$G$256))) -> 0.07626924 | I38: {=_xll.BDH(I$2,"PX_LAST",$A38,$A38,"Days=A","Fill=P")} -> 0.591 | J38: =$BQ$3*J37+(1-$BQ$3)*I38 -> -0.47246987 | K38: =(J38-MEDIAN(J19:J38))/AVEDEV(J19:J38) -> 2.8470764 | O38: {=_xll.BDH(O$3,"PX_LAST",$A38,$A38,"Days=A","Fill=P")} -> 37.8 | P38: =$BQ$5*P37+(1-$BQ$5)*O38 -> 31.686038 | T38: E | U38: =AVERAGE(D37,K38,N38,Q38) -> 0.7957052 | V38: =IF(U38-U37>0,IF(U38>=0,"E","R"),IF(U38>=0,"SD","C")) -> E | W38: =U38-U37 -> 0.2001582 | X38: =IF(OR(ABS($U38-$U37)>$W$1),1,0) -> 0 | Y38: =$U38-$U37 -> 0.2001582 | Z38: =IF(ABS($U38-$U37)>AE38,V38,Z37) -> E | AA38: =IF(Z38<>V37,U38,AA37) -> 0.32009915 | AB38: =Z38 -> E | AC38: Quanti | AD38: =ABS(W38) -> 0.2001582 | AE38: 0.15 | AI38: 0 | AK38: =IF(OR($AB38=AK$4,$AB39=AK$4),$U38,NA()) -> 0.7957052 | AL38: =IF(OR($AB38=AL$4,$AB39=AL$4),$U38,NA()) -> #N/A | AM38: =IF(OR($AB38=AM$4,$AB39=AM$4),$U38,NA()) -> #N/A | AN38: =IF(OR($AB38=AN$4,$AB39=AN$4),$U38,NA()) -> #N/A | AO38: =IF(OR($AB38=AO$5,$AB39=AO$5),$BG38,NA()) -> 235.81 | AP38: =IF(OR($AB38=AP$5,$AB39=AP$5),$BG38,NA()) -> #N/A | AQ38: =IF(OR($AB38=AQ$5,$AB39=AQ$5),$BG38,NA()) -> #N/A | AR38: =IF(OR($AB38=AN$5,$AB39=AN$5),$BG38,NA()) -> #N/A | AT38: =A38 -> 38016 | AU38: =IF($V38="E",4,IF($V38="R",2,IF($V38="SD",3,1))) -> 4 | AV38: =IF($Z38="E",4,IF($Z38="R",2,IF($Z38="SD",3,1))) -> 4 | BG38: {=_xll.BDH($BG$3,"PX_LAST",$A38,$A38,"Days=A","Fill=P")} -> 235.81 | BH38: =BG38/BG37-1 -> 0.028345907 | BI38: =AB38 -> E | BJ38: =_xlfn.XLOOKUP(BI38,$BP$23:$BP$26,$BQ$23:$BQ$26) -> 1 | BK38: =BJ38*BH39 -> 0.028751961 | BL38: =BL37*(1+BK37) -> 105.99631 | BM38: =BM37*(1+BH38) -> 105.99631 | BN38: =BL38/BM38 -> 1
... A43: 38168 | B43: =_xll.BDH(B$2,"PX_LAST",$A43,$A43,"Days=A","Fill=P") -> 99.9376 | C43: =$BQ$2*C42 + (1-$BQ$2)*B43 -> 99.528525 | D43: =(C43-AVERAGE(C24:C43))/AVEDEV(C24:C43) -> -0.059397592 | E43: 60.5 | F43: =$BQ$1*F42+(1-$BQ$1)*(E43-50) -> 9.0067853 | G43: -0.3 | H43: =$BQ$1*H42+(1-$BQ$1) * MAX(AVERAGE($G$4:$G$256)-3*STDEVA($G$4:$G$256),MIN(G43,AVERAGE($G$4:$G$256)+3*STDEVA($G$4:$G$256))) -> 0.1478015 | I43: {=_xll.BDH(I$2,"PX_LAST",$A43,$A43,"Days=A","Fill=P")} -> 0.774 | J43: =$BQ$3*J42+(1-$BQ$3)*I43 -> -0.22444607 | K43: =(J43-MEDIAN(J24:J43))/AVEDEV(J24:J43) -> 2.2334925 | O43: {=_xll.BDH(O$3,"PX_LAST",$A43,$A43,"Days=A","Fill=P")} -> -33.5 | P43: =$BQ$5*P42+(1-$BQ$5)*O43 -> 12.43753 | T43: E | U43: =AVERAGE(D42,K43,N43,Q43) -> 0.95116237 | V43: =IF(U43-U42>0,IF(U43>=0,"E","R"),IF(U43>=0,"SD","C")) -> E | W43: =U43-U42 -> 0.04289319 | X43: =IF(OR(ABS($U43-$U42)>$W$1),1,0) -> 0 | Y43: =$U43-$U42 -> 0.04289319 | Z43: =IF(ABS($U43-$U42)>AE43,V43,Z42) -> E | AA43: =IF(Z43<>V42,U43,AA42) -> 0.95116237 | AB43: =Z43 -> E | AC43: Quanti | AD43: =ABS(W43) -> 0.04289319 | AE43: 0.15 | AI43: 0 | AK43: =IF(OR($AB43=AK$4,$AB44=AK$4),$U43,NA()) -> 0.95116237 | AL43: =IF(OR($AB43=AL$4,$AB44=AL$4),$U43,NA()) -> #N/A | AM43: =IF(OR($AB43=AM$4,$AB44=AM$4),$U43,NA()) -> #N/A | AN43: =IF(OR($AB43=AN$4,$AB44=AN$4),$U43,NA()) -> #N/A | AO43: =IF(OR($AB43=AO$5,$AB44=AO$5),$BG43,NA()) -> 240.86 | AP43: =IF(OR($AB43=AP$5,$AB44=AP$5),$BG43,NA()) -> #N/A | AQ43: =IF(OR($AB43=AQ$5,$AB44=AQ$5),$BG43,NA()) -> #N/A | AR43: =IF(OR($AB43=AN$5,$AB44=AN$5),$BG43,NA()) -> #N/A | AT43: =A43 -> 38168 | AU43: =IF($V43="E",4,IF($V43="R",2,IF($V43="SD",3,1))) -> 4 | AV43: =IF($Z43="E",4,IF($Z43="R",2,IF($Z43="SD",3,1))) -> 4 | BG43: {=_xll.BDH($BG$3,"PX_LAST",$A43,$A43,"Days=A","Fill=P")} -> 240.86 | BH43: =BG43/BG42-1 -> 0.014788287 | BI43: =AB43 -> E | BJ43: =_xlfn.XLOOKUP(BI43,$BP$23:$BP$26,$BQ$23:$BQ$26) -> 1 | BK43: =BJ43*BH44 -> -0.018516981 | BL43: =BL42*(1+BK42) -> 108.26628 | BM43: =BM42*(1+BH43) -> 108.26628 | BN43: =BL43/BM43 -> 1
A44: 38198 | B44: =_xll.BDH(B$2,"PX_LAST",$A44,$A44,"Days=A","Fill=P") -> 99.9376 | C44: =$BQ$2*C43 + (1-$BQ$2)*B44 -> 99.548979 | D44: =(C44-AVERAGE(C25:C44))/AVEDEV(C25:C44) -> 0.30298735 | E44: 59.9 | F44: =$BQ$1*F43+(1-$BQ$1)*(E44-50) -> 9.1854283 | G44: 0.44 | H44: =$BQ$1*H43+(1-$BQ$1) * MAX(AVERAGE($G$4:$G$256)-3*STDEVA($G$4:$G$256),MIN(G44,AVERAGE($G$4:$G$256)+3*STDEVA($G$4:$G$256))) -> 0.2062412 | I44: {=_xll.BDH(I$2,"PX_LAST",$A44,$A44,"Days=A","Fill=P")} -> 0.703 | J44: =$BQ$3*J43+(1-$BQ$3)*I44 -> -0.17807377 | K44: =(J44-MEDIAN(J25:J44))/AVEDEV(J25:J44) -> 2.1184722 | O44: {=_xll.BDH(O$3,"PX_LAST",$A44,$A44,"Days=A","Fill=P")} -> 27.4 | P44: =$BQ$5*P43+(1-$BQ$5)*O44 -> 13.933777 | T44: E | U44: =AVERAGE(D43,K44,N44,Q44) -> 1.0295373 | V44: =IF(U44-U43>0,IF(U44>=0,"E","R"),IF(U44>=0,"SD","C")) -> E | W44: =U44-U43 -> 0.078374952 | X44: =IF(OR(ABS($U44-$U43)>$W$1),1,0) -> 0 | Y44: =$U44-$U43 -> 0.078374952 | Z44: =IF(ABS($U44-$U43)>AE44,V44,Z43) -> E | AA44: =IF(Z44<>V43,U44,AA43) -> 0.95116237 | AB44: =Z44 -> E | AC44: Quanti | AD44: =ABS(W44) -> 0.078374952 | AE44: =PERCENTILE(AD24:AD44,$Z$1) -> 0.12182271 | AI44: 0 | AK44: =IF(OR($AB44=AK$4,$AB45=AK$4),$U44,NA()) -> 1.0295373 | AL44: =IF(OR($AB44=AL$4,$AB45=AL$4),$U44,NA()) -> #N/A | AM44: =IF(OR($AB44=AM$4,$AB45=AM$4),$U44,NA()) -> #N/A | AN44: =IF(OR($AB44=AN$4,$AB45=AN$4),$U44,NA()) -> #N/A | AO44: =IF(OR($AB44=AO$5,$AB45=AO$5),$BG44,NA()) -> 236.4 | AP44: =IF(OR($AB44=AP$5,$AB45=AP$5),$BG44,NA()) -> #N/A | AQ44: =IF(OR($AB44=AQ$5,$AB45=AQ$5),$BG44,NA()) -> #N/A | AR44: =IF(OR($AB44=AN$5,$AB45=AN$5),$BG44,NA()) -> #N/A | AT44: =A44 -> 38198 | AU44: =IF($V44="E",4,IF($V44="R",2,IF($V44="SD",3,1))) -> 4 | AV44: =IF($Z44="E",4,IF($Z44="R",2,IF($Z44="SD",3,1))) -> 4 | BG44: {=_xll.BDH($BG$3,"PX_LAST",$A44,$A44,"Days=A","Fill=P")} -> 236.4 | BH44: =BG44/BG43-1 -> -0.018516981 | BI44: =AB44 -> E | BJ44: =_xlfn.XLOOKUP(BI44,$BP$23:$BP$26,$BQ$23:$BQ$26) -> 1 | BK44: =BJ44*BH45 -> -0.011717428 | BL44: =BL43*(1+BK43) -> 106.26152 | BM44: =BM43*(1+BH44) -> 106.26152 | BN44: =BL44/BM44 -> 1
A45: 38230 | B45: =_xll.BDH(B$2,"PX_LAST",$A45,$A45,"Days=A","Fill=P") -> 99.9941 | C45: =$BQ$2*C44 + (1-$BQ$2)*B45 -> 99.571235 | D45: =(C45-AVERAGE(C26:C45))/AVEDEV(C26:C45) -> 0.77993671 | E45: 58.5 | F45: =$BQ$1*F44+(1-$BQ$1)*(E45-50) -> 9.0483426 | G45: 0.3 | H45: =$BQ$1*H44+(1-$BQ$1) * MAX(AVERAGE($G$4:$G$256)-3*STDEVA($G$4:$G$256),MIN(G45,AVERAGE($G$4:$G$256)+3*STDEVA($G$4:$G$256))) -> 0.22499296 | I45: {=_xll.BDH(I$2,"PX_LAST",$A45,$A45,"Days=A","Fill=P")} -> 0.64 | J45: =$BQ$3*J44+(1-$BQ$3)*I45 -> -0.13717008 | K45: =(J45-MEDIAN(J26:J45))/AVEDEV(J26:J45) -> 1.9654116 | O45: {=_xll.BDH(O$3,"PX_LAST",$A45,$A45,"Days=A","Fill=P")} -> 6.2 | P45: =$BQ$5*P44+(1-$BQ$5)*O45 -> 13.160399 | T45: E | U45: =AVERAGE(D44,K45,N45,Q45) -> 1.1341995 | V45: =IF(U45-U44>0,IF(U45>=0,"E","R"),IF(U45>=0,"SD","C")) -> E | W45: =U45-U44 -> 0.10466217 | X45: =IF(OR(ABS($U45-$U44)>$W$1),1,0) -> 0 | Y45: =$U45-$U44 -> 0.10466217 | Z45: =IF(ABS($U45-$U44)>AE45,V45,Z44) -> E | AA45: =IF(Z45<>V44,U45,AA44) -> 0.95116237 | AB45: =Z45 -> E | AC45: Quanti | AD45: =ABS(W45) -> 0.10466217 | AE45: =PERCENTILE(AD25:AD45,$Z$1) -> 0.10466217 | AI45: 0 | AK45: =IF(OR($AB45=AK$4,$AB46=AK$4),$U45,NA()) -> 1.1341995 | AL45: =IF(OR($AB45=AL$4,$AB46=AL$4),$U45,NA()) -> 1.1341995 | AM45: =IF(OR($AB45=AM$4,$AB46=AM$4),$U45,NA()) -> #N/A | AN45: =IF(OR($AB45=AN$4,$AB46=AN$4),$U45,NA()) -> #N/A | AO45: =IF(OR($AB45=AO$5,$AB46=AO$5),$BG45,NA()) -> 233.63 | AP45: =IF(OR($AB45=AP$5,$AB46=AP$5),$BG45,NA()) -> 233.63 | AQ45: =IF(OR($AB45=AQ$5,$AB46=AQ$5),$BG45,NA()) -> #N/A | AR45: =IF(OR($AB45=AN$5,$AB46=AN$5),$BG45,NA()) -> #N/A | AT45: =A45 -> 38230 | AU45: =IF($V45="E",4,IF($V45="R",2,IF($V45="SD",3,1))) -> 4 | AV45: =IF($Z45="E",4,IF($Z45="R",2,IF($Z45="SD",3,1))) -> 4 | BG45: {=_xll.BDH($BG$3,"PX_LAST",$A45,$A45,"Days=A","Fill=P")} -> 233.63 | BH45: =BG45/BG44-1 -> -0.011717428 | BI45: =AB45 -> E | BJ45: =_xlfn.XLOOKUP(BI45,$BP$23:$BP$26,$BQ$23:$BQ$26) -> 1 | BK45: =BJ45*BH46 -> 0.017591919 | BL45: =BL44*(1+BK44) -> 105.01641 | BM45: =BM44*(1+BH45) -> 105.01641 | BN45: =BL45/BM45 -> 1
