Workbook

Sheet secto_us
A1: Date | B1: Automobiles & Parts | C1: Banks | D1: Basic Resources | E1: Chemicals | F1: Construction & Materials | G1: Financial Services | H1: Food & Beverage | I1: Health Care | J1: Industrial Goods & Services | K1: Insurance | L1: Media | M1: Energy | N1: Personal & Household Goods | O1: Real Estate | P1: Retail | Q1: Technology | R1: Telecommunications | S1: Travel & Leisure | T1: Utilities | U1: Total
A2: =Signals_US!B2 -> 39052 | B2: =0 -> 0 | C2: =IF(Signals_US!F2=1,Signals_US!Q2*Mapping!$E$3,IF(Signals_US!F2=-1,-Signals_US!R2*Mapping!$E$3,0)) -> 0 | D2: =IF(Signals_US!C2=1,Signals_US!Q2*Mapping!$E$4,IF(Signals_US!C2=-1,-Signals_US!R2*Mapping!$E$4,0)) -> 0 | E2: =IF(Signals_US!C2=1,Signals_US!Q2*Mapping!$E$5,IF(Signals_US!C2=-1,-Signals_US!R2*Mapping!$E$5,0)) -> 0 | F2: =IF(Signals_US!C2=1,Signals_US!Q2*Mapping!$E$6,IF(Signals_US!C2=-1,-Signals_US!R2*Mapping!$E$6,0)) -> 0 | G2: =IF(Signals_US!F2=1,Signals_US!Q2*Mapping!$E$7,IF(Signals_US!F2=-1,-Signals_US!R2*Mapping!$E$7,0)) -> 0 | H2: =IF(Signals_US!D2=1,Signals_US!Q2*Mapping!$E$8,IF(Signals_US!D2=-1,-Signals_US!R2*Mapping!$E$8,0)) -> 0 | I2: =IF(Signals_US!G2=1,Signals_US!Q2*Mapping!$E$9,IF(Signals_US!G2=-1,-Signals_US!R2*Mapping!$E$9,0)) -> 0 | J2: =IF(Signals_US!H2=1,Signals_US!Q2*Mapping!$E$10,IF(Signals_US!H2=-1,-Signals_US!R2*Mapping!$E$10,0)) -> 0 | K2: =IF(Signals_US!F2=1,Signals_US!Q2*Mapping!$E$11,IF(Signals_US!F2=-1,-Signals_US!R2*Mapping!$E$11,0)) -> 0 | L2: =IF(Signals_US!N2=1,Signals_US!Q2*Mapping!$E$12,IF(Signals_US!N2=-1,-Signals_US!R2*Mapping!$E$12,0)) -> 0 | M2: =IF(Signals_US!I2=1,Signals_US!Q2*Mapping!$E$13,IF(Signals_US!I2=-1,-Signals_US!R2*Mapping!$E$13,0)) -> 0 | N2: =0 -> 0 | O2: =0 -> 0 | P2: =IF(Signals_US!E2=1,Signals_US!Q2*Mapping!$E$16,IF(Signals_US!E2=-1,-Signals_US!R2*Mapping!$E$16,0)) -> 0 | Q2: =IF(Signals_US!J2=1,Signals_US!Q2*Mapping!$E$17,IF(Signals_US!J2=-1,-Signals_US!R2*Mapping!$E$17,0)) -> 0 | R2: =IF(Signals_US!K2=1,Signals_US!Q2*Mapping!$E$18,IF(Signals_US!K2=-1,-Signals_US!R2*Mapping!$E$18,0)) -> 0 | S2: =IF(Signals_US!M2=1,Signals_US!Q2*Mapping!$E$19,IF(Signals_US!M2=-1,-Signals_US!R2*Mapping!$E$19,0)) -> 0 | T2: =IF(Signals_US!L2=1,Signals_US!Q2*Mapping!$E$20,IF(Signals_US!L2=-1,-Signals_US!R2*Mapping!$E$20,0)) -> 0 | U2: =ROUND(SUM(B2:T2),12) -> 0
A3: =Signals_US!B3 -> 39083 | B3: =0 -> 0 | C3: =IF(Signals_US!F3=1,Signals_US!Q3*Mapping!$E$3,IF(Signals_US!F3=-1,-Signals_US!R3*Mapping!$E$3,0)) -> 0 | D3: =IF(Signals_US!C3=1,Signals_US!Q3*Mapping!$E$4,IF(Signals_US!C3=-1,-Signals_US!R3*Mapping!$E$4,0)) -> 0 | E3: =IF(Signals_US!C3=1,Signals_US!Q3*Mapping!$E$5,IF(Signals_US!C3=-1,-Signals_US!R3*Mapping!$E$5,0)) -> 0 | F3: =IF(Signals_US!C3=1,Signals_US!Q3*Mapping!$E$6,IF(Signals_US!C3=-1,-Signals_US!R3*Mapping!$E$6,0)) -> 0 | G3: =IF(Signals_US!F3=1,Signals_US!Q3*Mapping!$E$7,IF(Signals_US!F3=-1,-Signals_US!R3*Mapping!$E$7,0)) -> 0 | H3: =IF(Signals_US!D3=1,Signals_US!Q3*Mapping!$E$8,IF(Signals_US!D3=-1,-Signals_US!R3*Mapping!$E$8,0)) -> 0 | I3: =IF(Signals_US!G3=1,Signals_US!Q3*Mapping!$E$9,IF(Signals_US!G3=-1,-Signals_US!R3*Mapping!$E$9,0)) -> 0 | J3: =IF(Signals_US!H3=1,Signals_US!Q3*Mapping!$E$10,IF(Signals_US!H3=-1,-Signals_US!R3*Mapping!$E$10,0)) -> 0 | K3: =IF(Signals_US!F3=1,Signals_US!Q3*Mapping!$E$11,IF(Signals_US!F3=-1,-Signals_US!R3*Mapping!$E$11,0)) -> 0 | L3: =IF(Signals_US!N3=1,Signals_US!Q3*Mapping!$E$12,IF(Signals_US!N3=-1,-Signals_US!R3*Mapping!$E$12,0)) -> 0 | M3: =IF(Signals_US!I3=1,Signals_US!Q3*Mapping!$E$13,IF(Signals_US!I3=-1,-Signals_US!R3*Mapping!$E$13,0)) -> 0 | N3: =0 -> 0 | O3: =0 -> 0 | P3: =IF(Signals_US!E3=1,Signals_US!Q3*Mapping!$E$16,IF(Signals_US!E3=-1,-Signals_US!R3*Mapping!$E$16,0)) -> 0 | Q3: =IF(Signals_US!J3=1,Signals_US!Q3*Mapping!$E$17,IF(Signals_US!J3=-1,-Signals_US!R3*Mapping!$E$17,0)) -> 0 | R3: =IF(Signals_US!K3=1,Signals_US!Q3*Mapping!$E$18,IF(Signals_US!K3=-1,-Signals_US!R3*Mapping!$E$18,0)) -> 0 | S3: =IF(Signals_US!M3=1,Signals_US!Q3*Mapping!$E$19,IF(Signals_US!M3=-1,-Signals_US!R3*Mapping!$E$19,0)) -> 0 | T3: =IF(Signals_US!L3=1,Signals_US!Q3*Mapping!$E$20,IF(Signals_US!L3=-1,-Signals_US!R3*Mapping!$E$20,0)) -> 0 | U3: =ROUND(SUM(B3:T3),12) -> 0
A4: =Signals_US!B4 -> 39114 | B4: =0 -> 0 | C4: =IF(Signals_US!F4=1,Signals_US!Q4*Mapping!$E$3,IF(Signals_US!F4=-1,-Signals_US!R4*Mapping!$E$3,0)) -> 0 | D4: =IF(Signals_US!C4=1,Signals_US!Q4*Mapping!$E$4,IF(Signals_US!C4=-1,-Signals_US!R4*Mapping!$E$4,0)) -> 0 | E4: =IF(Signals_US!C4=1,Signals_US!Q4*Mapping!$E$5,IF(Signals_US!C4=-1,-Signals_US!R4*Mapping!$E$5,0)) -> 0 | F4: =IF(Signals_US!C4=1,Signals_US!Q4*Mapping!$E$6,IF(Signals_US!C4=-1,-Signals_US!R4*Mapping!$E$6,0)) -> 0 | G4: =IF(Signals_US!F4=1,Signals_US!Q4*Mapping!$E$7,IF(Signals_US!F4=-1,-Signals_US!R4*Mapping!$E$7,0)) -> 0 | H4: =IF(Signals_US!D4=1,Signals_US!Q4*Mapping!$E$8,IF(Signals_US!D4=-1,-Signals_US!R4*Mapping!$E$8,0)) -> 0 | I4: =IF(Signals_US!G4=1,Signals_US!Q4*Mapping!$E$9,IF(Signals_US!G4=-1,-Signals_US!R4*Mapping!$E$9,0)) -> 0 | J4: =IF(Signals_US!H4=1,Signals_US!Q4*Mapping!$E$10,IF(Signals_US!H4=-1,-Signals_US!R4*Mapping!$E$10,0)) -> 0 | K4: =IF(Signals_US!F4=1,Signals_US!Q4*Mapping!$E$11,IF(Signals_US!F4=-1,-Signals_US!R4*Mapping!$E$11,0)) -> 0 | L4: =IF(Signals_US!N4=1,Signals_US!Q4*Mapping!$E$12,IF(Signals_US!N4=-1,-Signals_US!R4*Mapping!$E$12,0)) -> 0 | M4: =IF(Signals_US!I4=1,Signals_US!Q4*Mapping!$E$13,IF(Signals_US!I4=-1,-Signals_US!R4*Mapping!$E$13,0)) -> 0 | N4: =0 -> 0 | O4: =0 -> 0 | P4: =IF(Signals_US!E4=1,Signals_US!Q4*Mapping!$E$16,IF(Signals_US!E4=-1,-Signals_US!R4*Mapping!$E$16,0)) -> 0 | Q4: =IF(Signals_US!J4=1,Signals_US!Q4*Mapping!$E$17,IF(Signals_US!J4=-1,-Signals_US!R4*Mapping!$E$17,0)) -> 0 | R4: =IF(Signals_US!K4=1,Signals_US!Q4*Mapping!$E$18,IF(Signals_US!K4=-1,-Signals_US!R4*Mapping!$E$18,0)) -> 0 | S4: =IF(Signals_US!M4=1,Signals_US!Q4*Mapping!$E$19,IF(Signals_US!M4=-1,-Signals_US!R4*Mapping!$E$19,0)) -> 0 | T4: =IF(Signals_US!L4=1,Signals_US!Q4*Mapping!$E$20,IF(Signals_US!L4=-1,-Signals_US!R4*Mapping!$E$20,0)) -> 0 | U4: =ROUND(SUM(B4:T4),12) -> 0
A5: =Signals_US!B5 -> 39142 | B5: =0 -> 0 | C5: =IF(Signals_US!F5=1,Signals_US!Q5*Mapping!$E$3,IF(Signals_US!F5=-1,-Signals_US!R5*Mapping!$E$3,0)) -> 0 | D5: =IF(Signals_US!C5=1,Signals_US!Q5*Mapping!$E$4,IF(Signals_US!C5=-1,-Signals_US!R5*Mapping!$E$4,0)) -> 0 | E5: =IF(Signals_US!C5=1,Signals_US!Q5*Mapping!$E$5,IF(Signals_US!C5=-1,-Signals_US!R5*Mapping!$E$5,0)) -> 0 | F5: =IF(Signals_US!C5=1,Signals_US!Q5*Mapping!$E$6,IF(Signals_US!C5=-1,-Signals_US!R5*Mapping!$E$6,0)) -> 0 | G5: =IF(Signals_US!F5=1,Signals_US!Q5*Mapping!$E$7,IF(Signals_US!F5=-1,-Signals_US!R5*Mapping!$E$7,0)) -> 0 | H5: =IF(Signals_US!D5=1,Signals_US!Q5*Mapping!$E$8,IF(Signals_US!D5=-1,-Signals_US!R5*Mapping!$E$8,0)) -> 0 | I5: =IF(Signals_US!G5=1,Signals_US!Q5*Mapping!$E$9,IF(Signals_US!G5=-1,-Signals_US!R5*Mapping!$E$9,0)) -> 0 | J5: =IF(Signals_US!H5=1,Signals_US!Q5*Mapping!$E$10,IF(Signals_US!H5=-1,-Signals_US!R5*Mapping!$E$10,0)) -> 0 | K5: =IF(Signals_US!F5=1,Signals_US!Q5*Mapping!$E$11,IF(Signals_US!F5=-1,-Signals_US!R5*Mapping!$E$11,0)) -> 0 | L5: =IF(Signals_US!N5=1,Signals_US!Q5*Mapping!$E$12,IF(Signals_US!N5=-1,-Signals_US!R5*Mapping!$E$12,0)) -> 0 | M5: =IF(Signals_US!I5=1,Signals_US!Q5*Mapping!$E$13,IF(Signals_US!I5=-1,-Signals_US!R5*Mapping!$E$13,0)) -> 0 | N5: =0 -> 0 | O5: =0 -> 0 | P5: =IF(Signals_US!E5=1,Signals_US!Q5*Mapping!$E$16,IF(Signals_US!E5=-1,-Signals_US!R5*Mapping!$E$16,0)) -> 0 | Q5: =IF(Signals_US!J5=1,Signals_US!Q5*Mapping!$E$17,IF(Signals_US!J5=-1,-Signals_US!R5*Mapping!$E$17,0)) -> 0 | R5: =IF(Signals_US!K5=1,Signals_US!Q5*Mapping!$E$18,IF(Signals_US!K5=-1,-Signals_US!R5*Mapping!$E$18,0)) -> 0 | S5: =IF(Signals_US!M5=1,Signals_US!Q5*Mapping!$E$19,IF(Signals_US!M5=-1,-Signals_US!R5*Mapping!$E$19,0)) -> 0 | T5: =IF(Signals_US!L5=1,Signals_US!Q5*Mapping!$E$20,IF(Signals_US!L5=-1,-Signals_US!R5*Mapping!$E$20,0)) -> 0 | U5: =ROUND(SUM(B5:T5),12) -> 0
A6: =Signals_US!B6 -> 39173 | B6: =0 -> 0 | C6: =IF(Signals_US!F6=1,Signals_US!Q6*Mapping!$E$3,IF(Signals_US!F6=-1,-Signals_US!R6*Mapping!$E$3,0)) -> 0 | D6: =IF(Signals_US!C6=1,Signals_US!Q6*Mapping!$E$4,IF(Signals_US!C6=-1,-Signals_US!R6*Mapping!$E$4,0)) -> 0 | E6: =IF(Signals_US!C6=1,Signals_US!Q6*Mapping!$E$5,IF(Signals_US!C6=-1,-Signals_US!R6*Mapping!$E$5,0)) -> 0 | F6: =IF(Signals_US!C6=1,Signals_US!Q6*Mapping!$E$6,IF(Signals_US!C6=-1,-Signals_US!R6*Mapping!$E$6,0)) -> 0 | G6: =IF(Signals_US!F6=1,Signals_US!Q6*Mapping!$E$7,IF(Signals_US!F6=-1,-Signals_US!R6*Mapping!$E$7,0)) -> 0 | H6: =IF(Signals_US!D6=1,Signals_US!Q6*Mapping!$E$8,IF(Signals_US!D6=-1,-Signals_US!R6*Mapping!$E$8,0)) -> 0 | I6: =IF(Signals_US!G6=1,Signals_US!Q6*Mapping!$E$9,IF(Signals_US!G6=-1,-Signals_US!R6*Mapping!$E$9,0)) -> 0 | J6: =IF(Signals_US!H6=1,Signals_US!Q6*Mapping!$E$10,IF(Signals_US!H6=-1,-Signals_US!R6*Mapping!$E$10,0)) -> 0 | K6: =IF(Signals_US!F6=1,Signals_US!Q6*Mapping!$E$11,IF(Signals_US!F6=-1,-Signals_US!R6*Mapping!$E$11,0)) -> 0 | L6: =IF(Signals_US!N6=1,Signals_US!Q6*Mapping!$E$12,IF(Signals_US!N6=-1,-Signals_US!R6*Mapping!$E$12,0)) -> 0 | M6: =IF(Signals_US!I6=1,Signals_US!Q6*Mapping!$E$13,IF(Signals_US!I6=-1,-Signals_US!R6*Mapping!$E$13,0)) -> 0 | N6: =0 -> 0 | O6: =0 -> 0 | P6: =IF(Signals_US!E6=1,Signals_US!Q6*Mapping!$E$16,IF(Signals_US!E6=-1,-Signals_US!R6*Mapping!$E$16,0)) -> 0 | Q6: =IF(Signals_US!J6=1,Signals_US!Q6*Mapping!$E$17,IF(Signals_US!J6=-1,-Signals_US!R6*Mapping!$E$17,0)) -> 0 | R6: =IF(Signals_US!K6=1,Signals_US!Q6*Mapping!$E$18,IF(Signals_US!K6=-1,-Signals_US!R6*Mapping!$E$18,0)) -> 0 | S6: =IF(Signals_US!M6=1,Signals_US!Q6*Mapping!$E$19,IF(Signals_US!M6=-1,-Signals_US!R6*Mapping!$E$19,0)) -> 0 | T6: =IF(Signals_US!L6=1,Signals_US!Q6*Mapping!$E$20,IF(Signals_US!L6=-1,-Signals_US!R6*Mapping!$E$20,0)) -> 0 | U6: =ROUND(SUM(B6:T6),12) -> 0
A7: =Signals_US!B7 -> 39203 | B7: =0 -> 0 | C7: =IF(Signals_US!F7=1,Signals_US!Q7*Mapping!$E$3,IF(Signals_US!F7=-1,-Signals_US!R7*Mapping!$E$3,0)) -> 0 | D7: =IF(Signals_US!C7=1,Signals_US!Q7*Mapping!$E$4,IF(Signals_US!C7=-1,-Signals_US!R7*Mapping!$E$4,0)) -> 0 | E7: =IF(Signals_US!C7=1,Signals_US!Q7*Mapping!$E$5,IF(Signals_US!C7=-1,-Signals_US!R7*Mapping!$E$5,0)) -> 0 | F7: =IF(Signals_US!C7=1,Signals_US!Q7*Mapping!$E$6,IF(Signals_US!C7=-1,-Signals_US!R7*Mapping!$E$6,0)) -> 0 | G7: =IF(Signals_US!F7=1,Signals_US!Q7*Mapping!$E$7,IF(Signals_US!F7=-1,-Signals_US!R7*Mapping!$E$7,0)) -> 0 | H7: =IF(Signals_US!D7=1,Signals_US!Q7*Mapping!$E$8,IF(Signals_US!D7=-1,-Signals_US!R7*Mapping!$E$8,0)) -> 0 | I7: =IF(Signals_US!G7=1,Signals_US!Q7*Mapping!$E$9,IF(Signals_US!G7=-1,-Signals_US!R7*Mapping!$E$9,0)) -> 0 | J7: =IF(Signals_US!H7=1,Signals_US!Q7*Mapping!$E$10,IF(Signals_US!H7=-1,-Signals_US!R7*Mapping!$E$10,0)) -> 0 | K7: =IF(Signals_US!F7=1,Signals_US!Q7*Mapping!$E$11,IF(Signals_US!F7=-1,-Signals_US!R7*Mapping!$E$11,0)) -> 0 | L7: =IF(Signals_US!N7=1,Signals_US!Q7*Mapping!$E$12,IF(Signals_US!N7=-1,-Signals_US!R7*Mapping!$E$12,0)) -> 0 | M7: =IF(Signals_US!I7=1,Signals_US!Q7*Mapping!$E$13,IF(Signals_US!I7=-1,-Signals_US!R7*Mapping!$E$13,0)) -> 0 | N7: =0 -> 0 | O7: =0 -> 0 | P7: =IF(Signals_US!E7=1,Signals_US!Q7*Mapping!$E$16,IF(Signals_US!E7=-1,-Signals_US!R7*Mapping!$E$16,0)) -> 0 | Q7: =IF(Signals_US!J7=1,Signals_US!Q7*Mapping!$E$17,IF(Signals_US!J7=-1,-Signals_US!R7*Mapping!$E$17,0)) -> 0 | R7: =IF(Signals_US!K7=1,Signals_US!Q7*Mapping!$E$18,IF(Signals_US!K7=-1,-Signals_US!R7*Mapping!$E$18,0)) -> 0 | S7: =IF(Signals_US!M7=1,Signals_US!Q7*Mapping!$E$19,IF(Signals_US!M7=-1,-Signals_US!R7*Mapping!$E$19,0)) -> 0 | T7: =IF(Signals_US!L7=1,Signals_US!Q7*Mapping!$E$20,IF(Signals_US!L7=-1,-Signals_US!R7*Mapping!$E$20,0)) -> 0 | U7: =ROUND(SUM(B7:T7),12) -> 0
A8: =Signals_US!B8 -> 39234 | B8: =0 -> 0 | C8: =IF(Signals_US!F8=1,Signals_US!Q8*Mapping!$E$3,IF(Signals_US!F8=-1,-Signals_US!R8*Mapping!$E$3,0)) -> 0 | D8: =IF(Signals_US!C8=1,Signals_US!Q8*Mapping!$E$4,IF(Signals_US!C8=-1,-Signals_US!R8*Mapping!$E$4,0)) -> 0 | E8: =IF(Signals_US!C8=1,Signals_US!Q8*Mapping!$E$5,IF(Signals_US!C8=-1,-Signals_US!R8*Mapping!$E$5,0)) -> 0 | F8: =IF(Signals_US!C8=1,Signals_US!Q8*Mapping!$E$6,IF(Signals_US!C8=-1,-Signals_US!R8*Mapping!$E$6,0)) -> 0 | G8: =IF(Signals_US!F8=1,Signals_US!Q8*Mapping!$E$7,IF(Signals_US!F8=-1,-Signals_US!R8*Mapping!$E$7,0)) -> 0 | H8: =IF(Signals_US!D8=1,Signals_US!Q8*Mapping!$E$8,IF(Signals_US!D8=-1,-Signals_US!R8*Mapping!$E$8,0)) -> 0 | I8: =IF(Signals_US!G8=1,Signals_US!Q8*Mapping!$E$9,IF(Signals_US!G8=-1,-Signals_US!R8*Mapping!$E$9,0)) -> 0 | J8: =IF(Signals_US!H8=1,Signals_US!Q8*Mapping!$E$10,IF(Signals_US!H8=-1,-Signals_US!R8*Mapping!$E$10,0)) -> 0 | K8: =IF(Signals_US!F8=1,Signals_US!Q8*Mapping!$E$11,IF(Signals_US!F8=-1,-Signals_US!R8*Mapping!$E$11,0)) -> 0 | L8: =IF(Signals_US!N8=1,Signals_US!Q8*Mapping!$E$12,IF(Signals_US!N8=-1,-Signals_US!R8*Mapping!$E$12,0)) -> 0 | M8: =IF(Signals_US!I8=1,Signals_US!Q8*Mapping!$E$13,IF(Signals_US!I8=-1,-Signals_US!R8*Mapping!$E$13,0)) -> 0 | N8: =0 -> 0 | O8: =0 -> 0 | P8: =IF(Signals_US!E8=1,Signals_US!Q8*Mapping!$E$16,IF(Signals_US!E8=-1,-Signals_US!R8*Mapping!$E$16,0)) -> 0 | Q8: =IF(Signals_US!J8=1,Signals_US!Q8*Mapping!$E$17,IF(Signals_US!J8=-1,-Signals_US!R8*Mapping!$E$17,0)) -> 0 | R8: =IF(Signals_US!K8=1,Signals_US!Q8*Mapping!$E$18,IF(Signals_US!K8=-1,-Signals_US!R8*Mapping!$E$18,0)) -> 0 | S8: =IF(Signals_US!M8=1,Signals_US!Q8*Mapping!$E$19,IF(Signals_US!M8=-1,-Signals_US!R8*Mapping!$E$19,0)) -> 0 | T8: =IF(Signals_US!L8=1,Signals_US!Q8*Mapping!$E$20,IF(Signals_US!L8=-1,-Signals_US!R8*Mapping!$E$20,0)) -> 0 | U8: =ROUND(SUM(B8:T8),12) -> 0
A9: =Signals_US!B9 -> 39264 | B9: =0 -> 0 | C9: =IF(Signals_US!F9=1,Signals_US!Q9*Mapping!$E$3,IF(Signals_US!F9=-1,-Signals_US!R9*Mapping!$E$3,0)) -> 0 | D9: =IF(Signals_US!C9=1,Signals_US!Q9*Mapping!$E$4,IF(Signals_US!C9=-1,-Signals_US!R9*Mapping!$E$4,0)) -> 0 | E9: =IF(Signals_US!C9=1,Signals_US!Q9*Mapping!$E$5,IF(Signals_US!C9=-1,-Signals_US!R9*Mapping!$E$5,0)) -> 0 | F9: =IF(Signals_US!C9=1,Signals_US!Q9*Mapping!$E$6,IF(Signals_US!C9=-1,-Signals_US!R9*Mapping!$E$6,0)) -> 0 | G9: =IF(Signals_US!F9=1,Signals_US!Q9*Mapping!$E$7,IF(Signals_US!F9=-1,-Signals_US!R9*Mapping!$E$7,0)) -> 0 | H9: =IF(Signals_US!D9=1,Signals_US!Q9*Mapping!$E$8,IF(Signals_US!D9=-1,-Signals_US!R9*Mapping!$E$8,0)) -> 0 | I9: =IF(Signals_US!G9=1,Signals_US!Q9*Mapping!$E$9,IF(Signals_US!G9=-1,-Signals_US!R9*Mapping!$E$9,0)) -> 0 | J9: =IF(Signals_US!H9=1,Signals_US!Q9*Mapping!$E$10,IF(Signals_US!H9=-1,-Signals_US!R9*Mapping!$E$10,0)) -> 0 | K9: =IF(Signals_US!F9=1,Signals_US!Q9*Mapping!$E$11,IF(Signals_US!F9=-1,-Signals_US!R9*Mapping!$E$11,0)) -> 0 | L9: =IF(Signals_US!N9=1,Signals_US!Q9*Mapping!$E$12,IF(Signals_US!N9=-1,-Signals_US!R9*Mapping!$E$12,0)) -> 0 | M9: =IF(Signals_US!I9=1,Signals_US!Q9*Mapping!$E$13,IF(Signals_US!I9=-1,-Signals_US!R9*Mapping!$E$13,0)) -> 0 | N9: =0 -> 0 | O9: =0 -> 0 | P9: =IF(Signals_US!E9=1,Signals_US!Q9*Mapping!$E$16,IF(Signals_US!E9=-1,-Signals_US!R9*Mapping!$E$16,0)) -> 0 | Q9: =IF(Signals_US!J9=1,Signals_US!Q9*Mapping!$E$17,IF(Signals_US!J9=-1,-Signals_US!R9*Mapping!$E$17,0)) -> 0 | R9: =IF(Signals_US!K9=1,Signals_US!Q9*Mapping!$E$18,IF(Signals_US!K9=-1,-Signals_US!R9*Mapping!$E$18,0)) -> 0 | S9: =IF(Signals_US!M9=1,Signals_US!Q9*Mapping!$E$19,IF(Signals_US!M9=-1,-Signals_US!R9*Mapping!$E$19,0)) -> 0 | T9: =IF(Signals_US!L9=1,Signals_US!Q9*Mapping!$E$20,IF(Signals_US!L9=-1,-Signals_US!R9*Mapping!$E$20,0)) -> 0 | U9: =ROUND(SUM(B9:T9),12) -> 0
A10: =Signals_US!B10 -> 39295 | B10: =0 -> 0 | C10: =IF(Signals_US!F10=1,Signals_US!Q10*Mapping!$E$3,IF(Signals_US!F10=-1,-Signals_US!R10*Mapping!$E$3,0)) -> 0 | D10: =IF(Signals_US!C10=1,Signals_US!Q10*Mapping!$E$4,IF(Signals_US!C10=-1,-Signals_US!R10*Mapping!$E$4,0)) -> 0 | E10: =IF(Signals_US!C10=1,Signals_US!Q10*Mapping!$E$5,IF(Signals_US!C10=-1,-Signals_US!R10*Mapping!$E$5,0)) -> 0 | F10: =IF(Signals_US!C10=1,Signals_US!Q10*Mapping!$E$6,IF(Signals_US!C10=-1,-Signals_US!R10*Mapping!$E$6,0)) -> 0 | G10: =IF(Signals_US!F10=1,Signals_US!Q10*Mapping!$E$7,IF(Signals_US!F10=-1,-Signals_US!R10*Mapping!$E$7,0)) -> 0 | H10: =IF(Signals_US!D10=1,Signals_US!Q10*Mapping!$E$8,IF(Signals_US!D10=-1,-Signals_US!R10*Mapping!$E$8,0)) -> 0 | I10: =IF(Signals_US!G10=1,Signals_US!Q10*Mapping!$E$9,IF(Signals_US!G10=-1,-Signals_US!R10*Mapping!$E$9,0)) -> 0 | J10: =IF(Signals_US!H10=1,Signals_US!Q10*Mapping!$E$10,IF(Signals_US!H10=-1,-Signals_US!R10*Mapping!$E$10,0)) -> 0 | K10: =IF(Signals_US!F10=1,Signals_US!Q10*Mapping!$E$11,IF(Signals_US!F10=-1,-Signals_US!R10*Mapping!$E$11,0)) -> 0 | L10: =IF(Signals_US!N10=1,Signals_US!Q10*Mapping!$E$12,IF(Signals_US!N10=-1,-Signals_US!R10*Mapping!$E$12,0)) -> 0 | M10: =IF(Signals_US!I10=1,Signals_US!Q10*Mapping!$E$13,IF(Signals_US!I10=-1,-Signals_US!R10*Mapping!$E$13,0)) -> 0 | N10: =0 -> 0 | O10: =0 -> 0 | P10: =IF(Signals_US!E10=1,Signals_US!Q10*Mapping!$E$16,IF(Signals_US!E10=-1,-Signals_US!R10*Mapping!$E$16,0)) -> 0 | Q10: =IF(Signals_US!J10=1,Signals_US!Q10*Mapping!$E$17,IF(Signals_US!J10=-1,-Signals_US!R10*Mapping!$E$17,0)) -> 0 | R10: =IF(Signals_US!K10=1,Signals_US!Q10*Mapping!$E$18,IF(Signals_US!K10=-1,-Signals_US!R10*Mapping!$E$18,0)) -> 0 | S10: =IF(Signals_US!M10=1,Signals_US!Q10*Mapping!$E$19,IF(Signals_US!M10=-1,-Signals_US!R10*Mapping!$E$19,0)) -> 0 | T10: =IF(Signals_US!L10=1,Signals_US!Q10*Mapping!$E$20,IF(Signals_US!L10=-1,-Signals_US!R10*Mapping!$E$20,0)) -> 0 | U10: =ROUND(SUM(B10:T10),12) -> 0
A11: =Signals_US!B11 -> 39326 | B11: =0 -> 0 | C11: =IF(Signals_US!F11=1,Signals_US!Q11*Mapping!$E$3,IF(Signals_US!F11=-1,-Signals_US!R11*Mapping!$E$3,0)) -> 0 | D11: =IF(Signals_US!C11=1,Signals_US!Q11*Mapping!$E$4,IF(Signals_US!C11=-1,-Signals_US!R11*Mapping!$E$4,0)) -> 0 | E11: =IF(Signals_US!C11=1,Signals_US!Q11*Mapping!$E$5,IF(Signals_US!C11=-1,-Signals_US!R11*Mapping!$E$5,0)) -> 0 | F11: =IF(Signals_US!C11=1,Signals_US!Q11*Mapping!$E$6,IF(Signals_US!C11=-1,-Signals_US!R11*Mapping!$E$6,0)) -> 0 | G11: =IF(Signals_US!F11=1,Signals_US!Q11*Mapping!$E$7,IF(Signals_US!F11=-1,-Signals_US!R11*Mapping!$E$7,0)) -> 0 | H11: =IF(Signals_US!D11=1,Signals_US!Q11*Mapping!$E$8,IF(Signals_US!D11=-1,-Signals_US!R11*Mapping!$E$8,0)) -> 0 | I11: =IF(Signals_US!G11=1,Signals_US!Q11*Mapping!$E$9,IF(Signals_US!G11=-1,-Signals_US!R11*Mapping!$E$9,0)) -> 0 | J11: =IF(Signals_US!H11=1,Signals_US!Q11*Mapping!$E$10,IF(Signals_US!H11=-1,-Signals_US!R11*Mapping!$E$10,0)) -> 0 | K11: =IF(Signals_US!F11=1,Signals_US!Q11*Mapping!$E$11,IF(Signals_US!F11=-1,-Signals_US!R11*Mapping!$E$11,0)) -> 0 | L11: =IF(Signals_US!N11=1,Signals_US!Q11*Mapping!$E$12,IF(Signals_US!N11=-1,-Signals_US!R11*Mapping!$E$12,0)) -> 0 | M11: =IF(Signals_US!I11=1,Signals_US!Q11*Mapping!$E$13,IF(Signals_US!I11=-1,-Signals_US!R11*Mapping!$E$13,0)) -> 0 | N11: =0 -> 0 | O11: =0 -> 0 | P11: =IF(Signals_US!E11=1,Signals_US!Q11*Mapping!$E$16,IF(Signals_US!E11=-1,-Signals_US!R11*Mapping!$E$16,0)) -> 0 | Q11: =IF(Signals_US!J11=1,Signals_US!Q11*Mapping!$E$17,IF(Signals_US!J11=-1,-Signals_US!R11*Mapping!$E$17,0)) -> 0 | R11: =IF(Signals_US!K11=1,Signals_US!Q11*Mapping!$E$18,IF(Signals_US!K11=-1,-Signals_US!R11*Mapping!$E$18,0)) -> 0 | S11: =IF(Signals_US!M11=1,Signals_US!Q11*Mapping!$E$19,IF(Signals_US!M11=-1,-Signals_US!R11*Mapping!$E$19,0)) -> 0 | T11: =IF(Signals_US!L11=1,Signals_US!Q11*Mapping!$E$20,IF(Signals_US!L11=-1,-Signals_US!R11*Mapping!$E$20,0)) -> 0 | U11: =ROUND(SUM(B11:T11),12) -> 0
A12: =Signals_US!B12 -> 39356 | B12: =0 -> 0 | C12: =IF(Signals_US!F12=1,Signals_US!Q12*Mapping!$E$3,IF(Signals_US!F12=-1,-Signals_US!R12*Mapping!$E$3,0)) -> 0 | D12: =IF(Signals_US!C12=1,Signals_US!Q12*Mapping!$E$4,IF(Signals_US!C12=-1,-Signals_US!R12*Mapping!$E$4,0)) -> 0 | E12: =IF(Signals_US!C12=1,Signals_US!Q12*Mapping!$E$5,IF(Signals_US!C12=-1,-Signals_US!R12*Mapping!$E$5,0)) -> 0 | F12: =IF(Signals_US!C12=1,Signals_US!Q12*Mapping!$E$6,IF(Signals_US!C12=-1,-Signals_US!R12*Mapping!$E$6,0)) -> 0 | G12: =IF(Signals_US!F12=1,Signals_US!Q12*Mapping!$E$7,IF(Signals_US!F12=-1,-Signals_US!R12*Mapping!$E$7,0)) -> 0 | H12: =IF(Signals_US!D12=1,Signals_US!Q12*Mapping!$E$8,IF(Signals_US!D12=-1,-Signals_US!R12*Mapping!$E$8,0)) -> 0 | I12: =IF(Signals_US!G12=1,Signals_US!Q12*Mapping!$E$9,IF(Signals_US!G12=-1,-Signals_US!R12*Mapping!$E$9,0)) -> 0 | J12: =IF(Signals_US!H12=1,Signals_US!Q12*Mapping!$E$10,IF(Signals_US!H12=-1,-Signals_US!R12*Mapping!$E$10,0)) -> 0 | K12: =IF(Signals_US!F12=1,Signals_US!Q12*Mapping!$E$11,IF(Signals_US!F12=-1,-Signals_US!R12*Mapping!$E$11,0)) -> 0 | L12: =IF(Signals_US!N12=1,Signals_US!Q12*Mapping!$E$12,IF(Signals_US!N12=-1,-Signals_US!R12*Mapping!$E$12,0)) -> 0 | M12: =IF(Signals_US!I12=1,Signals_US!Q12*Mapping!$E$13,IF(Signals_US!I12=-1,-Signals_US!R12*Mapping!$E$13,0)) -> 0 | N12: =0 -> 0 | O12: =0 -> 0 | P12: =IF(Signals_US!E12=1,Signals_US!Q12*Mapping!$E$16,IF(Signals_US!E12=-1,-Signals_US!R12*Mapping!$E$16,0)) -> 0 | Q12: =IF(Signals_US!J12=1,Signals_US!Q12*Mapping!$E$17,IF(Signals_US!J12=-1,-Signals_US!R12*Mapping!$E$17,0)) -> 0 | R12: =IF(Signals_US!K12=1,Signals_US!Q12*Mapping!$E$18,IF(Signals_US!K12=-1,-Signals_US!R12*Mapping!$E$18,0)) -> 0 | S12: =IF(Signals_US!M12=1,Signals_US!Q12*Mapping!$E$19,IF(Signals_US!M12=-1,-Signals_US!R12*Mapping!$E$19,0)) -> 0 | T12: =IF(Signals_US!L12=1,Signals_US!Q12*Mapping!$E$20,IF(Signals_US!L12=-1,-Signals_US!R12*Mapping!$E$20,0)) -> 0 | U12: =ROUND(SUM(B12:T12),12) -> 0
A13: =Signals_US!B13 -> 39387 | B13: =0 -> 0 | C13: =IF(Signals_US!F13=1,Signals_US!Q13*Mapping!$E$3,IF(Signals_US!F13=-1,-Signals_US!R13*Mapping!$E$3,0)) -> -0.016666667 | D13: =IF(Signals_US!C13=1,Signals_US!Q13*Mapping!$E$4,IF(Signals_US!C13=-1,-Signals_US!R13*Mapping!$E$4,0)) -> 0.016666667 | E13: =IF(Signals_US!C13=1,Signals_US!Q13*Mapping!$E$5,IF(Signals_US!C13=-1,-Signals_US!R13*Mapping!$E$5,0)) -> 0.016666667 | F13: =IF(Signals_US!C13=1,Signals_US!Q13*Mapping!$E$6,IF(Signals_US!C13=-1,-Signals_US!R13*Mapping!$E$6,0)) -> 0.016666667 | G13: =IF(Signals_US!F13=1,Signals_US!Q13*Mapping!$E$7,IF(Signals_US!F13=-1,-Signals_US!R13*Mapping!$E$7,0)) -> -0.016666667 | H13: =IF(Signals_US!D13=1,Signals_US!Q13*Mapping!$E$8,IF(Signals_US!D13=-1,-Signals_US!R13*Mapping!$E$8,0)) -> 0 | I13: =IF(Signals_US!G13=1,Signals_US!Q13*Mapping!$E$9,IF(Signals_US!G13=-1,-Signals_US!R13*Mapping!$E$9,0)) -> 0 | J13: =IF(Signals_US!H13=1,Signals_US!Q13*Mapping!$E$10,IF(Signals_US!H13=-1,-Signals_US!R13*Mapping!$E$10,0)) -> 0 | K13: =IF(Signals_US!F13=1,Signals_US!Q13*Mapping!$E$11,IF(Signals_US!F13=-1,-Signals_US!R13*Mapping!$E$11,0)) -> -0.016666667 | L13: =IF(Signals_US!N13=1,Signals_US!Q13*Mapping!$E$12,IF(Signals_US!N13=-1,-Signals_US!R13*Mapping!$E$12,0)) -> -0.05 | M13: =IF(Signals_US!I13=1,Signals_US!Q13*Mapping!$E$13,IF(Signals_US!I13=-1,-Signals_US!R13*Mapping!$E$13,0)) -> 0.05 | N13: =0 -> 0 | O13: =0 -> 0 | P13: =IF(Signals_US!E13=1,Signals_US!Q13*Mapping!$E$16,IF(Signals_US!E13=-1,-Signals_US!R13*Mapping!$E$16,0)) -> -0.05 | Q13: =IF(Signals_US!J13=1,Signals_US!Q13*Mapping!$E$17,IF(Signals_US!J13=-1,-Signals_US!R13*Mapping!$E$17,0)) -> 0.05 | R13: =IF(Signals_US!K13=1,Signals_US!Q13*Mapping!$E$18,IF(Signals_US!K13=-1,-Signals_US!R13*Mapping!$E$18,0)) -> 0 | S13: =IF(Signals_US!M13=1,Signals_US!Q13*Mapping!$E$19,IF(Signals_US!M13=-1,-Signals_US!R13*Mapping!$E$19,0)) -> 0 | T13: =IF(Signals_US!L13=1,Signals_US!Q13*Mapping!$E$20,IF(Signals_US!L13=-1,-Signals_US!R13*Mapping!$E$20,0)) -> 0 | U13: =ROUND(SUM(B13:T13),12) -> 0
... A240: =Signals_US!B240 -> 46296 | B240: =0 -> 0 | C240: =IF(Signals_US!F240=1,Signals_US!Q240*Mapping!$E$3,IF(Signals_US!F240=-1,-Signals_US!R240*Mapping!$E$3,0)) -> 0.016666667 | D240: =IF(Signals_US!C240=1,Signals_US!Q240*Mapping!$E$4,IF(Signals_US!C240=-1,-Signals_US!R240*Mapping!$E$4,0)) -> 0.016666667 | E240: =IF(Signals_US!C240=1,Signals_US!Q240*Mapping!$E$5,IF(Signals_US!C240=-1,-Signals_US!R240*Mapping!$E$5,0)) -> 0.016666667 | F240: =IF(Signals_US!C240=1,Signals_US!Q240*Mapping!$E$6,IF(Signals_US!C240=-1,-Signals_US!R240*Mapping!$E$6,0)) -> 0.016666667 | G240: =IF(Signals_US!F240=1,Signals_US!Q240*Mapping!$E$7,IF(Signals_US!F240=-1,-Signals_US!R240*Mapping!$E$7,0)) -> 0.016666667 | H240: =IF(Signals_US!D240=1,Signals_US!Q240*Mapping!$E$8,IF(Signals_US!D240=-1,-Signals_US!R240*Mapping!$E$8,0)) -> -0.05 | I240: =IF(Signals_US!G240=1,Signals_US!Q240*Mapping!$E$9,IF(Signals_US!G240=-1,-Signals_US!R240*Mapping!$E$9,0)) -> 0 | J240: =IF(Signals_US!H240=1,Signals_US!Q240*Mapping!$E$10,IF(Signals_US!H240=-1,-Signals_US!R240*Mapping!$E$10,0)) -> 0 | K240: =IF(Signals_US!F240=1,Signals_US!Q240*Mapping!$E$11,IF(Signals_US!F240=-1,-Signals_US!R240*Mapping!$E$11,0)) -> 0.016666667 | L240: =IF(Signals_US!N240=1,Signals_US!Q240*Mapping!$E$12,IF(Signals_US!N240=-1,-Signals_US!R240*Mapping!$E$12,0)) -> 0 | M240: =IF(Signals_US!I240=1,Signals_US!Q240*Mapping!$E$13,IF(Signals_US!I240=-1,-Signals_US!R240*Mapping!$E$13,0)) -> 0 | N240: =0 -> 0 | O240: =0 -> 0 | P240: =IF(Signals_US!E240=1,Signals_US!Q240*Mapping!$E$16,IF(Signals_US!E240=-1,-Signals_US!R240*Mapping!$E$16,0)) -> 0 | Q240: =IF(Signals_US!J240=1,Signals_US!Q240*Mapping!$E$17,IF(Signals_US!J240=-1,-Signals_US!R240*Mapping!$E$17,0)) -> 0.05 | R240: =IF(Signals_US!K240=1,Signals_US!Q240*Mapping!$E$18,IF(Signals_US!K240=-1,-Signals_US!R240*Mapping!$E$18,0)) -> -0.05 | S240: =IF(Signals_US!M240=1,Signals_US!Q240*Mapping!$E$19,IF(Signals_US!M240=-1,-Signals_US!R240*Mapping!$E$19,0)) -> 0 | T240: =IF(Signals_US!L240=1,Signals_US!Q240*Mapping!$E$20,IF(Signals_US!L240=-1,-Signals_US!R240*Mapping!$E$20,0)) -> -0.05 | U240: =ROUND(SUM(B240:T240),12) -> 0

Sheet secto_eu
A1: Date | B1: Automobiles & Parts | C1: Banks | D1: Basic Resources | E1: Chemicals | F1: Construction & Materials | G1: Financial Services | H1: Food & Beverage | I1: Health Care | J1: Industrial Goods & Services | K1: Insurance | L1: Media | M1: Energy | N1: Personal & Household Goods | O1: Real Estate | P1: Retail | Q1: Technology | R1: Telecommunications | S1: Travel & Leisure | T1: Utilities | U1: Total
A2: =Signals_EU!B2 -> 39052 | B2: =IF(Signals_EU!O2=1,Signals_EU!R2*Mapping!$C$2,IF(Signals_EU!O2=-1,-Signals_EU!S2*Mapping!$C$2,0)) -> 0 | C2: =IF(Signals_EU!F2=1,Signals_EU!R2*Mapping!$C$3,IF(Signals_EU!F2=-1,-Signals_EU!S2*Mapping!$C$3,0)) -> 0 | D2: =IF(Signals_EU!C2=1,Signals_EU!R2*Mapping!$C$4,IF(Signals_EU!C2=-1,-Signals_EU!S2*Mapping!$C$4,0)) -> 0 | E2: =IF(Signals_EU!C2=1,Signals_EU!R2*Mapping!$C$5,IF(Signals_EU!C2=-1,-Signals_EU!S2*Mapping!$C$5,0)) -> 0 | F2: =IF(Signals_EU!H2=1,Signals_EU!R2*Mapping!$C$6,IF(Signals_EU!H2=-1,-Signals_EU!S2*Mapping!$C$6,0)) -> 0 | G2: =IF(Signals_EU!F2=1,Signals_EU!R2*Mapping!$C$7,IF(Signals_EU!F2=-1,-Signals_EU!S2*Mapping!$C$7,0)) -> 0 | H2: =IF(Signals_EU!D2=1,Signals_EU!R2*Mapping!$C$8,IF(Signals_EU!D2=-1,-Signals_EU!S2*Mapping!$C$8,0)) -> 0 | I2: =IF(Signals_EU!G2=1,Signals_EU!R2*Mapping!$C$9,IF(Signals_EU!G2=-1,-Signals_EU!S2*Mapping!$C$9,0)) -> 0 | J2: =IF(Signals_EU!H2=1,Signals_EU!R2*Mapping!$C$10,IF(Signals_EU!H2=-1,-Signals_EU!S2*Mapping!$C$10,0)) -> 0 | K2: =IF(Signals_EU!F2=1,Signals_EU!R2*Mapping!$C$11,IF(Signals_EU!F2=-1,-Signals_EU!S2*Mapping!$C$11,0)) -> 0 | L2: =IF(Signals_EU!N2=1,Signals_EU!R2*Mapping!$C$12,IF(Signals_EU!N2=-1,-Signals_EU!S2*Mapping!$C$12,0)) -> 0 | M2: =IF(Signals_EU!I2=1,Signals_EU!R2*Mapping!$C$13,IF(Signals_EU!I2=-1,-Signals_EU!S2*Mapping!$C$13,0)) -> 0 | N2: =IF(Signals_EU!E2=1,Signals_EU!R2*Mapping!$C$14,IF(Signals_EU!E2=-1,-Signals_EU!S2*Mapping!$C$14,0)) -> 0 | O2: =0 -> 0 | P2: =0 -> 0 | Q2: =IF(Signals_EU!J2=1,Signals_EU!R2*Mapping!$C$17,IF(Signals_EU!J2=-1,-Signals_EU!S2*Mapping!$C$17,0)) -> 0 | R2: =IF(Signals_EU!K2=1,Signals_EU!R2*Mapping!$C$18,IF(Signals_EU!K2=-1,-Signals_EU!S2*Mapping!$C$18,0)) -> 0 | S2: =IF(Signals_EU!M2=1,Signals_EU!R2*Mapping!$C$19,IF(Signals_EU!M2=-1,-Signals_EU!S2*Mapping!$C$19,0)) -> 0 | T2: =IF(Signals_EU!L2=1,Signals_EU!R2*Mapping!$C$20,IF(Signals_EU!L2=-1,-Signals_EU!S2*Mapping!$C$20,0)) -> 0 | U2: =ROUND(SUM(B2:T2),12) -> 0
A3: =Signals_EU!B3 -> 39083 | B3: =IF(Signals_EU!O3=1,Signals_EU!R3*Mapping!$C$2,IF(Signals_EU!O3=-1,-Signals_EU!S3*Mapping!$C$2,0)) -> 0 | C3: =IF(Signals_EU!F3=1,Signals_EU!R3*Mapping!$C$3,IF(Signals_EU!F3=-1,-Signals_EU!S3*Mapping!$C$3,0)) -> 0 | D3: =IF(Signals_EU!C3=1,Signals_EU!R3*Mapping!$C$4,IF(Signals_EU!C3=-1,-Signals_EU!S3*Mapping!$C$4,0)) -> 0 | E3: =IF(Signals_EU!C3=1,Signals_EU!R3*Mapping!$C$5,IF(Signals_EU!C3=-1,-Signals_EU!S3*Mapping!$C$5,0)) -> 0 | F3: =IF(Signals_EU!H3=1,Signals_EU!R3*Mapping!$C$6,IF(Signals_EU!H3=-1,-Signals_EU!S3*Mapping!$C$6,0)) -> 0 | G3: =IF(Signals_EU!F3=1,Signals_EU!R3*Mapping!$C$7,IF(Signals_EU!F3=-1,-Signals_EU!S3*Mapping!$C$7,0)) -> 0 | H3: =IF(Signals_EU!D3=1,Signals_EU!R3*Mapping!$C$8,IF(Signals_EU!D3=-1,-Signals_EU!S3*Mapping!$C$8,0)) -> 0 | I3: =IF(Signals_EU!G3=1,Signals_EU!R3*Mapping!$C$9,IF(Signals_EU!G3=-1,-Signals_EU!S3*Mapping!$C$9,0)) -> 0 | J3: =IF(Signals_EU!H3=1,Signals_EU!R3*Mapping!$C$10,IF(Signals_EU!H3=-1,-Signals_EU!S3*Mapping!$C$10,0)) -> 0 | K3: =IF(Signals_EU!F3=1,Signals_EU!R3*Mapping!$C$11,IF(Signals_EU!F3=-1,-Signals_EU!S3*Mapping!$C$11,0)) -> 0 | L3: =IF(Signals_EU!N3=1,Signals_EU!R3*Mapping!$C$12,IF(Signals_EU!N3=-1,-Signals_EU!S3*Mapping!$C$12,0)) -> 0 | M3: =IF(Signals_EU!I3=1,Signals_EU!R3*Mapping!$C$13,IF(Signals_EU!I3=-1,-Signals_EU!S3*Mapping!$C$13,0)) -> 0 | N3: =IF(Signals_EU!E3=1,Signals_EU!R3*Mapping!$C$14,IF(Signals_EU!E3=-1,-Signals_EU!S3*Mapping!$C$14,0)) -> 0 | O3: =0 -> 0 | P3: =0 -> 0 | Q3: =IF(Signals_EU!J3=1,Signals_EU!R3*Mapping!$C$17,IF(Signals_EU!J3=-1,-Signals_EU!S3*Mapping!$C$17,0)) -> 0 | R3: =IF(Signals_EU!K3=1,Signals_EU!R3*Mapping!$C$18,IF(Signals_EU!K3=-1,-Signals_EU!S3*Mapping!$C$18,0)) -> 0 | S3: =IF(Signals_EU!M3=1,Signals_EU!R3*Mapping!$C$19,IF(Signals_EU!M3=-1,-Signals_EU!S3*Mapping!$C$19,0)) -> 0 | T3: =IF(Signals_EU!L3=1,Signals_EU!R3*Mapping!$C$20,IF(Signals_EU!L3=-1,-Signals_EU!S3*Mapping!$C$20,0)) -> 0 | U3: =ROUND(SUM(B3:T3),12) -> 0
A4: =Signals_EU!B4 -> 39114 | B4: =IF(Signals_EU!O4=1,Signals_EU!R4*Mapping!$C$2,IF(Signals_EU!O4=-1,-Signals_EU!S4*Mapping!$C$2,0)) -> 0 | C4: =IF(Signals_EU!F4=1,Signals_EU!R4*Mapping!$C$3,IF(Signals_EU!F4=-1,-Signals_EU!S4*Mapping!$C$3,0)) -> 0 | D4: =IF(Signals_EU!C4=1,Signals_EU!R4*Mapping!$C$4,IF(Signals_EU!C4=-1,-Signals_EU!S4*Mapping!$C$4,0)) -> 0 | E4: =IF(Signals_EU!C4=1,Signals_EU!R4*Mapping!$C$5,IF(Signals_EU!C4=-1,-Signals_EU!S4*Mapping!$C$5,0)) -> 0 | F4: =IF(Signals_EU!H4=1,Signals_EU!R4*Mapping!$C$6,IF(Signals_EU!H4=-1,-Signals_EU!S4*Mapping!$C$6,0)) -> 0 | G4: =IF(Signals_EU!F4=1,Signals_EU!R4*Mapping!$C$7,IF(Signals_EU!F4=-1,-Signals_EU!S4*Mapping!$C$7,0)) -> 0 | H4: =IF(Signals_EU!D4=1,Signals_EU!R4*Mapping!$C$8,IF(Signals_EU!D4=-1,-Signals_EU!S4*Mapping!$C$8,0)) -> 0 | I4: =IF(Signals_EU!G4=1,Signals_EU!R4*Mapping!$C$9,IF(Signals_EU!G4=-1,-Signals_EU!S4*Mapping!$C$9,0)) -> 0 | J4: =IF(Signals_EU!H4=1,Signals_EU!R4*Mapping!$C$10,IF(Signals_EU!H4=-1,-Signals_EU!S4*Mapping!$C$10,0)) -> 0 | K4: =IF(Signals_EU!F4=1,Signals_EU!R4*Mapping!$C$11,IF(Signals_EU!F4=-1,-Signals_EU!S4*Mapping!$C$11,0)) -> 0 | L4: =IF(Signals_EU!N4=1,Signals_EU!R4*Mapping!$C$12,IF(Signals_EU!N4=-1,-Signals_EU!S4*Mapping!$C$12,0)) -> 0 | M4: =IF(Signals_EU!I4=1,Signals_EU!R4*Mapping!$C$13,IF(Signals_EU!I4=-1,-Signals_EU!S4*Mapping!$C$13,0)) -> 0 | N4: =IF(Signals_EU!E4=1,Signals_EU!R4*Mapping!$C$14,IF(Signals_EU!E4=-1,-Signals_EU!S4*Mapping!$C$14,0)) -> 0 | O4: =0 -> 0 | P4: =0 -> 0 | Q4: =IF(Signals_EU!J4=1,Signals_EU!R4*Mapping!$C$17,IF(Signals_EU!J4=-1,-Signals_EU!S4*Mapping!$C$17,0)) -> 0 | R4: =IF(Signals_EU!K4=1,Signals_EU!R4*Mapping!$C$18,IF(Signals_EU!K4=-1,-Signals_EU!S4*Mapping!$C$18,0)) -> 0 | S4: =IF(Signals_EU!M4=1,Signals_EU!R4*Mapping!$C$19,IF(Signals_EU!M4=-1,-Signals_EU!S4*Mapping!$C$19,0)) -> 0 | T4: =IF(Signals_EU!L4=1,Signals_EU!R4*Mapping!$C$20,IF(Signals_EU!L4=-1,-Signals_EU!S4*Mapping!$C$20,0)) -> 0 | U4: =ROUND(SUM(B4:T4),12) -> 0
A5: =Signals_EU!B5 -> 39142 | B5: =IF(Signals_EU!O5=1,Signals_EU!R5*Mapping!$C$2,IF(Signals_EU!O5=-1,-Signals_EU!S5*Mapping!$C$2,0)) -> 0 | C5: =IF(Signals_EU!F5=1,Signals_EU!R5*Mapping!$C$3,IF(Signals_EU!F5=-1,-Signals_EU!S5*Mapping!$C$3,0)) -> 0 | D5: =IF(Signals_EU!C5=1,Signals_EU!R5*Mapping!$C$4,IF(Signals_EU!C5=-1,-Signals_EU!S5*Mapping!$C$4,0)) -> 0 | E5: =IF(Signals_EU!C5=1,Signals_EU!R5*Mapping!$C$5,IF(Signals_EU!C5=-1,-Signals_EU!S5*Mapping!$C$5,0)) -> 0 | F5: =IF(Signals_EU!H5=1,Signals_EU!R5*Mapping!$C$6,IF(Signals_EU!H5=-1,-Signals_EU!S5*Mapping!$C$6,0)) -> 0 | G5: =IF(Signals_EU!F5=1,Signals_EU!R5*Mapping!$C$7,IF(Signals_EU!F5=-1,-Signals_EU!S5*Mapping!$C$7,0)) -> 0 | H5: =IF(Signals_EU!D5=1,Signals_EU!R5*Mapping!$C$8,IF(Signals_EU!D5=-1,-Signals_EU!S5*Mapping!$C$8,0)) -> 0 | I5: =IF(Signals_EU!G5=1,Signals_EU!R5*Mapping!$C$9,IF(Signals_EU!G5=-1,-Signals_EU!S5*Mapping!$C$9,0)) -> 0 | J5: =IF(Signals_EU!H5=1,Signals_EU!R5*Mapping!$C$10,IF(Signals_EU!H5=-1,-Signals_EU!S5*Mapping!$C$10,0)) -> 0 | K5: =IF(Signals_EU!F5=1,Signals_EU!R5*Mapping!$C$11,IF(Signals_EU!F5=-1,-Signals_EU!S5*Mapping!$C$11,0)) -> 0 | L5: =IF(Signals_EU!N5=1,Signals_EU!R5*Mapping!$C$12,IF(Signals_EU!N5=-1,-Signals_EU!S5*Mapping!$C$12,0)) -> 0 | M5: =IF(Signals_EU!I5=1,Signals_EU!R5*Mapping!$C$13,IF(Signals_EU!I5=-1,-Signals_EU!S5*Mapping!$C$13,0)) -> 0 | N5: =IF(Signals_EU!E5=1,Signals_EU!R5*Mapping!$C$14,IF(Signals_EU!E5=-1,-Signals_EU!S5*Mapping!$C$14,0)) -> 0 | O5: =0 -> 0 | P5: =0 -> 0 | Q5: =IF(Signals_EU!J5=1,Signals_EU!R5*Mapping!$C$17,IF(Signals_EU!J5=-1,-Signals_EU!S5*Mapping!$C$17,0)) -> 0 | R5: =IF(Signals_EU!K5=1,Signals_EU!R5*Mapping!$C$18,IF(Signals_EU!K5=-1,-Signals_EU!S5*Mapping!$C$18,0)) -> 0 | S5: =IF(Signals_EU!M5=1,Signals_EU!R5*Mapping!$C$19,IF(Signals_EU!M5=-1,-Signals_EU!S5*Mapping!$C$19,0)) -> 0 | T5: =IF(Signals_EU!L5=1,Signals_EU!R5*Mapping!$C$20,IF(Signals_EU!L5=-1,-Signals_EU!S5*Mapping!$C$20,0)) -> 0 | U5: =ROUND(SUM(B5:T5),12) -> 0
A6: =Signals_EU!B6 -> 39173 | B6: =IF(Signals_EU!O6=1,Signals_EU!R6*Mapping!$C$2,IF(Signals_EU!O6=-1,-Signals_EU!S6*Mapping!$C$2,0)) -> 0 | C6: =IF(Signals_EU!F6=1,Signals_EU!R6*Mapping!$C$3,IF(Signals_EU!F6=-1,-Signals_EU!S6*Mapping!$C$3,0)) -> 0 | D6: =IF(Signals_EU!C6=1,Signals_EU!R6*Mapping!$C$4,IF(Signals_EU!C6=-1,-Signals_EU!S6*Mapping!$C$4,0)) -> 0 | E6: =IF(Signals_EU!C6=1,Signals_EU!R6*Mapping!$C$5,IF(Signals_EU!C6=-1,-Signals_EU!S6*Mapping!$C$5,0)) -> 0 | F6: =IF(Signals_EU!H6=1,Signals_EU!R6*Mapping!$C$6,IF(Signals_EU!H6=-1,-Signals_EU!S6*Mapping!$C$6,0)) -> 0 | G6: =IF(Signals_EU!F6=1,Signals_EU!R6*Mapping!$C$7,IF(Signals_EU!F6=-1,-Signals_EU!S6*Mapping!$C$7,0)) -> 0 | H6: =IF(Signals_EU!D6=1,Signals_EU!R6*Mapping!$C$8,IF(Signals_EU!D6=-1,-Signals_EU!S6*Mapping!$C$8,0)) -> 0 | I6: =IF(Signals_EU!G6=1,Signals_EU!R6*Mapping!$C$9,IF(Signals_EU!G6=-1,-Signals_EU!S6*Mapping!$C$9,0)) -> 0 | J6: =IF(Signals_EU!H6=1,Signals_EU!R6*Mapping!$C$10,IF(Signals_EU!H6=-1,-Signals_EU!S6*Mapping!$C$10,0)) -> 0 | K6: =IF(Signals_EU!F6=1,Signals_EU!R6*Mapping!$C$11,IF(Signals_EU!F6=-1,-Signals_EU!S6*Mapping!$C$11,0)) -> 0 | L6: =IF(Signals_EU!N6=1,Signals_EU!R6*Mapping!$C$12,IF(Signals_EU!N6=-1,-Signals_EU!S6*Mapping!$C$12,0)) -> 0 | M6: =IF(Signals_EU!I6=1,Signals_EU!R6*Mapping!$C$13,IF(Signals_EU!I6=-1,-Signals_EU!S6*Mapping!$C$13,0)) -> 0 | N6: =IF(Signals_EU!E6=1,Signals_EU!R6*Mapping!$C$14,IF(Signals_EU!E6=-1,-Signals_EU!S6*Mapping!$C$14,0)) -> 0 | O6: =0 -> 0 | P6: =0 -> 0 | Q6: =IF(Signals_EU!J6=1,Signals_EU!R6*Mapping!$C$17,IF(Signals_EU!J6=-1,-Signals_EU!S6*Mapping!$C$17,0)) -> 0 | R6: =IF(Signals_EU!K6=1,Signals_EU!R6*Mapping!$C$18,IF(Signals_EU!K6=-1,-Signals_EU!S6*Mapping!$C$18,0)) -> 0 | S6: =IF(Signals_EU!M6=1,Signals_EU!R6*Mapping!$C$19,IF(Signals_EU!M6=-1,-Signals_EU!S6*Mapping!$C$19,0)) -> 0 | T6: =IF(Signals_EU!L6=1,Signals_EU!R6*Mapping!$C$20,IF(Signals_EU!L6=-1,-Signals_EU!S6*Mapping!$C$20,0)) -> 0 | U6: =ROUND(SUM(B6:T6),12) -> 0
A7: =Signals_EU!B7 -> 39203 | B7: =IF(Signals_EU!O7=1,Signals_EU!R7*Mapping!$C$2,IF(Signals_EU!O7=-1,-Signals_EU!S7*Mapping!$C$2,0)) -> 0 | C7: =IF(Signals_EU!F7=1,Signals_EU!R7*Mapping!$C$3,IF(Signals_EU!F7=-1,-Signals_EU!S7*Mapping!$C$3,0)) -> 0 | D7: =IF(Signals_EU!C7=1,Signals_EU!R7*Mapping!$C$4,IF(Signals_EU!C7=-1,-Signals_EU!S7*Mapping!$C$4,0)) -> 0 | E7: =IF(Signals_EU!C7=1,Signals_EU!R7*Mapping!$C$5,IF(Signals_EU!C7=-1,-Signals_EU!S7*Mapping!$C$5,0)) -> 0 | F7: =IF(Signals_EU!H7=1,Signals_EU!R7*Mapping!$C$6,IF(Signals_EU!H7=-1,-Signals_EU!S7*Mapping!$C$6,0)) -> 0 | G7: =IF(Signals_EU!F7=1,Signals_EU!R7*Mapping!$C$7,IF(Signals_EU!F7=-1,-Signals_EU!S7*Mapping!$C$7,0)) -> 0 | H7: =IF(Signals_EU!D7=1,Signals_EU!R7*Mapping!$C$8,IF(Signals_EU!D7=-1,-Signals_EU!S7*Mapping!$C$8,0)) -> 0 | I7: =IF(Signals_EU!G7=1,Signals_EU!R7*Mapping!$C$9,IF(Signals_EU!G7=-1,-Signals_EU!S7*Mapping!$C$9,0)) -> 0 | J7: =IF(Signals_EU!H7=1,Signals_EU!R7*Mapping!$C$10,IF(Signals_EU!H7=-1,-Signals_EU!S7*Mapping!$C$10,0)) -> 0 | K7: =IF(Signals_EU!F7=1,Signals_EU!R7*Mapping!$C$11,IF(Signals_EU!F7=-1,-Signals_EU!S7*Mapping!$C$11,0)) -> 0 | L7: =IF(Signals_EU!N7=1,Signals_EU!R7*Mapping!$C$12,IF(Signals_EU!N7=-1,-Signals_EU!S7*Mapping!$C$12,0)) -> 0 | M7: =IF(Signals_EU!I7=1,Signals_EU!R7*Mapping!$C$13,IF(Signals_EU!I7=-1,-Signals_EU!S7*Mapping!$C$13,0)) -> 0 | N7: =IF(Signals_EU!E7=1,Signals_EU!R7*Mapping!$C$14,IF(Signals_EU!E7=-1,-Signals_EU!S7*Mapping!$C$14,0)) -> 0 | O7: =0 -> 0 | P7: =0 -> 0 | Q7: =IF(Signals_EU!J7=1,Signals_EU!R7*Mapping!$C$17,IF(Signals_EU!J7=-1,-Signals_EU!S7*Mapping!$C$17,0)) -> 0 | R7: =IF(Signals_EU!K7=1,Signals_EU!R7*Mapping!$C$18,IF(Signals_EU!K7=-1,-Signals_EU!S7*Mapping!$C$18,0)) -> 0 | S7: =IF(Signals_EU!M7=1,Signals_EU!R7*Mapping!$C$19,IF(Signals_EU!M7=-1,-Signals_EU!S7*Mapping!$C$19,0)) -> 0 | T7: =IF(Signals_EU!L7=1,Signals_EU!R7*Mapping!$C$20,IF(Signals_EU!L7=-1,-Signals_EU!S7*Mapping!$C$20,0)) -> 0 | U7: =ROUND(SUM(B7:T7),12) -> 0
A8: =Signals_EU!B8 -> 39234 | B8: =IF(Signals_EU!O8=1,Signals_EU!R8*Mapping!$C$2,IF(Signals_EU!O8=-1,-Signals_EU!S8*Mapping!$C$2,0)) -> 0 | C8: =IF(Signals_EU!F8=1,Signals_EU!R8*Mapping!$C$3,IF(Signals_EU!F8=-1,-Signals_EU!S8*Mapping!$C$3,0)) -> 0 | D8: =IF(Signals_EU!C8=1,Signals_EU!R8*Mapping!$C$4,IF(Signals_EU!C8=-1,-Signals_EU!S8*Mapping!$C$4,0)) -> 0 | E8: =IF(Signals_EU!C8=1,Signals_EU!R8*Mapping!$C$5,IF(Signals_EU!C8=-1,-Signals_EU!S8*Mapping!$C$5,0)) -> 0 | F8: =IF(Signals_EU!H8=1,Signals_EU!R8*Mapping!$C$6,IF(Signals_EU!H8=-1,-Signals_EU!S8*Mapping!$C$6,0)) -> 0 | G8: =IF(Signals_EU!F8=1,Signals_EU!R8*Mapping!$C$7,IF(Signals_EU!F8=-1,-Signals_EU!S8*Mapping!$C$7,0)) -> 0 | H8: =IF(Signals_EU!D8=1,Signals_EU!R8*Mapping!$C$8,IF(Signals_EU!D8=-1,-Signals_EU!S8*Mapping!$C$8,0)) -> 0 | I8: =IF(Signals_EU!G8=1,Signals_EU!R8*Mapping!$C$9,IF(Signals_EU!G8=-1,-Signals_EU!S8*Mapping!$C$9,0)) -> 0 | J8: =IF(Signals_EU!H8=1,Signals_EU!R8*Mapping!$C$10,IF(Signals_EU!H8=-1,-Signals_EU!S8*Mapping!$C$10,0)) -> 0 | K8: =IF(Signals_EU!F8=1,Signals_EU!R8*Mapping!$C$11,IF(Signals_EU!F8=-1,-Signals_EU!S8*Mapping!$C$11,0)) -> 0 | L8: =IF(Signals_EU!N8=1,Signals_EU!R8*Mapping!$C$12,IF(Signals_EU!N8=-1,-Signals_EU!S8*Mapping!$C$12,0)) -> 0 | M8: =IF(Signals_EU!I8=1,Signals_EU!R8*Mapping!$C$13,IF(Signals_EU!I8=-1,-Signals_EU!S8*Mapping!$C$13,0)) -> 0 | N8: =IF(Signals_EU!E8=1,Signals_EU!R8*Mapping!$C$14,IF(Signals_EU!E8=-1,-Signals_EU!S8*Mapping!$C$14,0)) -> 0 | O8: =0 -> 0 | P8: =0 -> 0 | Q8: =IF(Signals_EU!J8=1,Signals_EU!R8*Mapping!$C$17,IF(Signals_EU!J8=-1,-Signals_EU!S8*Mapping!$C$17,0)) -> 0 | R8: =IF(Signals_EU!K8=1,Signals_EU!R8*Mapping!$C$18,IF(Signals_EU!K8=-1,-Signals_EU!S8*Mapping!$C$18,0)) -> 0 | S8: =IF(Signals_EU!M8=1,Signals_EU!R8*Mapping!$C$19,IF(Signals_EU!M8=-1,-Signals_EU!S8*Mapping!$C$19,0)) -> 0 | T8: =IF(Signals_EU!L8=1,Signals_EU!R8*Mapping!$C$20,IF(Signals_EU!L8=-1,-Signals_EU!S8*Mapping!$C$20,0)) -> 0 | U8: =ROUND(SUM(B8:T8),12) -> 0
A9: =Signals_EU!B9 -> 39264 | B9: =IF(Signals_EU!O9=1,Signals_EU!R9*Mapping!$C$2,IF(Signals_EU!O9=-1,-Signals_EU!S9*Mapping!$C$2,0)) -> 0 | C9: =IF(Signals_EU!F9=1,Signals_EU!R9*Mapping!$C$3,IF(Signals_EU!F9=-1,-Signals_EU!S9*Mapping!$C$3,0)) -> 0 | D9: =IF(Signals_EU!C9=1,Signals_EU!R9*Mapping!$C$4,IF(Signals_EU!C9=-1,-Signals_EU!S9*Mapping!$C$4,0)) -> 0 | E9: =IF(Signals_EU!C9=1,Signals_EU!R9*Mapping!$C$5,IF(Signals_EU!C9=-1,-Signals_EU!S9*Mapping!$C$5,0)) -> 0 | F9: =IF(Signals_EU!H9=1,Signals_EU!R9*Mapping!$C$6,IF(Signals_EU!H9=-1,-Signals_EU!S9*Mapping!$C$6,0)) -> 0 | G9: =IF(Signals_EU!F9=1,Signals_EU!R9*Mapping!$C$7,IF(Signals_EU!F9=-1,-Signals_EU!S9*Mapping!$C$7,0)) -> 0 | H9: =IF(Signals_EU!D9=1,Signals_EU!R9*Mapping!$C$8,IF(Signals_EU!D9=-1,-Signals_EU!S9*Mapping!$C$8,0)) -> 0 | I9: =IF(Signals_EU!G9=1,Signals_EU!R9*Mapping!$C$9,IF(Signals_EU!G9=-1,-Signals_EU!S9*Mapping!$C$9,0)) -> 0 | J9: =IF(Signals_EU!H9=1,Signals_EU!R9*Mapping!$C$10,IF(Signals_EU!H9=-1,-Signals_EU!S9*Mapping!$C$10,0)) -> 0 | K9: =IF(Signals_EU!F9=1,Signals_EU!R9*Mapping!$C$11,IF(Signals_EU!F9=-1,-Signals_EU!S9*Mapping!$C$11,0)) -> 0 | L9: =IF(Signals_EU!N9=1,Signals_EU!R9*Mapping!$C$12,IF(Signals_EU!N9=-1,-Signals_EU!S9*Mapping!$C$12,0)) -> 0 | M9: =IF(Signals_EU!I9=1,Signals_EU!R9*Mapping!$C$13,IF(Signals_EU!I9=-1,-Signals_EU!S9*Mapping!$C$13,0)) -> 0 | N9: =IF(Signals_EU!E9=1,Signals_EU!R9*Mapping!$C$14,IF(Signals_EU!E9=-1,-Signals_EU!S9*Mapping!$C$14,0)) -> 0 | O9: =0 -> 0 | P9: =0 -> 0 | Q9: =IF(Signals_EU!J9=1,Signals_EU!R9*Mapping!$C$17,IF(Signals_EU!J9=-1,-Signals_EU!S9*Mapping!$C$17,0)) -> 0 | R9: =IF(Signals_EU!K9=1,Signals_EU!R9*Mapping!$C$18,IF(Signals_EU!K9=-1,-Signals_EU!S9*Mapping!$C$18,0)) -> 0 | S9: =IF(Signals_EU!M9=1,Signals_EU!R9*Mapping!$C$19,IF(Signals_EU!M9=-1,-Signals_EU!S9*Mapping!$C$19,0)) -> 0 | T9: =IF(Signals_EU!L9=1,Signals_EU!R9*Mapping!$C$20,IF(Signals_EU!L9=-1,-Signals_EU!S9*Mapping!$C$20,0)) -> 0 | U9: =ROUND(SUM(B9:T9),12) -> 0
A10: =Signals_EU!B10 -> 39295 | B10: =IF(Signals_EU!O10=1,Signals_EU!R10*Mapping!$C$2,IF(Signals_EU!O10=-1,-Signals_EU!S10*Mapping!$C$2,0)) -> 0 | C10: =IF(Signals_EU!F10=1,Signals_EU!R10*Mapping!$C$3,IF(Signals_EU!F10=-1,-Signals_EU!S10*Mapping!$C$3,0)) -> 0 | D10: =IF(Signals_EU!C10=1,Signals_EU!R10*Mapping!$C$4,IF(Signals_EU!C10=-1,-Signals_EU!S10*Mapping!$C$4,0)) -> 0 | E10: =IF(Signals_EU!C10=1,Signals_EU!R10*Mapping!$C$5,IF(Signals_EU!C10=-1,-Signals_EU!S10*Mapping!$C$5,0)) -> 0 | F10: =IF(Signals_EU!H10=1,Signals_EU!R10*Mapping!$C$6,IF(Signals_EU!H10=-1,-Signals_EU!S10*Mapping!$C$6,0)) -> 0 | G10: =IF(Signals_EU!F10=1,Signals_EU!R10*Mapping!$C$7,IF(Signals_EU!F10=-1,-Signals_EU!S10*Mapping!$C$7,0)) -> 0 | H10: =IF(Signals_EU!D10=1,Signals_EU!R10*Mapping!$C$8,IF(Signals_EU!D10=-1,-Signals_EU!S10*Mapping!$C$8,0)) -> 0 | I10: =IF(Signals_EU!G10=1,Signals_EU!R10*Mapping!$C$9,IF(Signals_EU!G10=-1,-Signals_EU!S10*Mapping!$C$9,0)) -> 0 | J10: =IF(Signals_EU!H10=1,Signals_EU!R10*Mapping!$C$10,IF(Signals_EU!H10=-1,-Signals_EU!S10*Mapping!$C$10,0)) -> 0 | K10: =IF(Signals_EU!F10=1,Signals_EU!R10*Mapping!$C$11,IF(Signals_EU!F10=-1,-Signals_EU!S10*Mapping!$C$11,0)) -> 0 | L10: =IF(Signals_EU!N10=1,Signals_EU!R10*Mapping!$C$12,IF(Signals_EU!N10=-1,-Signals_EU!S10*Mapping!$C$12,0)) -> 0 | M10: =IF(Signals_EU!I10=1,Signals_EU!R10*Mapping!$C$13,IF(Signals_EU!I10=-1,-Signals_EU!S10*Mapping!$C$13,0)) -> 0 | N10: =IF(Signals_EU!E10=1,Signals_EU!R10*Mapping!$C$14,IF(Signals_EU!E10=-1,-Signals_EU!S10*Mapping!$C$14,0)) -> 0 | O10: =0 -> 0 | P10: =0 -> 0 | Q10: =IF(Signals_EU!J10=1,Signals_EU!R10*Mapping!$C$17,IF(Signals_EU!J10=-1,-Signals_EU!S10*Mapping!$C$17,0)) -> 0 | R10: =IF(Signals_EU!K10=1,Signals_EU!R10*Mapping!$C$18,IF(Signals_EU!K10=-1,-Signals_EU!S10*Mapping!$C$18,0)) -> 0 | S10: =IF(Signals_EU!M10=1,Signals_EU!R10*Mapping!$C$19,IF(Signals_EU!M10=-1,-Signals_EU!S10*Mapping!$C$19,0)) -> 0 | T10: =IF(Signals_EU!L10=1,Signals_EU!R10*Mapping!$C$20,IF(Signals_EU!L10=-1,-Signals_EU!S10*Mapping!$C$20,0)) -> 0 | U10: =ROUND(SUM(B10:T10),12) -> 0
A11: =Signals_EU!B11 -> 39326 | B11: =IF(Signals_EU!O11=1,Signals_EU!R11*Mapping!$C$2,IF(Signals_EU!O11=-1,-Signals_EU!S11*Mapping!$C$2,0)) -> 0 | C11: =IF(Signals_EU!F11=1,Signals_EU!R11*Mapping!$C$3,IF(Signals_EU!F11=-1,-Signals_EU!S11*Mapping!$C$3,0)) -> 0 | D11: =IF(Signals_EU!C11=1,Signals_EU!R11*Mapping!$C$4,IF(Signals_EU!C11=-1,-Signals_EU!S11*Mapping!$C$4,0)) -> 0 | E11: =IF(Signals_EU!C11=1,Signals_EU!R11*Mapping!$C$5,IF(Signals_EU!C11=-1,-Signals_EU!S11*Mapping!$C$5,0)) -> 0 | F11: =IF(Signals_EU!H11=1,Signals_EU!R11*Mapping!$C$6,IF(Signals_EU!H11=-1,-Signals_EU!S11*Mapping!$C$6,0)) -> 0 | G11: =IF(Signals_EU!F11=1,Signals_EU!R11*Mapping!$C$7,IF(Signals_EU!F11=-1,-Signals_EU!S11*Mapping!$C$7,0)) -> 0 | H11: =IF(Signals_EU!D11=1,Signals_EU!R11*Mapping!$C$8,IF(Signals_EU!D11=-1,-Signals_EU!S11*Mapping!$C$8,0)) -> 0 | I11: =IF(Signals_EU!G11=1,Signals_EU!R11*Mapping!$C$9,IF(Signals_EU!G11=-1,-Signals_EU!S11*Mapping!$C$9,0)) -> 0 | J11: =IF(Signals_EU!H11=1,Signals_EU!R11*Mapping!$C$10,IF(Signals_EU!H11=-1,-Signals_EU!S11*Mapping!$C$10,0)) -> 0 | K11: =IF(Signals_EU!F11=1,Signals_EU!R11*Mapping!$C$11,IF(Signals_EU!F11=-1,-Signals_EU!S11*Mapping!$C$11,0)) -> 0 | L11: =IF(Signals_EU!N11=1,Signals_EU!R11*Mapping!$C$12,IF(Signals_EU!N11=-1,-Signals_EU!S11*Mapping!$C$12,0)) -> 0 | M11: =IF(Signals_EU!I11=1,Signals_EU!R11*Mapping!$C$13,IF(Signals_EU!I11=-1,-Signals_EU!S11*Mapping!$C$13,0)) -> 0 | N11: =IF(Signals_EU!E11=1,Signals_EU!R11*Mapping!$C$14,IF(Signals_EU!E11=-1,-Signals_EU!S11*Mapping!$C$14,0)) -> 0 | O11: =0 -> 0 | P11: =0 -> 0 | Q11: =IF(Signals_EU!J11=1,Signals_EU!R11*Mapping!$C$17,IF(Signals_EU!J11=-1,-Signals_EU!S11*Mapping!$C$17,0)) -> 0 | R11: =IF(Signals_EU!K11=1,Signals_EU!R11*Mapping!$C$18,IF(Signals_EU!K11=-1,-Signals_EU!S11*Mapping!$C$18,0)) -> 0 | S11: =IF(Signals_EU!M11=1,Signals_EU!R11*Mapping!$C$19,IF(Signals_EU!M11=-1,-Signals_EU!S11*Mapping!$C$19,0)) -> 0 | T11: =IF(Signals_EU!L11=1,Signals_EU!R11*Mapping!$C$20,IF(Signals_EU!L11=-1,-Signals_EU!S11*Mapping!$C$20,0)) -> 0 | U11: =ROUND(SUM(B11:T11),12) -> 0
A12: =Signals_EU!B12 -> 39356 | B12: =IF(Signals_EU!O12=1,Signals_EU!R12*Mapping!$C$2,IF(Signals_EU!O12=-1,-Signals_EU!S12*Mapping!$C$2,0)) -> 0 | C12: =IF(Signals_EU!F12=1,Signals_EU!R12*Mapping!$C$3,IF(Signals_EU!F12=-1,-Signals_EU!S12*Mapping!$C$3,0)) -> 0 | D12: =IF(Signals_EU!C12=1,Signals_EU!R12*Mapping!$C$4,IF(Signals_EU!C12=-1,-Signals_EU!S12*Mapping!$C$4,0)) -> 0 | E12: =IF(Signals_EU!C12=1,Signals_EU!R12*Mapping!$C$5,IF(Signals_EU!C12=-1,-Signals_EU!S12*Mapping!$C$5,0)) -> 0 | F12: =IF(Signals_EU!H12=1,Signals_EU!R12*Mapping!$C$6,IF(Signals_EU!H12=-1,-Signals_EU!S12*Mapping!$C$6,0)) -> 0 | G12: =IF(Signals_EU!F12=1,Signals_EU!R12*Mapping!$C$7,IF(Signals_EU!F12=-1,-Signals_EU!S12*Mapping!$C$7,0)) -> 0 | H12: =IF(Signals_EU!D12=1,Signals_EU!R12*Mapping!$C$8,IF(Signals_EU!D12=-1,-Signals_EU!S12*Mapping!$C$8,0)) -> 0 | I12: =IF(Signals_EU!G12=1,Signals_EU!R12*Mapping!$C$9,IF(Signals_EU!G12=-1,-Signals_EU!S12*Mapping!$C$9,0)) -> 0 | J12: =IF(Signals_EU!H12=1,Signals_EU!R12*Mapping!$C$10,IF(Signals_EU!H12=-1,-Signals_EU!S12*Mapping!$C$10,0)) -> 0 | K12: =IF(Signals_EU!F12=1,Signals_EU!R12*Mapping!$C$11,IF(Signals_EU!F12=-1,-Signals_EU!S12*Mapping!$C$11,0)) -> 0 | L12: =IF(Signals_EU!N12=1,Signals_EU!R12*Mapping!$C$12,IF(Signals_EU!N12=-1,-Signals_EU!S12*Mapping!$C$12,0)) -> 0 | M12: =IF(Signals_EU!I12=1,Signals_EU!R12*Mapping!$C$13,IF(Signals_EU!I12=-1,-Signals_EU!S12*Mapping!$C$13,0)) -> 0 | N12: =IF(Signals_EU!E12=1,Signals_EU!R12*Mapping!$C$14,IF(Signals_EU!E12=-1,-Signals_EU!S12*Mapping!$C$14,0)) -> 0 | O12: =0 -> 0 | P12: =0 -> 0 | Q12: =IF(Signals_EU!J12=1,Signals_EU!R12*Mapping!$C$17,IF(Signals_EU!J12=-1,-Signals_EU!S12*Mapping!$C$17,0)) -> 0 | R12: =IF(Signals_EU!K12=1,Signals_EU!R12*Mapping!$C$18,IF(Signals_EU!K12=-1,-Signals_EU!S12*Mapping!$C$18,0)) -> 0 | S12: =IF(Signals_EU!M12=1,Signals_EU!R12*Mapping!$C$19,IF(Signals_EU!M12=-1,-Signals_EU!S12*Mapping!$C$19,0)) -> 0 | T12: =IF(Signals_EU!L12=1,Signals_EU!R12*Mapping!$C$20,IF(Signals_EU!L12=-1,-Signals_EU!S12*Mapping!$C$20,0)) -> 0 | U12: =ROUND(SUM(B12:T12),12) -> 0
A13: =Signals_EU!B13 -> 39387 | B13: =IF(Signals_EU!O13=1,Signals_EU!R13*Mapping!$C$2,IF(Signals_EU!O13=-1,-Signals_EU!S13*Mapping!$C$2,0)) -> 0.05 | C13: =IF(Signals_EU!F13=1,Signals_EU!R13*Mapping!$C$3,IF(Signals_EU!F13=-1,-Signals_EU!S13*Mapping!$C$3,0)) -> -0.03 | D13: =IF(Signals_EU!C13=1,Signals_EU!R13*Mapping!$C$4,IF(Signals_EU!C13=-1,-Signals_EU!S13*Mapping!$C$4,0)) -> 0.025 | E13: =IF(Signals_EU!C13=1,Signals_EU!R13*Mapping!$C$5,IF(Signals_EU!C13=-1,-Signals_EU!S13*Mapping!$C$5,0)) -> 0.025 | F13: =IF(Signals_EU!H13=1,Signals_EU!R13*Mapping!$C$6,IF(Signals_EU!H13=-1,-Signals_EU!S13*Mapping!$C$6,0)) -> 0 | G13: =IF(Signals_EU!F13=1,Signals_EU!R13*Mapping!$C$7,IF(Signals_EU!F13=-1,-Signals_EU!S13*Mapping!$C$7,0)) -> -0.01 | H13: =IF(Signals_EU!D13=1,Signals_EU!R13*Mapping!$C$8,IF(Signals_EU!D13=-1,-Signals_EU!S13*Mapping!$C$8,0)) -> 0 | I13: =IF(Signals_EU!G13=1,Signals_EU!R13*Mapping!$C$9,IF(Signals_EU!G13=-1,-Signals_EU!S13*Mapping!$C$9,0)) -> -0.05 | J13: =IF(Signals_EU!H13=1,Signals_EU!R13*Mapping!$C$10,IF(Signals_EU!H13=-1,-Signals_EU!S13*Mapping!$C$10,0)) -> 0 | K13: =IF(Signals_EU!F13=1,Signals_EU!R13*Mapping!$C$11,IF(Signals_EU!F13=-1,-Signals_EU!S13*Mapping!$C$11,0)) -> -0.01 | L13: =IF(Signals_EU!N13=1,Signals_EU!R13*Mapping!$C$12,IF(Signals_EU!N13=-1,-Signals_EU!S13*Mapping!$C$12,0)) -> 0 | M13: =IF(Signals_EU!I13=1,Signals_EU!R13*Mapping!$C$13,IF(Signals_EU!I13=-1,-Signals_EU!S13*Mapping!$C$13,0)) -> 0 | N13: =IF(Signals_EU!E13=1,Signals_EU!R13*Mapping!$C$14,IF(Signals_EU!E13=-1,-Signals_EU!S13*Mapping!$C$14,0)) -> 0 | O13: =0 -> 0 | P13: =0 -> 0 | Q13: =IF(Signals_EU!J13=1,Signals_EU!R13*Mapping!$C$17,IF(Signals_EU!J13=-1,-Signals_EU!S13*Mapping!$C$17,0)) -> 0 | R13: =IF(Signals_EU!K13=1,Signals_EU!R13*Mapping!$C$18,IF(Signals_EU!K13=-1,-Signals_EU!S13*Mapping!$C$18,0)) -> 0.05 | S13: =IF(Signals_EU!M13=1,Signals_EU!R13*Mapping!$C$19,IF(Signals_EU!M13=-1,-Signals_EU!S13*Mapping!$C$19,0)) -> -0.05 | T13: =IF(Signals_EU!L13=1,Signals_EU!R13*Mapping!$C$20,IF(Signals_EU!L13=-1,-Signals_EU!S13*Mapping!$C$20,0)) -> 0 | U13: =ROUND(SUM(B13:T13),12) -> 0
... A240: =Signals_EU!B240 -> 46296 | B240: =IF(Signals_EU!O240=1,Signals_EU!R240*Mapping!$C$2,IF(Signals_EU!O240=-1,-Signals_EU!S240*Mapping!$C$2,0)) -> -0.05 | C240: =IF(Signals_EU!F240=1,Signals_EU!R240*Mapping!$C$3,IF(Signals_EU!F240=-1,-Signals_EU!S240*Mapping!$C$3,0)) -> 0.03 | D240: =IF(Signals_EU!C240=1,Signals_EU!R240*Mapping!$C$4,IF(Signals_EU!C240=-1,-Signals_EU!S240*Mapping!$C$4,0)) -> 0 | E240: =IF(Signals_EU!C240=1,Signals_EU!R240*Mapping!$C$5,IF(Signals_EU!C240=-1,-Signals_EU!S240*Mapping!$C$5,0)) -> 0 | F240: =IF(Signals_EU!H240=1,Signals_EU!R240*Mapping!$C$6,IF(Signals_EU!H240=-1,-Signals_EU!S240*Mapping!$C$6,0)) -> 0 | G240: =IF(Signals_EU!F240=1,Signals_EU!R240*Mapping!$C$7,IF(Signals_EU!F240=-1,-Signals_EU!S240*Mapping!$C$7,0)) -> 0.01 | H240: =IF(Signals_EU!D240=1,Signals_EU!R240*Mapping!$C$8,IF(Signals_EU!D240=-1,-Signals_EU!S240*Mapping!$C$8,0)) -> -0.05 | I240: =IF(Signals_EU!G240=1,Signals_EU!R240*Mapping!$C$9,IF(Signals_EU!G240=-1,-Signals_EU!S240*Mapping!$C$9,0)) -> 0.05 | J240: =IF(Signals_EU!H240=1,Signals_EU!R240*Mapping!$C$10,IF(Signals_EU!H240=-1,-Signals_EU!S240*Mapping!$C$10,0)) -> 0 | K240: =IF(Signals_EU!F240=1,Signals_EU!R240*Mapping!$C$11,IF(Signals_EU!F240=-1,-Signals_EU!S240*Mapping!$C$11,0)) -> 0.01 | L240: =IF(Signals_EU!N240=1,Signals_EU!R240*Mapping!$C$12,IF(Signals_EU!N240=-1,-Signals_EU!S240*Mapping!$C$12,0)) -> 0 | M240: =IF(Signals_EU!I240=1,Signals_EU!R240*Mapping!$C$13,IF(Signals_EU!I240=-1,-Signals_EU!S240*Mapping!$C$13,0)) -> -0.05 | N240: =IF(Signals_EU!E240=1,Signals_EU!R240*Mapping!$C$14,IF(Signals_EU!E240=-1,-Signals_EU!S240*Mapping!$C$14,0)) -> 0 | O240: =0 -> 0 | P240: =0 -> 0 | Q240: =IF(Signals_EU!J240=1,Signals_EU!R240*Mapping!$C$17,IF(Signals_EU!J240=-1,-Signals_EU!S240*Mapping!$C$17,0)) -> 0.05 | R240: =IF(Signals_EU!K240=1,Signals_EU!R240*Mapping!$C$18,IF(Signals_EU!K240=-1,-Signals_EU!S240*Mapping!$C$18,0)) -> 0 | S240: =IF(Signals_EU!M240=1,Signals_EU!R240*Mapping!$C$19,IF(Signals_EU!M240=-1,-Signals_EU!S240*Mapping!$C$19,0)) -> 0 | T240: =IF(Signals_EU!L240=1,Signals_EU!R240*Mapping!$C$20,IF(Signals_EU!L240=-1,-Signals_EU!S240*Mapping!$C$20,0)) -> 0 | U240: =ROUND(SUM(B240:T240),12) -> 0

Sheet Signals_US
A1: Date signal | B1: Date allocation | C1: Materials | D1: ConsStaples | E1: Retail | F1: Fin | G1: HealthCare | H1: Indus | I1: Oil | J1: Tech | K1: Telco | L1: Utili | M1: Travel & leisure | N1: Media | O1: Nb Positive | P1: Nb Negative | Q1: Unité Positive | R1: Unité Negative
A2: 39051 | B2: 39052 | C2: 1 | D2: 1 | E2: 1 | F2: 0 | G2: 0 | H2: 0 | I2: 0 | J2: 0 | K2: 0 | L2: 0 | M2: 0 | N2: 0 | O2: =COUNTIF(C2:N2,1) -> 3 | P2: =COUNTIF(C2:N2,-1) -> 0 | Q2: =IF(OR(O2=0,P2=0),0,MIN(O2,P2)*Mapping!$I$2/O2) -> 0 | R2: =IF(OR(O2=0,P2=0),0,MIN(O2,P2)*Mapping!$I$2/P2) -> 0
A3: 39082 | B3: 39083 | C3: 1 | D3: 1 | E3: 1 | F3: 0 | G3: 0 | H3: 0 | I3: 0 | J3: 0 | K3: 0 | L3: 0 | M3: 0 | N3: 0 | O3: =COUNTIF(C3:N3,1) -> 3 | P3: =COUNTIF(C3:N3,-1) -> 0 | Q3: =IF(OR(O3=0,P3=0),0,MIN(O3,P3)*Mapping!$I$2/O3) -> 0 | R3: =IF(OR(O3=0,P3=0),0,MIN(O3,P3)*Mapping!$I$2/P3) -> 0
A4: 39113 | B4: 39114 | C4: 1 | D4: 1 | E4: 1 | F4: 0 | G4: 0 | H4: 0 | I4: 0 | J4: 0 | K4: 0 | L4: 0 | M4: 0 | N4: 0 | O4: =COUNTIF(C4:N4,1) -> 3 | P4: =COUNTIF(C4:N4,-1) -> 0 | Q4: =IF(OR(O4=0,P4=0),0,MIN(O4,P4)*Mapping!$I$2/O4) -> 0 | R4: =IF(OR(O4=0,P4=0),0,MIN(O4,P4)*Mapping!$I$2/P4) -> 0
A5: 39141 | B5: 39142 | C5: 1 | D5: 1 | E5: 1 | F5: 0 | G5: 0 | H5: 0 | I5: 0 | J5: 0 | K5: 0 | L5: 0 | M5: 0 | N5: 0 | O5: =COUNTIF(C5:N5,1) -> 3 | P5: =COUNTIF(C5:N5,-1) -> 0 | Q5: =IF(OR(O5=0,P5=0),0,MIN(O5,P5)*Mapping!$I$2/O5) -> 0 | R5: =IF(OR(O5=0,P5=0),0,MIN(O5,P5)*Mapping!$I$2/P5) -> 0
A6: 39172 | B6: 39173 | C6: 1 | D6: 1 | E6: 1 | F6: 0 | G6: 0 | H6: 0 | I6: 0 | J6: 0 | K6: 0 | L6: 0 | M6: 0 | N6: 0 | O6: =COUNTIF(C6:N6,1) -> 3 | P6: =COUNTIF(C6:N6,-1) -> 0 | Q6: =IF(OR(O6=0,P6=0),0,MIN(O6,P6)*Mapping!$I$2/O6) -> 0 | R6: =IF(OR(O6=0,P6=0),0,MIN(O6,P6)*Mapping!$I$2/P6) -> 0
A7: 39202 | B7: 39203 | C7: 1 | D7: 1 | E7: 1 | F7: 0 | G7: 0 | H7: 0 | I7: 0 | J7: 0 | K7: 0 | L7: 0 | M7: 0 | N7: 0 | O7: =COUNTIF(C7:N7,1) -> 3 | P7: =COUNTIF(C7:N7,-1) -> 0 | Q7: =IF(OR(O7=0,P7=0),0,MIN(O7,P7)*Mapping!$I$2/O7) -> 0 | R7: =IF(OR(O7=0,P7=0),0,MIN(O7,P7)*Mapping!$I$2/P7) -> 0
A8: 39233 | B8: 39234 | C8: 1 | D8: 1 | E8: 1 | F8: 0 | G8: 0 | H8: 0 | I8: 0 | J8: 0 | K8: 0 | L8: 0 | M8: 0 | N8: 0 | O8: =COUNTIF(C8:N8,1) -> 3 | P8: =COUNTIF(C8:N8,-1) -> 0 | Q8: =IF(OR(O8=0,P8=0),0,MIN(O8,P8)*Mapping!$I$2/O8) -> 0 | R8: =IF(OR(O8=0,P8=0),0,MIN(O8,P8)*Mapping!$I$2/P8) -> 0
A9: 39263 | B9: 39264 | C9: 1 | D9: 1 | E9: 1 | F9: 0 | G9: 0 | H9: 0 | I9: 0 | J9: 0 | K9: 0 | L9: 0 | M9: 0 | N9: 0 | O9: =COUNTIF(C9:N9,1) -> 3 | P9: =COUNTIF(C9:N9,-1) -> 0 | Q9: =IF(OR(O9=0,P9=0),0,MIN(O9,P9)*Mapping!$I$2/O9) -> 0 | R9: =IF(OR(O9=0,P9=0),0,MIN(O9,P9)*Mapping!$I$2/P9) -> 0
A10: 39294 | B10: 39295 | C10: 1 | D10: 1 | E10: 1 | F10: 0 | G10: 0 | H10: 0 | I10: 0 | J10: 0 | K10: 0 | L10: 0 | M10: 0 | N10: 0 | O10: =COUNTIF(C10:N10,1) -> 3 | P10: =COUNTIF(C10:N10,-1) -> 0 | Q10: =IF(OR(O10=0,P10=0),0,MIN(O10,P10)*Mapping!$I$2/O10) -> 0 | R10: =IF(OR(O10=0,P10=0),0,MIN(O10,P10)*Mapping!$I$2/P10) -> 0
A11: 39325 | B11: 39326 | C11: 1 | D11: 1 | E11: 1 | F11: 0 | G11: 0 | H11: 0 | I11: 0 | J11: 0 | K11: 0 | L11: 0 | M11: 0 | N11: 0 | O11: =COUNTIF(C11:N11,1) -> 3 | P11: =COUNTIF(C11:N11,-1) -> 0 | Q11: =IF(OR(O11=0,P11=0),0,MIN(O11,P11)*Mapping!$I$2/O11) -> 0 | R11: =IF(OR(O11=0,P11=0),0,MIN(O11,P11)*Mapping!$I$2/P11) -> 0
A12: 39355 | B12: 39356 | C12: 1 | D12: 1 | E12: 1 | F12: 0 | G12: 0 | H12: 0 | I12: 0 | J12: 0 | K12: 0 | L12: 0 | M12: 0 | N12: 0 | O12: =COUNTIF(C12:N12,1) -> 3 | P12: =COUNTIF(C12:N12,-1) -> 0 | Q12: =IF(OR(O12=0,P12=0),0,MIN(O12,P12)*Mapping!$I$2/O12) -> 0 | R12: =IF(OR(O12=0,P12=0),0,MIN(O12,P12)*Mapping!$I$2/P12) -> 0
A13: 39386 | B13: 39387 | C13: 1 | D13: 0 | E13: -1 | F13: -1 | G13: 0 | H13: 0 | I13: 1 | J13: 1 | K13: 0 | L13: 0 | M13: 0 | N13: -1 | O13: =COUNTIF(C13:N13,1) -> 3 | P13: =COUNTIF(C13:N13,-1) -> 3 | Q13: =IF(OR(O13=0,P13=0),0,MIN(O13,P13)*Mapping!$I$2/O13) -> 0.05 | R13: =IF(OR(O13=0,P13=0),0,MIN(O13,P13)*Mapping!$I$2/P13) -> 0.05
... A240: 46295 | B240: 46296 | C240: 1 | D240: -1 | E240: 0 | F240: 1 | G240: 0 | H240: 0 | I240: 0 | J240: 1 | K240: -1 | L240: -1 | M240: 0 | N240: 0 | O240: =COUNTIF(C240:N240,1) -> 3 | P240: =COUNTIF(C240:N240,-1) -> 3 | Q240: =IF(OR(O240=0,P240=0),0,MIN(O240,P240)*Mapping!$I$2/O240) -> 0.05 | R240: =IF(OR(O240=0,P240=0),0,MIN(O240,P240)*Mapping!$I$2/P240) -> 0.05

Sheet Signals_EU
A1: Date signal | B1: Date allocation | C1: Materials | D1: ConsStaples | E1: Pers. Goods | F1: Fin | G1: HealthCare | H1: Indus | I1: Oil | J1: Tech | K1: Telco | L1: Utili | M1: Travel & leisure | N1: Media | O1: Auto | P1: Nb Positive | Q1: Nb Negative | R1: Unité Positive | S1: Unité Negative
A2: 39051 | B2: 39052 | C2: 1 | D2: 1 | E2: 1 | F2: 0 | G2: 0 | H2: 0 | I2: 0 | J2: 0 | K2: 0 | L2: 0 | M2: 0 | N2: 0 | O2: 0 | P2: =COUNTIF(C2:O2,1) -> 3 | Q2: =COUNTIF(C2:O2,-1) -> 0 | R2: =IF(OR(P2=0,Q2=0),0,MIN(P2,Q2)*Mapping!$I$2/P2) -> 0 | S2: =IF(OR(P2=0,Q2=0),0,MIN(P2,Q2)*Mapping!$I$2/Q2) -> 0
A3: 39082 | B3: 39083 | C3: 1 | D3: 1 | E3: 1 | F3: 0 | G3: 0 | H3: 0 | I3: 0 | J3: 0 | K3: 0 | L3: 0 | M3: 0 | N3: 0 | O3: 0 | P3: =COUNTIF(C3:O3,1) -> 3 | Q3: =COUNTIF(C3:O3,-1) -> 0 | R3: =IF(OR(P3=0,Q3=0),0,MIN(P3,Q3)*Mapping!$I$2/P3) -> 0 | S3: =IF(OR(P3=0,Q3=0),0,MIN(P3,Q3)*Mapping!$I$2/Q3) -> 0
A4: 39113 | B4: 39114 | C4: 1 | D4: 1 | E4: 1 | F4: 0 | G4: 0 | H4: 0 | I4: 0 | J4: 0 | K4: 0 | L4: 0 | M4: 0 | N4: 0 | O4: 0 | P4: =COUNTIF(C4:O4,1) -> 3 | Q4: =COUNTIF(C4:O4,-1) -> 0 | R4: =IF(OR(P4=0,Q4=0),0,MIN(P4,Q4)*Mapping!$I$2/P4) -> 0 | S4: =IF(OR(P4=0,Q4=0),0,MIN(P4,Q4)*Mapping!$I$2/Q4) -> 0
A5: 39141 | B5: 39142 | C5: 1 | D5: 1 | E5: 1 | F5: 0 | G5: 0 | H5: 0 | I5: 0 | J5: 0 | K5: 0 | L5: 0 | M5: 0 | N5: 0 | O5: 0 | P5: =COUNTIF(C5:O5,1) -> 3 | Q5: =COUNTIF(C5:O5,-1) -> 0 | R5: =IF(OR(P5=0,Q5=0),0,MIN(P5,Q5)*Mapping!$I$2/P5) -> 0 | S5: =IF(OR(P5=0,Q5=0),0,MIN(P5,Q5)*Mapping!$I$2/Q5) -> 0
A6: 39172 | B6: 39173 | C6: 1 | D6: 1 | E6: 1 | F6: 0 | G6: 0 | H6: 0 | I6: 0 | J6: 0 | K6: 0 | L6: 0 | M6: 0 | N6: 0 | O6: 0 | P6: =COUNTIF(C6:O6,1) -> 3 | Q6: =COUNTIF(C6:O6,-1) -> 0 | R6: =IF(OR(P6=0,Q6=0),0,MIN(P6,Q6)*Mapping!$I$2/P6) -> 0 | S6: =IF(OR(P6=0,Q6=0),0,MIN(P6,Q6)*Mapping!$I$2/Q6) -> 0
A7: 39202 | B7: 39203 | C7: 1 | D7: 1 | E7: 1 | F7: 0 | G7: 0 | H7: 0 | I7: 0 | J7: 0 | K7: 0 | L7: 0 | M7: 0 | N7: 0 | O7: 0 | P7: =COUNTIF(C7:O7,1) -> 3 | Q7: =COUNTIF(C7:O7,-1) -> 0 | R7: =IF(OR(P7=0,Q7=0),0,MIN(P7,Q7)*Mapping!$I$2/P7) -> 0 | S7: =IF(OR(P7=0,Q7=0),0,MIN(P7,Q7)*Mapping!$I$2/Q7) -> 0
A8: 39233 | B8: 39234 | C8: 1 | D8: 1 | E8: 1 | F8: 0 | G8: 0 | H8: 0 | I8: 0 | J8: 0 | K8: 0 | L8: 0 | M8: 0 | N8: 0 | O8: 0 | P8: =COUNTIF(C8:O8,1) -> 3 | Q8: =COUNTIF(C8:O8,-1) -> 0 | R8: =IF(OR(P8=0,Q8=0),0,MIN(P8,Q8)*Mapping!$I$2/P8) -> 0 | S8: =IF(OR(P8=0,Q8=0),0,MIN(P8,Q8)*Mapping!$I$2/Q8) -> 0
A9: 39263 | B9: 39264 | C9: 1 | D9: 1 | E9: 1 | F9: 0 | G9: 0 | H9: 0 | I9: 0 | J9: 0 | K9: 0 | L9: 0 | M9: 0 | N9: 0 | O9: 0 | P9: =COUNTIF(C9:O9,1) -> 3 | Q9: =COUNTIF(C9:O9,-1) -> 0 | R9: =IF(OR(P9=0,Q9=0),0,MIN(P9,Q9)*Mapping!$I$2/P9) -> 0 | S9: =IF(OR(P9=0,Q9=0),0,MIN(P9,Q9)*Mapping!$I$2/Q9) -> 0
A10: 39294 | B10: 39295 | C10: 1 | D10: 1 | E10: 1 | F10: 0 | G10: 0 | H10: 0 | I10: 0 | J10: 0 | K10: 0 | L10: 0 | M10: 0 | N10: 0 | O10: 0 | P10: =COUNTIF(C10:O10,1) -> 3 | Q10: =COUNTIF(C10:O10,-1) -> 0 | R10: =IF(OR(P10=0,Q10=0),0,MIN(P10,Q10)*Mapping!$I$2/P10) -> 0 | S10: =IF(OR(P10=0,Q10=0),0,MIN(P10,Q10)*Mapping!$I$2/Q10) -> 0
