Workbook
Name Annee_Bench: Output!$N$435:INDEX(Output!$N:$N,434+COUNT(Output!$M$435:$M$10000))
Name Annee_Bottom: Output!$Q$435:INDEX(Output!$Q:$Q,434+COUNT(Output!$M$435:$M$10000))
Name Annee_Date: Output!$M$435:INDEX(Output!$M:$M,434+COUNT(Output!$M$435:$M$10000))
Name Annee_Ptf: Output!$O$435:INDEX(Output!$O:$O,434+COUNT(Output!$M$435:$M$10000))
Name Annee_Top: Output!$P$435:INDEX(Output!$P:$P,434+COUNT(Output!$M$435:$M$10000))
Name Courbe_Bench: Output!$E$435:INDEX(Output!$E:$E,434+COUNT(Output!$D$435:$D$10000))
Name Courbe_Bottom: Output!$H$435:INDEX(Output!$H:$H,434+COUNT(Output!$D$435:$D$10000))
Name Courbe_Date: Output!$D$435:INDEX(Output!$D:$D,434+COUNT(Output!$D$435:$D$10000))
Name Courbe_LS: Output!$I$435:INDEX(Output!$I:$I,434+COUNT(Output!$D$435:$D$10000))
Name Courbe_Ptf: Output!$F$435:INDEX(Output!$F:$F,434+COUNT(Output!$D$435:$D$10000))
Name Courbe_Top: Output!$G$435:INDEX(Output!$G:$G,434+COUNT(Output!$D$435:$D$10000))
Name DateExport: Config!$C$37
Name delta_Wi: Config!$C$33
Name ExportFile: Config!$C$39
Name ImportFile: Config!$C$38
Name IND_Auto: Config!$B$20
Name IND_Bench: Config!$B$7
Name IND_ConsGd: Config!$B$9
Name IND_Fin: Config!$B$11
Name IND_Health: Config!$B$12
Name IND_Indus: Config!$B$13
Name IND_Mat: Config!$B$8
Name Ind_Media: Config!$B$19
Name IND_Oil: Config!$B$14
Name IND_PersGoods: Config!$B$10
Name Ind_Retail: Config!$B$10
Name IND_Tech: Config!$B$15
Name IND_Telco: Config!$B$16
Name Ind_Travel: Config!$B$18
Name IND_Utili: Config!$B$17
Name nb_Bottom: Config!$C$28
Name nb_Long: Config!$C$30
Name nb_Short: Config!$C$31
Name nb_Top: Config!$C$27
Name RFolder: Config!$C$40
Name RFunction: Config!$C$41

Sheet Dashboard
I4: SCORECARD | BN4: Date: | BO4: =Output!B2 -> 46295 | BP4: =Output!B9 -> 46296 | BQ4: =Output!B10 -> 46266
I5: EU SECTORS
CC6: Last Month Allocation Performance
BP7: =Output!B11 -> Sectors Ranking Oct-2026 | BV7: =Output!B12 -> Sectors Ranking Sept-2026
I8: Low leverage rank | J8: Net debt to EBITDA | M8: FCF to Total Debt | P8: Total Debt to Equity | S8: Margin rank | T8: Operating margin | W8: Net margin | Z8: EBITDA margin | AC8: Valuation rank | AD8: PFCF | AG8: EV / EBITDA | AJ8: Price to sales | AM8: Momentum rank | AN8: Perf 6M-1M | AP8: Perf 12M-1M | AR8: Earnings revision ratio | AU8: Growth rank | AV8: EPS 12M growth forecast | AY8: Sales 12M growth forecast | BB8: EBITDA 12M growth forecast | BE8: Low volatility rank | BF8: Vol 6M | BH8: Vol downside 18M | BJ8: =Output!B13 -> Macro rank - Currently in Expansion | BK8: Rate signal - Bonus Leverage & Value | CD8: Last Month EQ Performance
J9: vs. moy secteurs perc. 5y | K9: vs. moy secteurs histo 5y | L9: metric | M9: vs. moy secteurs perc. 5y | N9: vs. moy secteurs histo 5y | O9: metric | P9: vs. moy secteurs perc. 5y | Q9: vs. moy secteurs histo 5y | R9: metric | T9: vs. moy secteurs perc. 5y | U9: vs. moy secteurs histo 5y | V9: metric | W9: vs. moy secteurs perc. 5y | X9: vs. moy secteurs histo 5y | Y9: metric | Z9: vs. moy secteurs perc. 5y | AA9: vs. moy secteurs histo 5y | AB9: metric | AD9: vs. moy secteurs perc. 5y | AE9: vs. moy secteurs histo 5y | AF9: metric | AG9: vs. moy secteurs perc. 5y | AH9: vs. moy secteurs histo 5y | AI9: metric | AJ9: vs. moy secteurs perc. 5y | AK9: vs. moy secteurs histo 5y | AL9: metric | AN9: Score (rank) | AO9: Perf | AP9: Score (rank) | AQ9: Perf | AR9: Score (rank) | AS9: Ratio histo 5y | AT9: Ratio | AV9: vs. moy secteurs perc. 5y | AW9: vs. moy secteurs histo 5y | AX9: metric | AY9: vs. moy secteurs perc. 5y | AZ9: vs. moy secteurs histo 5y | BA9: metric | BB9: vs. moy secteurs perc. 5y | BC9: vs. moy secteurs histo 5y | BD9: metric | BF9: Score (rank) | BG9: Vol | BH9: Score (rank) | BI9: Vol | BN9: Nb Top 3 pillars | BO9: Nb Worst 3 pillars | BP9: Global - Weighted Score | BQ9: Reco | BR9: Δ Reco | BU9: Previous nb piliers Top 3 | BV9: Previous nb piliers Worst 3 | BW9: Previous global - Weighted Score | BX9: Previous Reco | BY9: =Output!BU1 -> Sept-2026 EQ Performance | BZ9: =Output!BV1 -> Sept-2026 XSRet vs FTSE World Europe | CC9: Long Portfolio | CD9: =Output!B15 -> 0.014712331
H10: Materials | I10: =Output!E2 -> 12 | J10: =Output!F2 -> 3.9344262 | L10: =Output!H2 -> 1.5176704 | M10: =Output!I2 -> 0.6557377 | O10: =Output!K2 -> 10.980834 | P10: =Output!L2 -> 0.6557377 | R10: =Output!N2 -> 57.789196 | S10: =Output!O2 -> 10 | T10: =Output!P2 -> 3.3102144 | V10: =Output!R2 -> 8.6551612 | W10: =Output!S2 -> 3.8020177 | Y10: =Output!U2 -> 6.0453761 | Z10: =Output!V2 -> 2.9003783 | AB10: =Output!X2 -> 13.757778 | AC10: =Output!Y2 -> 11 | AD10: =Output!Z2 -> 0.32786885 | AF10: =Output!AB2 -> 8.9422186 | AG10: =Output!AC2 -> 0.49180328 | AI10: =Output!AE2 -> 7.7631122 | AJ10: =Output!AF2 -> 1.8032787 | AL10: =Output!AH2 -> 1.0583207 | AM10: =Output!AI2 -> 4 | AN10: =Output!AJ2 -> 6.1538462 | AO10: =Output!AK2 -> 0.13038207 | AP10: =Output!AL2 -> 9.2307692 | AQ10: =Output!AM2 -> 0.33963863 | AR10: =Output!AN2 -> 6.1538462 | AT10: =Output!AP2 -> 0.057142857 | AU10: =Output!AQ2 -> 4 | AV10: =Output!AR2 -> 5.7377049 | AX10: =Output!AT2 -> 18.168167 | AY10: =Output!AU2 -> 8.5245902 | BA10: =Output!AW2 -> 3.7950325 | BB10: =Output!AX2 -> 6.7213115 | BD10: =Output!AZ2 -> 10.282517 | BE10: =Output!BA2 -> 2 | BF10: =Output!BB2 -> 7.3770492 | BG10: =Output!BC2 -> 0.18247089 | BH10: =Output!BD2 -> 9.3442623 | BI10: =Output!BE2 -> 0.062962012 | BJ10: =Output!BF2 -> 8 | BK10: =Output!B6 -> On | BM10: Materials | BN10: =Output!BJ2 -> 1 | BO10: =Output!BK2 -> 4 | BP10: =Output!BL2 -> 6.7142857 | BQ10: =Output!BM2 -> Neutral | BR10: =Output!BN2 -> 0 | BU10: =Output!BQ2 -> 2 | BV10: =Output!BR2 -> 3 | BW10: =Output!BS2 -> 6.7142857 | BX10: =Output!BT2 -> Neutral | BY10: =Output!BU2 -> -0.043807237 | BZ10: =Output!BV2 -> -0.018626796 | CC10: Short Portfolio | CD10: =Output!B16 -> 0.067264722
H11: Consumer Staples | I11: =Output!E3 -> 10 | J11: =Output!F3 -> 4.2622951 | L11: =Output!H3 -> 2.57611 | M11: =Output!I3 -> 7.3770492 | O11: =Output!K3 -> 17.981573 | P11: =Output!L3 -> 0.32786885 | R11: =Output!N3 -> 115.95281 | S11: =Output!O3 -> 12 | T11: =Output!P3 -> 2.9886507 | V11: =Output!R3 -> 11.498439 | W11: =Output!S3 -> 3.3165195 | Y11: =Output!U3 -> 7.318707 | Z11: =Output!V3 -> 3.3417402 | AB11: =Output!X3 -> 15.836251 | AC11: =Output!Y3 -> 6 | AD11: =Output!Z3 -> 6.7213115 | AF11: =Output!AB3 -> 10.04444 | AG11: =Output!AC3 -> 7.3770492 | AI11: =Output!AE3 -> 9.7333979 | AJ11: =Output!AF3 -> 9.1803279 | AL11: =Output!AH3 -> 1.1770891 | AM11: =Output!AI3 -> 9 | AN11: =Output!AJ3 -> 4.6153846 | AO11: =Output!AK3 -> 0.02999415 | AP11: =Output!AL3 -> 3.8461538 | AQ11: =Output!AM3 -> 0.042321296 | AR11: =Output!AN3 -> 3.8461538 | AT11: =Output!AP3 -> -0.11363636 | AU11: =Output!AQ3 -> 11 | AV11: =Output!AR3 -> 3.9344262 | AX11: =Output!AT3 -> 6.9131176 | AY11: =Output!AU3 -> 2.9508197 | BA11: =Output!AW3 -> 3.6888091 | BB11: =Output!AX3 -> 3.442623 | BD11: =Output!AZ3 -> 4.8960757 | BE11: =Output!BA3 -> 12 | BF11: =Output!BB3 -> 3.2786885 | BG11: =Output!BC3 -> 0.18050462 | BH11: =Output!BD3 -> 1.147541 | BI11: =Output!BE3 -> 0.11597345 | BJ11: =Output!BF3 -> 12 | BK11: - A sector that is at least 3 times in worst 3 sectors (resp. top 3) of different pillars can not have a positive recommendation (resp. negative). - If two sectors are as many times in the top or worst 3, we differentiate them by their mean score. - Macro pillar counts twice. - If rate signal is on, value and leverage pillars count twice. | BM11: Consumer Staples | BN11: =Output!BJ3 -> 0 | BO11: =Output!BK3 -> 5 | BP11: =Output!BL3 -> 3.7142857 | BQ11: =Output!BM3 -> Negative | BR11: =Output!BN3 -> 0 | BU11: =Output!BQ3 -> 0 | BV11: =Output!BR3 -> 3 | BW11: =Output!BS3 -> 4.1428571 | BX11: =Output!BT3 -> Negative | BY11: =Output!BU3 -> -0.032147216 | BZ11: =Output!BV3 -> -0.0069667762 | CC11: L/S Portfolio | CD11: =Output!B17 -> 0.081977053
H12: Personal Goods | I12: =Output!E4 -> 4 | J12: =Output!F4 -> 4.9180328 | L12: =Output!H4 -> 0.73907005 | M12: =Output!I4 -> 7.2131148 | O12: =Output!K4 -> 33.20084 | P12: =Output!L4 -> 3.6065574 | R12: =Output!N4 -> 58.519142 | S12: =Output!O4 -> 8 | T12: =Output!P4 -> 4.4766709 | V12: =Output!R4 -> 18.044296 | W12: =Output!S4 -> 4.9117276 | Y12: =Output!U4 -> 11.481202 | Z12: =Output!V4 -> 4.8549811 | AB12: =Output!X4 -> 25.277612 | AC12: =Output!Y4 -> 2 | AD12: =Output!Z4 -> 10 | AF12: =Output!AB4 -> 14.473667 | AG12: =Output!AC4 -> 10 | AI12: =Output!AE4 -> 11.329662 | AJ12: =Output!AF4 -> 10 | AL12: =Output!AH4 -> 2.7591781 | AM12: =Output!AI4 -> 12 | AN12: =Output!AJ4 -> 5.3846154 | AO12: =Output!AK4 -> 0.09934833 | AP12: =Output!AL4 -> 2.3076923 | AQ12: =Output!AM4 -> -0.026194227 | AR12: =Output!AN4 -> 2.3076923 | AT12: =Output!AP4 -> -0.38461538 | AU12: =Output!AQ4 -> 12 | AV12: =Output!AR4 -> 3.7704918 | AX12: =Output!AT4 -> 13.004314 | AY12: =Output!AU4 -> 2.1311475 | BA12: =Output!AW4 -> 6.0954359 | BB12: =Output!AX4 -> 2.6229508 | BD12: =Output!AZ4 -> 7.7301313 | BE12: =Output!BA4 -> 7 | BF12: =Output!BB4 -> 5.4098361 | BG12: =Output!BC4 -> 0.25442201 | BH12: =Output!BD4 -> 2.1311475 | BI12: =Output!BE4 -> 0.18750445 | BJ12: =Output!BF4 -> 9 | BM12: Personal Goods | BN12: =Output!BJ4 -> 2 | BO12: =Output!BK4 -> 2 | BP12: =Output!BL4 -> 6.2857143 | BQ12: =Output!BM4 -> Neutral | BR12: =Output!BN4 -> 1 | BU12: =Output!BQ4 -> 1 | BV12: =Output!BR4 -> 4 | BW12: =Output!BS4 -> 6.2857143 | BX12: =Output!BT4 -> Negative | BY12: =Output!BU4 -> -0.079729636 | BZ12: =Output!BV4 -> -0.054549195 | CC12: Ptf dev secto | CD12: =Output!B18 -> -0.015123767
H13: Financials | I13: =Output!E5 -> 2 | J13: =Output!F5 -> 7.0491803 | L13: =Output!H5 -> 10.11696 | M13: =Output!I5 -> 3.1147541 | O13: =Output!K5 -> 2.8015014 | P13: =Output!L5 -> 8.6885246 | R13: =Output!N5 -> 417.95205 | S13: =Output!O5 -> 3 | T13: =Output!P5 -> 7.7805801 | V13: =Output!R5 -> 17.486197 | W13: =Output!S5 -> 8.6569987 | Y13: =Output!U5 -> 12.648923 | Z13: =Output!V5 -> 7.0491803 | AB13: =Output!X5 -> 51.665548 | AC13: =Output!Y5 -> n.a. | AD13: =Output!Z5 -> n.a. | AF13: =Output!AB5 -> n.a. | AG13: =Output!AC5 -> n.a. | AI13: =Output!AE5 -> n.a. | AJ13: =Output!AF5 -> 0.32786885 | AL13: =Output!AH5 -> 2.1662574 | AM13: =Output!AI5 -> 1 | AN13: =Output!AJ5 -> 9.2307692 | AO13: =Output!AK5 -> 0.23881973 | AP13: =Output!AL5 -> 8.4615385 | AQ13: =Output!AM5 -> 0.2750319 | AR13: =Output!AN5 -> 6.9230769 | AT13: =Output!AP5 -> 0.17094017 | AU13: =Output!AQ5 -> 9 | AV13: =Output!AR5 -> 4.0983607 | AX13: =Output!AT5 -> 10.637174 | AY13: =Output!AU5 -> 5.5737705 | BA13: =Output!AW5 -> 5.0359127 | BB13: =Output!AX5 -> n.a. | BD13: =Output!AZ5 -> n.a. | BE13: =Output!BA5 -> 8 | BF13: =Output!BB5 -> 2.7868852 | BG13: =Output!BC5 -> 0.20099649 | BH13: =Output!BD5 -> 3.442623 | BI13: =Output!BE5 -> 0.12262943 | BJ13: =Output!BF5 -> n.a. | BM13: Financials | BN13: =Output!BJ5 -> 4 | BO13: =Output!BK5 -> 0 | BP13: =Output!BL5 -> n.a. | BQ13: =Output!BM5 -> Positive | BR13: =Output!BN5 -> 0 | BU13: =Output!BQ5 -> 3 | BV13: =Output!BR5 -> 0 | BW13: =Output!BS5 -> n.a. | BX13: =Output!BT5 -> Positive | BY13: =Output!BU5 -> -0.029492517 | BZ13: =Output!BV5 -> -0.0043120766 | CC13: FTSE Europe | CD13: =Output!B19 -> -0.02518044
H14: HealthCare | I14: =Output!E6 -> 5 | J14: =Output!F6 -> 5.0819672 | L14: =Output!H6 -> 1.5089102 | M14: =Output!I6 -> 7.8688525 | O14: =Output!K6 -> 28.807423 | P14: =Output!L6 -> 1.9672131 | R14: =Output!N6 -> 66.839496 | S14: =Output!O6 -> 1 | T14: =Output!P6 -> 9.4262295 | V14: =Output!R6 -> 23.281359 | W14: =Output!S6 -> 7.8940731 | Y14: =Output!U6 -> 16.548002 | Z14: =Output!V6 -> 9.2307692 | AB14: =Output!X6 -> 31.620939 | AC14: =Output!Y6 -> 3 | AD14: =Output!Z6 -> 8.3606557 | AF14: =Output!AB6 -> 12.337819 | AG14: =Output!AC6 -> 8.852459 | AI14: =Output!AE6 -> 10.802642 | AJ14: =Output!AF6 -> 9.5081967 | AL14: =Output!AH6 -> 2.9853111 | AM14: =Output!AI6 -> 7 | AN14: =Output!AJ6 -> 3.8461538 | AO14: =Output!AK6 -> 0.024259956 | AP14: =Output!AL6 -> 4.6153846 | AQ14: =Output!AM6 -> 0.1062622 | AR14: =Output!AN6 -> 8.4615385 | AT14: =Output!AP6 -> 0.35555556 | AU14: =Output!AQ6 -> 10 | AV14: =Output!AR6 -> 3.9344262 | AX14: =Output!AT6 -> 8.06437 | AY14: =Output!AU6 -> 3.7704918 | BA14: =Output!AW6 -> 5.4978133 | BB14: =Output!AX6 -> 3.6065574 | BD14: =Output!AZ6 -> 7.6618302 | BE14: =Output!BA6 -> 3 | BF14: =Output!BB6 -> 8.0327869 | BG14: =Output!BC6 -> 0.12836426 | BH14: =Output!BD6 -> 7.3770492 | BI14: =Output!BE6 -> 0.085948425 | BJ14: =Output!BF6 -> 3 | BM14: HealthCare | BN14: =Output!BJ6 -> 6 | BO14: =Output!BK6 -> 0 | BP14: =Output!BL6 -> 9.4285714 | BQ14: =Output!BM6 -> Positive | BR14: =Output!BN6 -> 1 | BU14: =Output!BQ6 -> 2 | BV14: =Output!BR6 -> 0 | BW14: =Output!BS6 -> 8.5714286 | BX14: =Output!BT6 -> Neutral | BY14: =Output!BU6 -> -0.030060214 | BZ14: =Output!BV6 -> -0.0048797734
H15: Industrials | I15: =Output!E7 -> 3 | J15: =Output!F7 -> 4.2622951 | L15: =Output!H7 -> 1.6366061 | M15: =Output!I7 -> 10 | O15: =Output!K7 -> 22.892464 | P15: =Output!L7 -> 2.295082 | R15: =Output!N7 -> 85.294826 | S15: =Output!O7 -> 7 | T15: =Output!P7 -> 4.4892812 | V15: =Output!R7 -> 11.077253 | W15: =Output!S7 -> 5.3152585 | Y15: =Output!U7 -> 7.5557529 | Z15: =Output!V7 -> 5.2017654 | AB15: =Output!X7 -> 15.843936 | AC15: =Output!Y7 -> 10 | AD15: =Output!Z7 -> 1.3114754 | AF15: =Output!AB7 -> 13.814605 | AG15: =Output!AC7 -> 1.4754098 | AI15: =Output!AE7 -> 11.854577 | AJ15: =Output!AF7 -> 1.3114754 | AL15: =Output!AH7 -> 1.7658251 | AM15: =Output!AI7 -> 5 | AN15: =Output!AJ7 -> 6.9230769 | AO15: =Output!AK7 -> 0.13319026 | AP15: =Output!AL7 -> 5.3846154 | AQ15: =Output!AM7 -> 0.10708826 | AR15: =Output!AN7 -> 7.6923077 | AT15: =Output!AP7 -> 0.23478261 | AU15: =Output!AQ7 -> 2 | AV15: =Output!AR7 -> 6.7213115 | AX15: =Output!AT7 -> 16.132483 | AY15: =Output!AU7 -> 10 | BA15: =Output!AW7 -> 7.5180213 | BB15: =Output!AX7 -> 7.5409836 | BD15: =Output!AZ7 -> 10.381888 | BE15: =Output!BA7 -> 12 | BF15: =Output!BB7 -> 3.6065574 | BG15: =Output!BC7 -> 0.21927049 | BH15: =Output!BD7 -> 0.81967213 | BI15: =Output!BE7 -> 0.14291346 | BJ15: =Output!BF7 -> 6 | BM15: Industrials | BN15: =Output!BJ7 -> 3 | BO15: =Output!BK7 -> 1 | BP15: =Output!BL7 -> 7.5714286 | BQ15: =Output!BM7 -> Neutral | BR15: =Output!BN7 -> 0 | BU15: =Output!BQ7 -> 2 | BV15: =Output!BR7 -> 2 | BW15: =Output!BS7 -> 7.4285714 | BX15: =Output!BT7 -> Neutral | BY15: =Output!BU7 -> -0.037750141 | BZ15: =Output!BV7 -> -0.012569701
H16: Energy | I16: =Output!E8 -> 9 | J16: =Output!F8 -> 5.2459016 | L16: =Output!H8 -> 0.75166269 | M16: =Output!I8 -> 5.2459016 | O16: =Output!K8 -> 26.597811 | P16: =Output!L8 -> 1.9672131 | R16: =Output!N8 -> 62.418637 | S16: =Output!O8 -> 6 | T16: =Output!P8 -> 5.258512 | V16: =Output!R8 -> 12.707879 | W16: =Output!S8 -> 6.7339218 | Y16: =Output!U8 -> 7.516947 | Z16: =Output!V8 -> 5.4224464 | AB16: =Output!X8 -> 19.852902 | AC16: =Output!Y8 -> 13 | AD16: =Output!Z8 -> 0.32786885 | AF16: =Output!AB8 -> 5.34985 | AG16: =Output!AC8 -> 0.81967213 | AI16: =Output!AE8 -> 4.7964169 | AJ16: =Output!AF8 -> 0.6557377 | AL16: =Output!AH8 -> 0.87351089 | AM16: =Output!AI8 -> 4 | AN16: =Output!AJ8 -> 1.5384615 | AO16: =Output!AK8 -> -0.030101683 | AP16: =Output!AL8 -> 10 | AQ16: =Output!AM8 -> 0.41327662 | AR16: =Output!AN8 -> 10 | AT16: =Output!AP8 -> 0.77272727 | AU16: =Output!AQ8 -> 7 | AV16: =Output!AR8 -> 7.5409836 | AX16: =Output!AT8 -> 13.270838 | AY16: =Output!AU8 -> 1.8032787 | BA16: =Output!AW8 -> -0.3291555 | BB16: =Output!AX8 -> 7.0491803 | BD16: =Output!AZ8 -> 1.6743774 | BE16: =Output!BA8 -> 13 | BF16: =Output!BB8 -> 0.49180328 | BG16: =Output!BC8 -> 0.27017194 | BH16: =Output!BD8 -> 1.8032787 | BI16: =Output!BE8 -> 0.16184847 | BJ16: =Output!BF8 -> 11 | BM16: Energy | BN16: =Output!BJ8 -> 0 | BO16: =Output!BK8 -> 5 | BP16: =Output!BL8 -> 5 | BQ16: =Output!BM8 -> Negative | BR16: =Output!BN8 -> -2 | BU16: =Output!BQ8 -> 3 | BV16: =Output!BR8 -> 1 | BW16: =Output!BS8 -> 7.5714286 | BX16: =Output!BT8 -> Positive | BY16: =Output!BU8 -> 0.03336263 | BZ16: =Output!BV8 -> 0.05854307
H17: Tech | I17: =Output!E9 -> 8 | J17: =Output!F9 -> 5.0819672 | L17: =Output!H9 -> 0.43980775 | M17: =Output!I9 -> 7.3770492 | O17: =Output!K9 -> 51.01086 | P17: =Output!L9 -> 0.49180328 | R17: =Output!N9 -> 42.505912 | S17: =Output!O9 -> 2 | T17: =Output!P9 -> 8.8776797 | V17: =Output!R9 -> 23.063598 | W17: =Output!S9 -> 8.6065574 | Y17: =Output!U9 -> 21.193798 | Z17: =Output!V9 -> 8.3543506 | AB17: =Output!X9 -> 29.081963 | AC17: =Output!Y9 -> 5 | AD17: =Output!Z9 -> 8.1081081 | AF17: =Output!AB9 -> 21.186471 | AG17: =Output!AC9 -> 7.5675676 | AI17: =Output!AE9 -> 18.199697 | AJ17: =Output!AF9 -> 0.6557377 | AL17: =Output!AH9 -> 6.0528066 | AM17: =Output!AI9 -> 2 | AN17: =Output!AJ9 -> 10 | AO17: =Output!AK9 -> 0.32019032 | AP17: =Output!AL9 -> 7.6923077 | AQ17: =Output!AM9 -> 0.26770248 | AR17: =Output!AN9 -> 5.3846154 | AT17: =Output!AP9 -> -0.045454545 | AU17: =Output!AQ9 -> 1 | AV17: =Output!AR9 -> 8.1967213 | AX17: =Output!AT9 -> 27.448513 | AY17: =Output!AU9 -> 10 | BA17: =Output!AW9 -> 15.915395 | BB17: =Output!AX9 -> 9.6721311 | BD17: =Output!AZ9 -> 24.497585 | BE17: =Output!BA9 -> 10 | BF17: =Output!BB9 -> 0.81967213 | BG17: =Output!BC9 -> 0.32402071 | BH17: =Output!BD9 -> 4.4262295 | BI17: =Output!BE9 -> 0.12996419 | BJ17: =Output!BF9 -> 2 | BM17: Tech | BN17: =Output!BJ9 -> 5 | BO17: =Output!BK9 -> 0 | BP17: =Output!BL9 -> 9.7142857 | BQ17: =Output!BM9 -> Positive | BR17: =Output!BN9 -> 0 | BU17: =Output!BQ9 -> 6 | BV17: =Output!BR9 -> 0 | BW17: =Output!BS9 -> 9.8571429 | BX17: =Output!BT9 -> Positive | BY17: =Output!BU9 -> 0.04026688 | BZ17: =Output!BV9 -> 0.06544732
H18: Teleco | I18: =Output!E10 -> 7 | J18: =Output!F10 -> 6.2295082 | L18: =Output!H10 -> 2.6984758 | M18: =Output!I10 -> 6.2295082 | O18: =Output!K10 -> 14.772993 | P18: =Output!L10 -> 0.98360656 | R18: =Output!N10 -> 168.09143 | S18: =Output!O10 -> 4 | T18: =Output!P10 -> 6.8221942 | V18: =Output!R10 -> 15.845054 | W18: =Output!S10 -> 4.6532156 | Y18: =Output!U10 -> 6.9782061 | Z18: =Output!V10 -> 8.7137453 | AB18: =Output!X10 -> 36.809322 | AC18: =Output!Y10 -> 9 | AD18: =Output!Z10 -> 1.9672131 | AF18: =Output!AB10 -> 4.3402105 | AG18: =Output!AC10 -> 4.5901639 | AI18: =Output!AE10 -> 6.1657458 | AJ18: =Output!AF10 -> 3.2786885 | AL18: =Output!AH10 -> 1.1898465 | AM18: =Output!AI10 -> 10 | AN18: =Output!AJ10 -> 0.76923077 | AO18: =Output!AK10 -> -0.037905638 | AP18: =Output!AL10 -> 6.1538462 | AQ18: =Output!AM10 -> 0.1327567 | AR18: =Output!AN10 -> 4.6153846 | AT18: =Output!AP10 -> -0.090909091 | AU18: =Output!AQ10 -> 7 | AV18: =Output!AR10 -> 2.7868852 | AX18: =Output!AT10 -> 11.467269 | AY18: =Output!AU10 -> 8.0327869 | BA18: =Output!AW10 -> 4.1123275 | BB18: =Output!AX10 -> 5.5737705 | BD18: =Output!AZ10 -> 7.9311492 | BE18: =Output!BA10 -> 6 | BF18: =Output!BB10 -> 4.4262295 | BG18: =Output!BC10 -> 0.17849265 | BH18: =Output!BD10 -> 5.5737705 | BI18: =Output!BE10 -> 0.093612562 | BJ18: =Output!BF10 -> 8 | BM18: Teleco | BN18: =Output!BJ10 -> 0 | BO18: =Output!BK10 -> 0 | BP18: =Output!BL10 -> 6.7142857 | BQ18: =Output!BM10 -> Neutral | BR18: =Output!BN10 -> 0 | BU18: =Output!BQ10 -> 0 | BV18: =Output!BR10 -> 1 | BW18: =Output!BS10 -> 5.7142857 | BX18: =Output!BT10 -> Neutral | BY18: =Output!BU10 -> -0.050840092 | BZ18: =Output!BV10 -> -0.025659652
H19: Utilities | I19: =Output!E11 -> 11 | J19: =Output!F11 -> 2.7868852 | L19: =Output!H11 -> 3.8202383 | M19: =Output!I11 -> 2.4590164 | O19: =Output!K11 -> -0.77896414 | P19: =Output!L11 -> 3.6065574 | R19: =Output!N11 -> 161.16847 | S19: =Output!O11 -> 5 | T19: =Output!P11 -> 6.2736444 | V19: =Output!R11 -> 15.274553 | W19: =Output!S11 -> 6.519546 | Y19: =Output!U11 -> 9.3596083 | Z19: =Output!V11 -> 7.3392182 | AB19: =Output!X11 -> 24.749056 | AC19: =Output!Y11 -> 12 | AD19: =Output!Z11 -> 0.6557377 | AF19: =Output!AB11 -> 7.0686782 | AG19: =Output!AC11 -> 0.6557377 | AI19: =Output!AE11 -> 9.2075184 | AJ19: =Output!AF11 -> 0.6557377 | AL19: =Output!AH11 -> 1.3786408 | AM19: =Output!AI11 -> 6 | AN19: =Output!AJ11 -> 2.3076923 | AO19: =Output!AK11 -> -0.008192229 | AP19: =Output!AL11 -> 6.9230769 | AQ19: =Output!AM11 -> 0.22574507 | AR19: =Output!AN11 -> 9.2307692 | AT19: =Output!AP11 -> 0.4 | AU19: =Output!AQ11 -> 3 | AV19: =Output!AR11 -> 6.7213115 | AX19: =Output!AT11 -> 8.8611013 | AY19: =Output!AU11 -> 8.3606557 | BA19: =Output!AW11 -> 3.7008948 | BB19: =Output!AX11 -> 8.852459 | BD19: =Output!AZ11 -> 7.5169853 | BE19: =Output!BA11 -> 1 | BF19: =Output!BB11 -> 9.8360656 | BG19: =Output!BC11 -> 0.1232486 | BH19: =Output!BD11 -> 9.8360656 | BI19: =Output!BE11 -> 0.045158298 | BJ19: =Output!BF11 -> 4 | BM19: Utilities | BN19: =Output!BJ11 -> 2 | BO19: =Output!BK11 -> 4 | BP19: =Output!BL11 -> 8 | BQ19: =Output!BM11 -> Neutral | BR19: =Output!BN11 -> 0 | BU19: =Output!BQ11 -> 1 | BV19: =Output!BR11 -> 2 | BW19: =Output!BS11 -> 8.1428571 | BX19: =Output!BT11 -> Neutral | BY19: =Output!BU11 -> -0.01670002 | BZ19: =Output!BV11 -> 0.0084804198
H20: Travel & leisure | I20: =Output!E12 -> 6 | J20: =Output!F12 -> 7.5409836 | L20: =Output!H12 -> 2.270226 | M20: =Output!I12 -> 2.1311475 | O20: =Output!K12 -> 12.530214 | P20: =Output!L12 -> 4.5901639 | R20: =Output!N12 -> 140.78828 | S20: =Output!O12 -> 11 | T20: =Output!P12 -> 3.4489281 | V20: =Output!R12 -> 8.6825696 | W20: =Output!S12 -> 3.6948298 | Y20: =Output!U12 -> 6.9651861 | Z20: =Output!V12 -> 2.7931904 | AB20: =Output!X12 -> 15.6113 | AC20: =Output!Y12 -> 7 | AD20: =Output!Z12 -> 7.0491803 | AF20: =Output!AB12 -> 6.4467161 | AG20: =Output!AC12 -> 7.0491803 | AI20: =Output!AE12 -> 6.9236286 | AJ20: =Output!AF12 -> 8.5245902 | AL20: =Output!AH12 -> 0.86422859 | AM20: =Output!AI12 -> 8 | AN20: =Output!AJ12 -> 7.6923077 | AO20: =Output!AK12 -> 0.153393 | AP20: =Output!AL12 -> 3.0769231 | AQ20: =Output!AM12 -> 0.01906116 | AR20: =Output!AN12 -> 3.0769231 | AT20: =Output!AP12 -> -0.15384615 | AU20: =Output!AQ12 -> 13 | AV20: =Output!AR12 -> 2.295082 | AX20: =Output!AT12 -> 11.405847 | AY20: =Output!AU12 -> 0.49180328 | BA20: =Output!AW12 -> 5.2466352 | BB20: =Output!AX12 -> 1.6393443 | BD20: =Output!AZ12 -> 8.7677295 | BE20: =Output!BA12 -> 4 | BF20: =Output!BB12 -> 5.5737705 | BG20: =Output!BC12 -> 0.23539098 | BH20: =Output!BD12 -> 6.3934426 | BI20: =Output!BE12 -> 0.16722511 | BJ20: =Output!BF12 -> 10 | BM20: Travel & leisure | BN20: =Output!BJ12 -> 0 | BO20: =Output!BK12 -> 0 | BP20: =Output!BL12 -> 5.5714286 | BQ20: =Output!BM12 -> Neutral | BR20: =Output!BN12 -> 0 | BU20: =Output!BQ12 -> 0 | BV20: =Output!BR12 -> 0 | BW20: =Output!BS12 -> 4.4285714 | BX20: =Output!BT12 -> Neutral | BY20: =Output!BU12 -> -0.019294953 | BZ20: =Output!BV12 -> 0.0058854876
H21: Media | I21: =Output!E13 -> 1 | J21: =Output!F13 -> 5.7377049 | L21: =Output!H13 -> 1.3799431 | M21: =Output!I13 -> 9.0163934 | O21: =Output!K13 -> 36.153504 | P21: =Output!L13 -> 8.852459 | R21: =Output!N13 -> 52.438497 | S21: =Output!O13 -> 9 | T21: =Output!P13 -> 4.0037831 | V21: =Output!R13 -> 14.746342 | W21: =Output!S13 -> 5.3467844 | Y21: =Output!U13 -> 10.100818 | Z21: =Output!V13 -> 4.0037831 | AB21: =Output!X13 -> 21.01695 | AC21: =Output!Y13 -> 4 | AD21: =Output!Z13 -> 9.1803279 | AF21: =Output!AB13 -> 10.431807 | AG21: =Output!AC13 -> 8.5245902 | AI21: =Output!AE13 -> 9.1977671 | AJ21: =Output!AF13 -> 9.0163934 | AL21: =Output!AH13 -> 1.7470843 | AM21: =Output!AI13 -> 11 | AN21: =Output!AJ13 -> 8.4615385 | AO21: =Output!AK13 -> 0.17405353 | AP21: =Output!AL13 -> 1.5384615 | AQ21: =Output!AM13 -> -0.077522896 | AR21: =Output!AN13 -> 0.76923077 | AT21: =Output!AP13 -> -0.57142857 | AU21: =Output!AQ13 -> 8 | AV21: =Output!AR13 -> 3.9344262 | AX21: =Output!AT13 -> 9.433947 | AY21: =Output!AU13 -> 7.0491803 | BA21: =Output!AW13 -> 6.5215206 | BB21: =Output!AX13 -> 4.4262295 | BD21: =Output!AZ13 -> 8.0313612 | BE21: =Output!BA13 -> 6 | BF21: =Output!BB13 -> 1.6393443 | BG21: =Output!BC13 -> 0.21917602 | BH21: =Output!BD13 -> 8.3606557 | BI21: =Output!BE13 -> 0.085880967 | BJ21: =Output!BF13 -> 6 | BM21: Media | BN21: =Output!BJ13 -> 2 | BO21: =Output!BK13 -> 1 | BP21: =Output!BL13 -> 7.5714286 | BQ21: =Output!BM13 -> Neutral | BR21: =Output!BN13 -> 0 | BU21: =Output!BQ13 -> 1 | BV21: =Output!BR13 -> 1 | BW21: =Output!BS13 -> 7.1428571 | BX21: =Output!BT13 -> Neutral | BY21: =Output!BU13 -> -0.044827494 | BZ21: =Output!BV13 -> -0.019647054
H22: Automobile | I22: =Output!E14 -> 13 | J22: =Output!F14 -> 0.32786885 | L22: =Output!H14 -> 5.6573717 | M22: =Output!I14 -> 0.49180328 | O22: =Output!K14 -> 0.019678022 | P22: =Output!L14 -> 0.6557377 | R22: =Output!N14 -> 135.79482 | S22: =Output!O14 -> 13 | T22: =Output!P14 -> 0.54854981 | V22: =Output!R14 -> 2.5611904 | W22: =Output!S14 -> 1.0403531 | Y22: =Output!U14 -> 1.0105513 | Z22: =Output!V14 -> 0.95838588 | AB22: =Output!X14 -> 9.9166825 | AC22: =Output!Y14 -> 8 | AD22: =Output!Z14 -> 4.5901639 | AF22: =Output!AB14 -> 3.199751 | AG22: =Output!AC14 -> 0.16393443 | AI22: =Output!AE14 -> 7.3237932 | AJ22: =Output!AF14 -> 9.1803279 | AL22: =Output!AH14 -> 0.30671046 | AM22: =Output!AI14 -> 13 | AN22: =Output!AJ14 -> 3.0769231 | AO22: =Output!AK14 -> 0.0015710487 | AP22: =Output!AL14 -> 0.76923077 | AQ22: =Output!AM14 -> -0.12051359 | AR22: =Output!AN14 -> 1.5384615 | AT22: =Output!AP14 -> -0.46666667 | AU22: =Output!AQ14 -> 5 | AV22: =Output!AR14 -> 8.0327869 | AX22: =Output!AT14 -> 64.431376 | AY22: =Output!AU14 -> 1.4754098 | BA22: =Output!AW14 -> 1.9925869 | BB22: =Output!AX14 -> 7.8688525 | BD22: =Output!AZ14 -> 12.445815 | BE22: =Output!BA14 -> 9 | BF22: =Output!BB14 -> 3.6065574 | BG22: =Output!BC14 -> 0.25969496 | BH22: =Output!BD14 -> 2.295082 | BI22: =Output!BE14 -> 0.14671131 | BJ22: =Output!BF14 -> 13 | BM22: Automobile | BN22: =Output!BJ14 -> 0 | BO22: =Output!BK14 -> 6 | BP22: =Output!BL14 -> 3.4285714 | BQ22: =Output!BM14 -> Negative | BR22: =Output!BN14 -> 0 | BU22: =Output!BQ14 -> 0 | BV22: =Output!BR14 -> 5 | BW22: =Output!BS14 -> 3.7142857 | BX22: =Output!BT14 -> Negative | BY22: =Output!BU14 -> -0.089917315 | BZ22: =Output!BV14 -> -0.064736875
H26: =TEXT(Output!B2,"[$-040C]mmm-yyyy")&" Commentaire : " -> sept.-2026 Commentaire :

Sheet Output
A1: Marché | B1: EU | D1: Secteur | E1: Leverage | F1: Score net debt ebitda | H1: net debt ebitda | I1: Score fcf total debt | K1: fcf total debt | L1: Score debt equity | N1: debt equity | O1: Margin | P1: Score operating margin | R1: operating margin | S1: Score net margin | U1: net margin | V1: Score ebitda margin | X1: ebitda margin | Y1: Value | Z1: Score price fcf | AB1: price fcf | AC1: Score ev ebitda | AE1: ev ebitda | AF1: Score price sales | AH1: price sales | AI1: Momentum | AJ1: Score momentum 6m 1m | AK1: momentum 6m 1m | AL1: Score momentum 12m 1m | AM1: momentum 12m 1m | AN1: Score earnings revision ratio | AP1: earnings revision ratio | AQ1: Growth | AR1: Score eps growth | AT1: eps growth | AU1: Score sales growth | AW1: sales growth | AX1: Score ebitda growth | AZ1: ebitda growth | BA1: Volatility | BB1: Score volatility 6m | BC1: volatility 6m | BD1: Score downside volatility 18m | BE1: downside volatility 18m | BF1: Macro | BI1: Secteur | BJ1: Votes Top | BK1: Votes Worst | BL1: Score global | BM1: Reco | BN1: Variation reco | BQ1: Votes Top précédents | BR1: Votes Worst précédents | BS1: Score précédent | BT1: Reco précédente | BU1: Sept-2026 EQ Performance | BV1: Sept-2026 XSRet vs FTSE World Europe
A2: Date modèle | B2: 46295 | D2: Materials | E2: 12 | F2: 3.9344262 | H2: 1.5176704 | I2: 0.6557377 | K2: 10.980834 | L2: 0.6557377 | N2: 57.789196 | O2: 10 | P2: 3.3102144 | R2: 8.6551612 | S2: 3.8020177 | U2: 6.0453761 | V2: 2.9003783 | X2: 13.757778 | Y2: 11 | Z2: 0.32786885 | AB2: 8.9422186 | AC2: 0.49180328 | AE2: 7.7631122 | AF2: 1.8032787 | AH2: 1.0583207 | AI2: 4 | AJ2: 6.1538462 | AK2: 0.13038207 | AL2: 9.2307692 | AM2: 0.33963863 | AN2: 6.1538462 | AP2: 0.057142857 | AQ2: 4 | AR2: 5.7377049 | AT2: 18.168167 | AU2: 8.5245902 | AW2: 3.7950325 | AX2: 6.7213115 | AZ2: 10.282517 | BA2: 2 | BB2: 7.3770492 | BC2: 0.18247089 | BD2: 9.3442623 | BE2: 0.062962012 | BF2: 8 | BI2: Materials | BJ2: 1 | BK2: 4 | BL2: 6.7142857 | BM2: Neutral | BN2: 0 | BQ2: 2 | BR2: 3 | BS2: 6.7142857 | BT2: Neutral | BU2: -0.043807237 | BV2: -0.018626796
A3: Derniers piliers | B3: 46295 | D3: ConsStaples | E3: 10 | F3: 4.2622951 | H3: 2.57611 | I3: 7.3770492 | K3: 17.981573 | L3: 0.32786885 | N3: 115.95281 | O3: 12 | P3: 2.9886507 | R3: 11.498439 | S3: 3.3165195 | U3: 7.318707 | V3: 3.3417402 | X3: 15.836251 | Y3: 6 | Z3: 6.7213115 | AB3: 10.04444 | AC3: 7.3770492 | AE3: 9.7333979 | AF3: 9.1803279 | AH3: 1.1770891 | AI3: 9 | AJ3: 4.6153846 | AK3: 0.02999415 | AL3: 3.8461538 | AM3: 0.042321296 | AN3: 3.8461538 | AP3: -0.11363636 | AQ3: 11 | AR3: 3.9344262 | AT3: 6.9131176 | AU3: 2.9508197 | AW3: 3.6888091 | AX3: 3.442623 | AZ3: 4.8960757 | BA3: 12 | BB3: 3.2786885 | BC3: 0.18050462 | BD3: 1.147541 | BE3: 0.11597345 | BF3: 12 | BI3: ConsStaples | BJ3: 0 | BK3: 5 | BL3: 3.7142857 | BM3: Negative | BN3: 0 | BQ3: 0 | BR3: 3 | BS3: 4.1428571 | BT3: Negative | BU3: -0.032147216 | BV3: -0.0069667762
A4: Allocation | B4: 46296 | D4: Pers. Goods | E4: 4 | F4: 4.9180328 | H4: 0.73907005 | I4: 7.2131148 | K4: 33.20084 | L4: 3.6065574 | N4: 58.519142 | O4: 8 | P4: 4.4766709 | R4: 18.044296 | S4: 4.9117276 | U4: 11.481202 | V4: 4.8549811 | X4: 25.277612 | Y4: 2 | Z4: 10 | AB4: 14.473667 | AC4: 10 | AE4: 11.329662 | AF4: 10 | AH4: 2.7591781 | AI4: 12 | AJ4: 5.3846154 | AK4: 0.09934833 | AL4: 2.3076923 | AM4: -0.026194227 | AN4: 2.3076923 | AP4: -0.38461538 | AQ4: 12 | AR4: 3.7704918 | AT4: 13.004314 | AU4: 2.1311475 | AW4: 6.0954359 | AX4: 2.6229508 | AZ4: 7.7301313 | BA4: 7 | BB4: 5.4098361 | BC4: 0.25442201 | BD4: 2.1311475 | BE4: 0.18750445 | BF4: 9 | BI4: Pers. Goods | BJ4: 2 | BK4: 2 | BL4: 6.2857143 | BM4: Neutral | BN4: 1 | BQ4: 1 | BR4: 4 | BS4: 6.2857143 | BT4: Negative | BU4: -0.079729636 | BV4: -0.054549195
A5: Cycle | B5: E | D5: Fin | E5: 2 | F5: 7.0491803 | H5: 10.11696 | I5: 3.1147541 | K5: 2.8015014 | L5: 8.6885246 | N5: 417.95205 | O5: 3 | P5: 7.7805801 | R5: 17.486197 | S5: 8.6569987 | U5: 12.648923 | V5: 7.0491803 | X5: 51.665548 | Y5: n.a. | Z5: n.a. | AB5: n.a. | AC5: n.a. | AE5: n.a. | AF5: 0.32786885 | AH5: 2.1662574 | AI5: 1 | AJ5: 9.2307692 | AK5: 0.23881973 | AL5: 8.4615385 | AM5: 0.2750319 | AN5: 6.9230769 | AP5: 0.17094017 | AQ5: 9 | AR5: 4.0983607 | AT5: 10.637174 | AU5: 5.5737705 | AW5: 5.0359127 | AX5: n.a. | AZ5: n.a. | BA5: 8 | BB5: 2.7868852 | BC5: 0.20099649 | BD5: 3.442623 | BE5: 0.12262943 | BF5: n.a. | BI5: Fin | BJ5: 4 | BK5: 0 | BL5: n.a. | BM5: Positive | BN5: 0 | BQ5: 3 | BR5: 0 | BS5: n.a. | BT5: Positive | BU5: -0.029492517 | BV5: -0.0043120766
A6: Signal taux | B6: On | D6: HealthCare | E6: 5 | F6: 5.0819672 | H6: 1.5089102 | I6: 7.8688525 | K6: 28.807423 | L6: 1.9672131 | N6: 66.839496 | O6: 1 | P6: 9.4262295 | R6: 23.281359 | S6: 7.8940731 | U6: 16.548002 | V6: 9.2307692 | X6: 31.620939 | Y6: 3 | Z6: 8.3606557 | AB6: 12.337819 | AC6: 8.852459 | AE6: 10.802642 | AF6: 9.5081967 | AH6: 2.9853111 | AI6: 7 | AJ6: 3.8461538 | AK6: 0.024259956 | AL6: 4.6153846 | AM6: 0.1062622 | AN6: 8.4615385 | AP6: 0.35555556 | AQ6: 10 | AR6: 3.9344262 | AT6: 8.06437 | AU6: 3.7704918 | AW6: 5.4978133 | AX6: 3.6065574 | AZ6: 7.6618302 | BA6: 3 | BB6: 8.0327869 | BC6: 0.12836426 | BD6: 7.3770492 | BE6: 0.085948425 | BF6: 3 | BI6: HealthCare | BJ6: 6 | BK6: 0 | BL6: 9.4285714 | BM6: Positive | BN6: 1 | BQ6: 2 | BR6: 0 | BS6: 8.5714286 | BT6: Neutral | BU6: -0.030060214 | BV6: -0.0048797734
A7: Derniers poids benchmark | B7: 46326 | D7: Indus | E7: 3 | F7: 4.2622951 | H7: 1.6366061 | I7: 10 | K7: 22.892464 | L7: 2.295082 | N7: 85.294826 | O7: 7 | P7: 4.4892812 | R7: 11.077253 | S7: 5.3152585 | U7: 7.5557529 | V7: 5.2017654 | X7: 15.843936 | Y7: 10 | Z7: 1.3114754 | AB7: 13.814605 | AC7: 1.4754098 | AE7: 11.854577 | AF7: 1.3114754 | AH7: 1.7658251 | AI7: 5 | AJ7: 6.9230769 | AK7: 0.13319026 | AL7: 5.3846154 | AM7: 0.10708826 | AN7: 7.6923077 | AP7: 0.23478261 | AQ7: 2 | AR7: 6.7213115 | AT7: 16.132483 | AU7: 10 | AW7: 7.5180213 | AX7: 7.5409836 | AZ7: 10.381888 | BA7: 12 | BB7: 3.6065574 | BC7: 0.21927049 | BD7: 0.81967213 | BE7: 0.14291346 | BF7: 6 | BI7: Indus | BJ7: 3 | BK7: 1 | BL7: 7.5714286 | BM7: Neutral | BN7: 0 | BQ7: 2 | BR7: 2 | BS7: 7.4285714 | BT7: Neutral | BU7: -0.037750141 | BV7: -0.012569701
A8: Derniers rendements | B8: 46295 | D8: Oil | E8: 9 | F8: 5.2459016 | H8: 0.75166269 | I8: 5.2459016 | K8: 26.597811 | L8: 1.9672131 | N8: 62.418637 | O8: 6 | P8: 5.258512 | R8: 12.707879 | S8: 6.7339218 | U8: 7.516947 | V8: 5.4224464 | X8: 19.852902 | Y8: 13 | Z8: 0.32786885 | AB8: 5.34985 | AC8: 0.81967213 | AE8: 4.7964169 | AF8: 0.6557377 | AH8: 0.87351089 | AI8: 4 | AJ8: 1.5384615 | AK8: -0.030101683 | AL8: 10 | AM8: 0.41327662 | AN8: 10 | AP8: 0.77272727 | AQ8: 7 | AR8: 7.5409836 | AT8: 13.270838 | AU8: 1.8032787 | AW8: -0.3291555 | AX8: 7.0491803 | AZ8: 1.6743774 | BA8: 13 | BB8: 0.49180328 | BC8: 0.27017194 | BD8: 1.8032787 | BE8: 0.16184847 | BF8: 11 | BI8: Oil | BJ8: 0 | BK8: 5 | BL8: 5 | BM8: Negative | BN8: -2 | BQ8: 3 | BR8: 1 | BS8: 7.5714286 | BT8: Positive | BU8: 0.03336263 | BV8: 0.05854307
A9: Mois allocation | B9: 46296 | D9: Tech | E9: 8 | F9: 5.0819672 | H9: 0.43980775 | I9: 7.3770492 | K9: 51.01086 | L9: 0.49180328 | N9: 42.505912 | O9: 2 | P9: 8.8776797 | R9: 23.063598 | S9: 8.6065574 | U9: 21.193798 | V9: 8.3543506 | X9: 29.081963 | Y9: 5 | Z9: 8.1081081 | AB9: 21.186471 | AC9: 7.5675676 | AE9: 18.199697 | AF9: 0.6557377 | AH9: 6.0528066 | AI9: 2 | AJ9: 10 | AK9: 0.32019032 | AL9: 7.6923077 | AM9: 0.26770248 | AN9: 5.3846154 | AP9: -0.045454545 | AQ9: 1 | AR9: 8.1967213 | AT9: 27.448513 | AU9: 10 | AW9: 15.915395 | AX9: 9.6721311 | AZ9: 24.497585 | BA9: 10 | BB9: 0.81967213 | BC9: 0.32402071 | BD9: 4.4262295 | BE9: 0.12996419 | BF9: 2 | BI9: Tech | BJ9: 5 | BK9: 0 | BL9: 9.7142857 | BM9: Positive | BN9: 0 | BQ9: 6 | BR9: 0 | BS9: 9.8571429 | BT9: Positive | BU9: 0.04026688 | BV9: 0.06544732
A10: Mois signal | B10: 46266 | D10: Telco | E10: 7 | F10: 6.2295082 | H10: 2.6984758 | I10: 6.2295082 | K10: 14.772993 | L10: 0.98360656 | N10: 168.09143 | O10: 4 | P10: 6.8221942 | R10: 15.845054 | S10: 4.6532156 | U10: 6.9782061 | V10: 8.7137453 | X10: 36.809322 | Y10: 9 | Z10: 1.9672131 | AB10: 4.3402105 | AC10: 4.5901639 | AE10: 6.1657458 | AF10: 3.2786885 | AH10: 1.1898465 | AI10: 10 | AJ10: 0.76923077 | AK10: -0.037905638 | AL10: 6.1538462 | AM10: 0.1327567 | AN10: 4.6153846 | AP10: -0.090909091 | AQ10: 7 | AR10: 2.7868852 | AT10: 11.467269 | AU10: 8.0327869 | AW10: 4.1123275 | AX10: 5.5737705 | AZ10: 7.9311492 | BA10: 6 | BB10: 4.4262295 | BC10: 0.17849265 | BD10: 5.5737705 | BE10: 0.093612562 | BF10: 8 | BI10: Telco | BJ10: 0 | BK10: 0 | BL10: 6.7142857 | BM10: Neutral | BN10: 0 | BQ10: 0 | BR10: 1 | BS10: 5.7142857 | BT10: Neutral | BU10: -0.050840092 | BV10: -0.025659652
A11: Classement courant | B11: Sectors Ranking Oct-2026 | D11: Utili | E11: 11 | F11: 2.7868852 | H11: 3.8202383 | I11: 2.4590164 | K11: -0.77896414 | L11: 3.6065574 | N11: 161.16847 | O11: 5 | P11: 6.2736444 | R11: 15.274553 | S11: 6.519546 | U11: 9.3596083 | V11: 7.3392182 | X11: 24.749056 | Y11: 12 | Z11: 0.6557377 | AB11: 7.0686782 | AC11: 0.6557377 | AE11: 9.2075184 | AF11: 0.6557377 | AH11: 1.3786408 | AI11: 6 | AJ11: 2.3076923 | AK11: -0.008192229 | AL11: 6.9230769 | AM11: 0.22574507 | AN11: 9.2307692 | AP11: 0.4 | AQ11: 3 | AR11: 6.7213115 | AT11: 8.8611013 | AU11: 8.3606557 | AW11: 3.7008948 | AX11: 8.852459 | AZ11: 7.5169853 | BA11: 1 | BB11: 9.8360656 | BC11: 0.1232486 | BD11: 9.8360656 | BE11: 0.045158298 | BF11: 4 | BI11: Utili | BJ11: 2 | BK11: 4 | BL11: 8 | BM11: Neutral | BN11: 0 | BQ11: 1 | BR11: 2 | BS11: 8.1428571 | BT11: Neutral | BU11: -0.01670002 | BV11: 0.0084804198
A12: Classement précédent | B12: Sectors Ranking Sept-2026 | D12: Travel & leisure | E12: 6 | F12: 7.5409836 | H12: 2.270226 | I12: 2.1311475 | K12: 12.530214 | L12: 4.5901639 | N12: 140.78828 | O12: 11 | P12: 3.4489281 | R12: 8.6825696 | S12: 3.6948298 | U12: 6.9651861 | V12: 2.7931904 | X12: 15.6113 | Y12: 7 | Z12: 7.0491803 | AB12: 6.4467161 | AC12: 7.0491803 | AE12: 6.9236286 | AF12: 8.5245902 | AH12: 0.86422859 | AI12: 8 | AJ12: 7.6923077 | AK12: 0.153393 | AL12: 3.0769231 | AM12: 0.01906116 | AN12: 3.0769231 | AP12: -0.15384615 | AQ12: 13 | AR12: 2.295082 | AT12: 11.405847 | AU12: 0.49180328 | AW12: 5.2466352 | AX12: 1.6393443 | AZ12: 8.7677295 | BA12: 4 | BB12: 5.5737705 | BC12: 0.23539098 | BD12: 6.3934426 | BE12: 0.16722511 | BF12: 10 | BI12: Travel & leisure | BJ12: 0 | BK12: 0 | BL12: 5.5714286 | BM12: Neutral | BN12: 0 | BQ12: 0 | BR12: 0 | BS12: 4.4285714 | BT12: Neutral | BU12: -0.019294953 | BV12: 0.0058854876
A13: Classement macro | B13: Macro rank - Currently in Expansion | D13: Media | E13: 1 | F13: 5.7377049 | H13: 1.3799431 | I13: 9.0163934 | K13: 36.153504 | L13: 8.852459 | N13: 52.438497 | O13: 9 | P13: 4.0037831 | R13: 14.746342 | S13: 5.3467844 | U13: 10.100818 | V13: 4.0037831 | X13: 21.01695 | Y13: 4 | Z13: 9.1803279 | AB13: 10.431807 | AC13: 8.5245902 | AE13: 9.1977671 | AF13: 9.0163934 | AH13: 1.7470843 | AI13: 11 | AJ13: 8.4615385 | AK13: 0.17405353 | AL13: 1.5384615 | AM13: -0.077522896 | AN13: 0.76923077 | AP13: -0.57142857 | AQ13: 8 | AR13: 3.9344262 | AT13: 9.433947 | AU13: 7.0491803 | AW13: 6.5215206 | AX13: 4.4262295 | AZ13: 8.0313612 | BA13: 6 | BB13: 1.6393443 | BC13: 0.21917602 | BD13: 8.3606557 | BE13: 0.085880967 | BF13: 6 | BI13: Media | BJ13: 2 | BK13: 1 | BL13: 7.5714286 | BM13: Neutral | BN13: 0 | BQ13: 1 | BR13: 1 | BS13: 7.1428571 | BT13: Neutral | BU13: -0.044827494 | BV13: -0.019647054
A14: Référence | B14: Bench | D14: Auto | E14: 13 | F14: 0.32786885 | H14: 5.6573717 | I14: 0.49180328 | K14: 0.019678022 | L14: 0.6557377 | N14: 135.79482 | O14: 13 | P14: 0.54854981 | R14: 2.5611904 | S14: 1.0403531 | U14: 1.0105513 | V14: 0.95838588 | X14: 9.9166825 | Y14: 8 | Z14: 4.5901639 | AB14: 3.199751 | AC14: 0.16393443 | AE14: 7.3237932 | AF14: 9.1803279 | AH14: 0.30671046 | AI14: 13 | AJ14: 3.0769231 | AK14: 0.0015710487 | AL14: 0.76923077 | AM14: -0.12051359 | AN14: 1.5384615 | AP14: -0.46666667 | AQ14: 5 | AR14: 8.0327869 | AT14: 64.431376 | AU14: 1.4754098 | AW14: 1.9925869 | AX14: 7.8688525 | AZ14: 12.445815 | BA14: 9 | BB14: 3.6065574 | BC14: 0.25969496 | BD14: 2.295082 | BE14: 0.14671131 | BF14: 13 | BI14: Auto | BJ14: 0 | BK14: 6 | BL14: 3.4285714 | BM14: Negative | BN14: 0 | BQ14: 0 | BR14: 5 | BS14: 3.7142857 | BT14: Negative | BU14: -0.089917315 | BV14: -0.064736875
A15: Top | B15: 0.014712331
A16: Short | B16: 0.067264722
A17: Long / Short | B17: 0.081977053
A18: Portefeuille | B18: -0.015123767
A19: Benchmark | B19: -0.02518044
D22: EU Reco | E22: 45870 | F22: 45901 | G22: 45931 | H22: 45962 | I22: 45992 | J22: 46023 | K22: 46054 | L22: 46082 | M22: 46113 | N22: 46143 | O22: 46174 | P22: 46204 | Q22: 46235 | R22: 46266 | S22: 46296 | W22: Europe equity sectors Performance
D23: Materials | E23: 0 | F23: -1 | G23: -1 | H23: -1 | I23: -1 | J23: 0 | K23: 0 | L23: 0 | M23: 0 | N23: 1 | O23: 0 | P23: 1 | Q23: -1 | R23: 0 | S23: 0 | W23: Materials | X23: ConsStaples | Y23: Pers. Goods | Z23: Fin | AA23: HealthCare | AB23: Indus | AC23: Oil | AD23: Tech | AE23: Telco | AF23: Utili | AG23: Travel & leisure | AH23: Media | AI23: Auto
D24: ConsStaples | E24: 0 | F24: -1 | G24: -1 | H24: -1 | I24: -1 | J24: -1 | K24: -1 | L24: -1 | M24: -1 | N24: -1 | O24: -1 | P24: -1 | Q24: -1 | R24: -1 | S24: -1 | V24: 1M | W24: -0.043807237 | X24: -0.032147216 | Y24: -0.079729636 | Z24: -0.029492517 | AA24: -0.030060214 | AB24: -0.037750141 | AC24: 0.03336263 | AD24: 0.04026688 | AE24: -0.050840092 | AF24: -0.01670002 | AG24: -0.019294953 | AH24: -0.044827494 | AI24: -0.089917315
D25: Pers. Goods | E25: -1 | F25: 0 | G25: -1 | H25: 0 | I25: 0 | J25: -1 | K25: -1 | L25: -1 | M25: -1 | N25: -1 | O25: -1 | P25: -1 | Q25: 0 | R25: -1 | S25: 0 | V25: 3M | W25: 0.0427452 | X25: -0.048685946 | Y25: -0.09940537 | Z25: 0.036457237 | AA25: -0.051903929 | AB25: -0.028227302 | AC25: 0.13910881 | AD25: -0.026489059 | AE25: -0.048274053 | AF25: -0.045405094 | AG25: -0.063303054 | AH25: -0.026007204 | AI25: -0.026321971
D26: Fin | E26: 1 | F26: 1 | G26: 1 | H26: 1 | I26: 1 | J26: 1 | K26: 1 | L26: 1 | M26: 0 | N26: 0 | O26: 0 | P26: 0 | Q26: 0 | R26: 1 | S26: 1 | V26: YTD | W26: 0.22073486 | X26: -0.0001503357 | Y26: -0.17485053 | Z26: 0.16749572 | AA26: -0.010645471 | AB26: 0.070164104 | AC26: 0.39359227 | AD26: 0.28613537 | AE26: 0.087179055 | AF26: 0.12140323 | AG26: 0.018879819 | AH26: -0.072138314 | AI26: -0.17995834
D27: HealthCare | E27: 0 | F27: 0 | G27: 0 | H27: 0 | I27: 0 | J27: 0 | K27: 1 | L27: 0 | M27: 0 | N27: 0 | O27: 0 | P27: 0 | Q27: 0 | R27: 0 | S27: 1 | V27: 1Y | W27: 0.31520465 | X27: 0.046128609 | Y27: -0.089127272 | Z27: 0.29042655 | AA27: 0.099695101 | AB27: 0.085445802 | AC27: 0.51707098 | AD27: 0.28048153 | AE27: 0.11406794 | AF27: 0.24203082 | AG27: 0.024036422 | AH27: -0.0908249 | AI27: -0.16439077
D28: Indus | E28: 0 | F28: 0 | G28: 0 | H28: 0 | I28: 0 | J28: 0 | K28: 0 | L28: 0 | M28: -1 | N28: -1 | O28: 0 | P28: 0 | Q28: 0 | R28: 0 | S28: 0 | V28: 3Y | W28: 0.36726095 | X28: 0.063035257 | Y28: -0.11975984 | Z28: 1.3891311 | AA28: 0.12144016 | AB28: 0.70067364 | AC28: 0.66171784 | AD28: 0.84747424 | AE28: 0.57951211 | AF28: 0.70034887 | AG28: 0.26833428 | AH28: 0.10217513 | AI28: -0.17698084
D29: Oil | E29: -1 | F29: 0 | G29: 0 | H29: -1 | I29: 0 | J29: -1 | K29: -1 | L29: -1 | M29: 0 | N29: 0 | O29: 1 | P29: 0 | Q29: 0 | R29: 1 | S29: -1 | V29: 5Y | W29: 0.40166616 | X29: 0.059002477 | Y29: -0.042604777 | Z29: 1.8750191 | AA29: 0.25863487 | AB29: 0.69887572 | AC29: 1.4414555 | AD29: 0.66434199 | AE29: 0.44506623 | AF29: 0.87762153 | AG29: 0.18631449 | AH29: 0.30160625 | AI29: -0.099462702
D30: Tech | E30: 0 | F30: 1 | G30: 1 | H30: 1 | I30: 1 | J30: 1 | K30: 1 | L30: 1 | M30: 1 | N30: 1 | O30: 1 | P30: 1 | Q30: 1 | R30: 1 | S30: 1
D31: Telco | E31: 1 | F31: 0 | G31: 1 | H31: 1 | I31: 0 | J31: 0 | K31: 0 | L31: 1 | M31: 0 | N31: 0 | O31: 0 | P31: 0 | Q31: 0 | R31: 0 | S31: 0
D32: Utili | E32: 1 | F32: 1 | G32: 0 | H32: 0 | I32: 1 | J32: 1 | K32: 0 | L32: 0 | M32: 1 | N32: 1 | O32: 1 | P32: 1 | Q32: 1 | R32: 0 | S32: 0
D33: Travel & leisure | E33: 0 | F33: 0 | G33: 0 | H33: 0 | I33: 0 | J33: 0 | K33: 0 | L33: 0 | M33: 0 | N33: 0 | O33: 0 | P33: 0 | Q33: 0 | R33: 0 | S33: 0
D34: Media | E34: 0 | F34: 0 | G34: 0 | H34: 0 | I34: -1 | J34: 0 | K34: 0 | L34: 0 | M34: 1 | N34: 0 | O34: 0 | P34: 0 | Q34: 1 | R34: 0 | S34: 0
D35: Auto | E35: -1 | F35: -1 | G35: 0 | H35: 0 | I35: 0 | J35: 0 | K35: 0 | L35: 0 | M35: 0 | N35: 0 | O35: -1 | P35: -1 | Q35: -1 | R35: -1 | S35: -1
D38: Variable | E38: Secteur | F38: 46295 | G38: 46265 | H38: 46234 | I38: 46203 | J38: 46173 | K38: 46142 | L38: 46112 | M38: 46081 | N38: 46053 | O38: 46022 | P38: 45991 | Q38: 45961 | R38: 45930 | S38: 45900 | T38: 45869 | U38: 45838 | V38: 45808 | W38: 45777 | X38: 45747 | Y38: 45716 | Z38: 45688 | AA38: 45657 | AB38: 45626 | AC38: 45596 | AD38: 45565 | AE38: 45535 | AF38: 45504 | AG38: 45473 | AH38: 45443 | AI38: 45412 | AJ38: 45382 | AK38: 45351 | AL38: 45322 | AM38: 45291 | AN38: 45260 | AO38: 45230 | AP38: 45199 | AQ38: 45169 | AR38: 45138 | AS38: 45107 | AT38: 45077 | AU38: 45046 | AV38: 45016 | AW38: 44985 | AX38: 44957 | AY38: 44926 | AZ38: 44895 | BA38: 44865 | BB38: 44834 | BC38: 44804 | BD38: 44773 | BE38: 44742 | BF38: 44712 | BG38: 44681 | BH38: 44651 | BI38: 44620 | BJ38: 44592 | BK38: 44561 | BL38: 44530 | BM38: 44500
D39: net_debt_ebitda | E39: Materials | F39: -1.1833336 | G39: -1.1089537 | H39: -1.3648645 | I39: -1.3669497 | J39: -1.316195 | K39: -0.89222034 | L39: -0.89743153 | M39: -0.89387337 | N39: -1.2197486 | O39: -1.2234747 | P39: -1.2397965 | Q39: -0.85701623 | R39: -0.83641595 | S39: -0.82547232 | T39: -1.2197704 | U39: -1.2293163 | V39: -1.1731623 | W39: -0.69356232 | X39: -0.69397548 | Y39: -0.69959511 | Z39: -0.76612943 | AA39: -0.76997227 | AB39: -0.77010926 | AC39: -0.85303497 | AD39: -0.85059628 | AE39: -0.84238892 | AF39: -0.9077245 | AG39: -0.90142122 | AH39: -0.90198046 | AI39: -0.9748874 | AJ39: -0.96390473 | AK39: -0.97229296 | AL39: -1.6414242 | AM39: -1.6244064 | AN39: -1.6335519 | AO39: -1.2039697 | AP39: -1.2020554 | AQ39: -1.1991678 | AR39: -1.8687748 | AS39: -1.9183149 | AT39: -1.9362559 | AU39: -1.5320233 | AV39: -1.5568659 | AW39: -1.5110515 | AX39: -1.9779994 | AY39: -1.8806666 | AZ39: -1.8466724 | BA39: -1.8271768 | BB39: -1.8867189 | BC39: -1.8532664 | BD39: -2.3065876 | BE39: -2.2302514 | BF39: -2.3128409 | BG39: -2.2010161 | BH39: -2.2727873 | BI39: -2.3163657 | BJ39: -2.6460549 | BK39: -2.8651562 | BL39: -2.8283226 | BM39: -3.5696113
D40: net_debt_ebitda | E40: ConsStaples | F40: -0.12489404 | G40: -0.060838076 | H40: -0.54054818 | I40: -0.5403058 | J40: -0.5594406 | K40: -0.15315852 | L40: -0.14690004 | M40: -0.17514738 | N40: -0.20470101 | O40: -0.22367374 | P40: -0.21691049 | Q40: 0.11611023 | R40: 0.12201772 | S40: 0.10229786 | T40: -0.27094963 | U40: -0.27244637 | V40: -0.24745042 | W40: 0.12271103 | X40: 0.10929875 | Y40: 0.098832522 | Z40: 0.14555369 | AA40: 0.13643835 | AB40: 0.15328883 | AC40: 0.11151459 | AD40: 0.11208674 | AE40: 0.12023993 | AF40: 0.047467194 | AG40: 0.041979773 | AH40: 0.062732492 | AI40: -0.007735934 | AJ40: 0.0049033798 | AK40: -0.0019103086 | AL40: -0.31925737 | AM40: -0.33473832 | AN40: -0.33182771 | AO40: 0.15568788 | AP40: 0.16796374 | AQ40: 0.15946946 | AR40: -0.44880501 | AS40: -0.46715923 | AT40: -0.47985286 | AU40: -0.12199598 | AV40: -0.10436356 | AW40: -0.11785936 | AX40: -0.29832498 | AY40: -0.20786126 | AZ40: -0.21188648 | BA40: -0.17213898 | BB40: -0.17485124 | BC40: -0.18008225 | BD40: -0.76051896 | BE40: -0.75602723 | BF40: -0.77492241 | BG40: -0.7242952 | BH40: -0.79678657 | BI40: -0.80923509 | BJ40: -1.0803497 | BK40: -1.065819 | BL40: -1.0713966 | BM40: -1.7827848
D41: net_debt_ebitda | E41: Pers. Goods | F41: -1.961934 | G41: -1.8741242 | H41: -2.2661089 | I41: -2.2804201 | J41: -2.2448421 | K41: -1.8508127 | L41: -1.8804456 | M41: -1.8967963 | N41: -2.0133267 | O41: -2.0035086 | P41: -2.0293782 | Q41: -1.7533558 | R41: -1.7130936 | S41: -1.7475286 | T41: -1.9859109 | U41: -2.0033002 | V41: -1.9305588 | W41: -1.5692666 | X41: -1.5711057 | Y41: -1.5644353 | Z41: -1.4191301 | AA41: -1.4170273 | AB41: -1.4395392 | AC41: -1.6048561 | AD41: -1.5882143 | AE41: -1.5731301 | AF41: -1.5909249 | AG41: -1.579986 | AH41: -1.5539598 | AI41: -1.6756413 | AJ41: -1.6721401 | AK41: -1.6948991 | AL41: -2.1849494 | AM41: -2.1564806 | AN41: -2.1345775 | AO41: -1.7222003 | AP41: -1.7200456 | AQ41: -1.7351729 | AR41: -2.2046983 | AS41: -2.2595602 | AT41: -2.2580552 | AU41: -1.8189468 | AV41: -1.845697 | AW41: -1.8227348 | AX41: -2.2534794 | AY41: -2.1564583 | AZ41: -2.1150048 | BA41: -2.1424059 | BB41: -2.216454 | BC41: -2.1806656 | BD41: -2.6701702 | BE41: -2.5792806 | BF41: -2.6507404 | BG41: -2.5177027 | BH41: -2.5860364 | BI41: -2.6553016 | BJ41: -2.9802671 | BK41: -2.992544 | BL41: -2.978761 | BM41: -3.7058429
D42: net_debt_ebitda | E42: Fin | F42: 7.4159561 | G42: 6.4794726 | H42: 11.805699 | I42: 11.863528 | J42: 11.79832 | K42: 8.0511556 | L42: 8.1833137 | M42: 7.9847409 | N42: 11.284631 | O42: 11.350897 | P42: 11.448198 | Q42: 7.2677131 | R42: 7.0746248 | S42: 7.3436517 | T42: 11.843701 | U42: 11.945076 | V42: 11.302872 | W42: 7.0340717 | X42: 7.0798236 | Y42: 6.9820333 | Z42: 5.9388225 | AA42: 5.9682129 | AB42: 5.9718288 | AC42: 6.9622761 | AD42: 6.9002668 | AE42: 6.8908117 | AF42: 7.1768962 | AG42: 7.1166561 | AH42: 7.1064971 | AI42: 8.8512626 | AJ42: 8.8006103 | AK42: 8.9445341 | AL42: 13.821553 | AM42: 13.706896 | AN42: 13.574999 | AO42: 7.8499878 | AP42: 7.8900645 | AQ42: 7.9386427 | AR42: 13.758532 | AS42: 14.147798 | AT42: 14.307221 | AU42: 8.6584375 | AV42: 8.841965 | AW42: 8.4403859 | AX42: 11.162758 | AY42: 10.03157 | AZ42: 9.834278 | BA42: 8.8335447 | BB42: 8.9062247 | BC42: 8.8176936 | BD42: 12.343276 | BE42: 11.840635 | BF42: 12.258457 | BG42: 8.5208549 | BH42: 8.4301251 | BI42: 8.5687217 | BJ42: 9.9907089 | BK42: 10.132468 | BL42: 10.015146 | BM42: 5.4661317
D43: net_debt_ebitda | E43: HealthCare | F43: -1.1920938 | G43: -1.1139941 | H43: -1.457199 | I43: -1.4658077 | J43: -1.4605678 | K43: -1.2331533 | L43: -1.2477767 | M43: -1.256427 | N43: -1.5047175 | O43: -1.5019102 | P43: -1.5195568 | Q43: -1.1455167 | R43: -1.1195116 | S43: -1.1894332 | T43: -1.3011006 | U43: -1.3122482 | V43: -1.2666432 | W43: -0.95337886 | X43: -0.95449562 | Y43: -0.94136116 | Z43: -0.78484282 | AA43: -0.79074661 | AB43: -0.79735044 | AC43: -0.81269464 | AD43: -0.80722024 | AE43: -0.7988802 | AF43: -0.76757705 | AG43: -0.7665156 | AH43: -0.74552725 | AI43: -0.98245314 | AJ43: -0.9725472 | AK43: -0.98157515 | AL43: -1.3519547 | AM43: -1.3435758 | AN43: -1.3236664 | AO43: -0.77379804 | AP43: -0.74614033 | AQ43: -0.75490724 | AR43: -1.2379518 | AS43: -1.2694126 | AT43: -1.2853123 | AU43: -0.99064831 | AV43: -1.0038667 | AW43: -0.96776732 | AX43: -1.2576655 | AY43: -1.166796 | AZ43: -1.1471933 | BA43: -1.088085 | BB43: -1.128136 | BC43: -1.0393622 | BD43: -1.491177 | BE43: -1.4355412 | BF43: -1.4800695 | BG43: -1.4389928 | BH43: -1.513319 | BI43: -1.5912606 | BJ43: -1.9709991 | BK43: -1.9648794 | BL43: -1.9438682 | BM43: -2.6023326
D44: net_debt_ebitda | E44: Indus | F44: -1.0643979 | G44: -0.96381168 | H44: -1.3472502 | I44: -1.3592243 | J44: -1.3625301 | K44: -1.0405681 | L44: -1.0513062 | M44: -1.06652 | N44: -1.1451506 | O44: -1.1359613 | P44: -1.1569549 | Q44: -0.79070373 | R44: -0.77986496 | S44: -0.79476101 | T44: -1.1902913 | U44: -1.200215 | V44: -1.1764526 | W44: -0.85276129 | X44: -0.85463008 | Y44: -0.85370507 | Z44: -0.48847026 | AA44: -0.49236828 | AB44: -0.49041129 | AC44: -0.6281815 | AD44: -0.62686175 | AE44: -0.65096992 | AF44: -0.75271756 | AG44: -0.75222005 | AH44: -0.73362258 | AI44: -0.94529404 | AJ44: -0.93980185 | AK44: -0.95650561 | AL44: -1.2510981 | AM44: -1.2432124 | AN44: -1.1947266 | AO44: -0.77308201 | AP44: -0.76516862 | AQ44: -0.78272829 | AR44: -1.4139133 | AS44: -1.4475174 | AT44: -1.4531938 | AU44: -1.0593523 | AV44: -1.078016 | AW44: -1.0690384 | AX44: -1.3564038 | AY44: -1.2642554 | AZ44: -1.2391787 | BA44: -1.0772179 | BB44: -1.1238061 | BC44: -1.1392352 | BD44: -1.5685125 | BE44: -1.5216369 | BF44: -1.5713194 | BG44: -1.4890144 | BH44: -1.5620161 | BI44: -1.6038058 | BJ44: -1.8570448 | BK44: -1.8719268 | BL44: -1.8635956 | BM44: -2.5483514
...

Sheet Reco_histo
B1: Top | O1: Worst
B2: Materials | C2: ConsStaples | D2: Pers. Goods | E2: Fin | F2: HealthCare | G2: Indus | H2: Oil | I2: Tech | J2: Telco | K2: Utili | L2: Travel & leisure | M2: Media | N2: Auto | O2: Materials | P2: ConsStaples | Q2: Pers. Goods | R2: Fin | S2: HealthCare | T2: Indus | U2: Oil | V2: Tech | W2: Telco | X2: Utili | Y2: Travel & leisure | Z2: Media | AA2: Auto
A3: 40235 | B3: 1 | C3: 0 | D3: 0 | E3: 0 | F3: 0 | G3: 1 | H3: 0 | I3: 1 | J3: 0 | K3: 0 | L3: 0 | M3: 0 | N3: 0 | O3: 0 | P3: 0 | Q3: 0 | R3: 0 | S3: 0 | T3: 0 | U3: 0 | V3: 0 | W3: 1 | X3: 1 | Y3: 0 | Z3: 0 | AA3: 1
A4: 40268 | B4: 0 | C4: 1 | D4: 1 | E4: 0 | F4: 1 | G4: 0 | H4: 0 | I4: 0 | J4: 0 | K4: 0 | L4: 0 | M4: 0 | N4: 0 | O4: 0 | P4: 0 | Q4: 0 | R4: 0 | S4: 0 | T4: 0 | U4: 0 | V4: 0 | W4: 0 | X4: 1 | Y4: 0 | Z4: 0 | AA4: 1
A5: 40298 | B5: 0 | C5: 0 | D5: 1 | E5: 0 | F5: 1 | G5: 0 | H5: 0 | I5: 0 | J5: 0 | K5: 0 | L5: 0 | M5: 1 | N5: 0 | O5: 0 | P5: 0 | Q5: 0 | R5: 1 | S5: 0 | T5: 0 | U5: 0 | V5: 0 | W5: 0 | X5: 0 | Y5: 0 | Z5: 0 | AA5: 1
A6: 40326 | B6: 0 | C6: 1 | D6: 1 | E6: 0 | F6: 0 | G6: 0 | H6: 0 | I6: 0 | J6: 0 | K6: 0 | L6: 0 | M6: 1 | N6: 0 | O6: 0 | P6: 0 | Q6: 0 | R6: 0 | S6: 0 | T6: 0 | U6: 1 | V6: 0 | W6: 0 | X6: 0 | Y6: 0 | Z6: 0 | AA6: 1
A7: 40359 | B7: 1 | C7: 1 | D7: 0 | E7: 0 | F7: 0 | G7: 0 | H7: 0 | I7: 0 | J7: 0 | K7: 0 | L7: 0 | M7: 1 | N7: 0 | O7: 0 | P7: 0 | Q7: 0 | R7: 0 | S7: 0 | T7: 0 | U7: 1 | V7: 0 | W7: 0 | X7: 1 | Y7: 0 | Z7: 0 | AA7: 1
A8: 40389 | B8: 0 | C8: 1 | D8: 0 | E8: 0 | F8: 0 | G8: 0 | H8: 0 | I8: 0 | J8: 0 | K8: 0 | L8: 0 | M8: 1 | N8: 0 | O8: 0 | P8: 0 | Q8: 0 | R8: 1 | S8: 0 | T8: 1 | U8: 0 | V8: 0 | W8: 1 | X8: 0 | Y8: 0 | Z8: 0 | AA8: 0
A9: 40421 | B9: 1 | C9: 1 | D9: 1 | E9: 0 | F9: 0 | G9: 0 | H9: 0 | I9: 0 | J9: 0 | K9: 0 | L9: 0 | M9: 0 | N9: 0 | O9: 0 | P9: 0 | Q9: 0 | R9: 1 | S9: 0 | T9: 0 | U9: 0 | V9: 0 | W9: 1 | X9: 1 | Y9: 0 | Z9: 0 | AA9: 0
A10: 40451 | B10: 0 | C10: 1 | D10: 1 | E10: 0 | F10: 1 | G10: 0 | H10: 0 | I10: 0 | J10: 0 | K10: 0 | L10: 0 | M10: 0 | N10: 0 | O10: 0 | P10: 0 | Q10: 0 | R10: 0 | S10: 0 | T10: 0 | U10: 1 | V10: 1 | W10: 1 | X10: 0 | Y10: 0 | Z10: 0 | AA10: 0
A11: 40480 | B11: 1 | C11: 1 | D11: 0 | E11: 0 | F11: 0 | G11: 0 | H11: 0 | I11: 0 | J11: 0 | K11: 0 | L11: 0 | M11: 0 | N11: 0 | O11: 0 | P11: 0 | Q11: 0 | R11: 0 | S11: 0 | T11: 0 | U11: 1 | V11: 0 | W11: 1 | X11: 1 | Y11: 0 | Z11: 0 | AA11: 0
A12: 40512 | B12: 0 | C12: 1 | D12: 0 | E12: 0 | F12: 0 | G12: 0 | H12: 0 | I12: 0 | J12: 0 | K12: 0 | L12: 0 | M12: 1 | N12: 1 | O12: 0 | P12: 0 | Q12: 0 | R12: 1 | S12: 0 | T12: 0 | U12: 1 | V12: 0 | W12: 1 | X12: 0 | Y12: 0 | Z12: 0 | AA12: 0
A13: 40543 | B13: 0 | C13: 1 | D13: 0 | E13: 0 | F13: 0 | G13: 0 | H13: 0 | I13: 0 | J13: 0 | K13: 0 | L13: 0 | M13: 0 | N13: 1 | O13: 0 | P13: 0 | Q13: 0 | R13: 0 | S13: 0 | T13: 0 | U13: 1 | V13: 1 | W13: 0 | X13: 1 | Y13: 0 | Z13: 0 | AA13: 0
A14: 40574 | B14: 0 | C14: 1 | D14: 1 | E14: 0 | F14: 0 | G14: 0 | H14: 0 | I14: 0 | J14: 0 | K14: 0 | L14: 0 | M14: 0 | N14: 1 | O14: 0 | P14: 0 | Q14: 0 | R14: 1 | S14: 0 | T14: 0 | U14: 1 | V14: 0 | W14: 1 | X14: 0 | Y14: 0 | Z14: 0 | AA14: 0
... A202: 46295 | B202: 0 | C202: 0 | D202: 0 | E202: 1 | F202: 1 | G202: 0 | H202: 0 | I202: 1 | J202: 0 | K202: 0 | L202: 0 | M202: 0 | N202: 0 | O202: 0 | P202: 1 | Q202: 0 | R202: 0 | S202: 0 | T202: 0 | U202: 1 | V202: 0 | W202: 0 | X202: 0 | Y202: 0 | Z202: 0 | AA202: 1

Sheet Config
B4: FACTSET Ids | C4: INDEX NAME | D4: Named Range | E4: Secto Name
B7: 181085 | C7: {=_xll.FDS(B7,"FG_COMPANY_NAME")} -> FTSE World Europe | D7: IND_Bench | F7: Nb of Const
B8: I00037 | C8: {=_xll.FDS(B8,"FG_COMPANY_NAME")} -> FTSE World Europe / Basic Materials - IND | D8: IND_Mat | E8: Materials | F8: {=_xll.FDS(B8,"FTAW_NUMBER_IDX(0,0,D,""CLOSE"")")} -> 49
B9: I00109 | C9: {=_xll.FDS(B9,"FG_COMPANY_NAME")} -> FTSE World Europe / Consumer Staples - IND | D9: IND_ConsGd | E9: ConsStaples | F9: {=_xll.FDS(B9,"FTAW_NUMBER_IDX(0,0,D,""CLOSE"")")} -> 47
B10: I20438 | C10: {=_xll.FDS(B10,"FG_COMPANY_NAME")} -> FTSE World Europe / Personal Goods - SEC | D10: IND_PersGoods | E10: Pers. Goods | F10: {=_xll.FDS(B10,"FTAW_NUMBER_IDX(0,0,D,""CLOSE"")")} -> 14
B11: I00253 | C11: {=_xll.FDS(B11,"FG_COMPANY_NAME")} -> FTSE World Europe / Financials - IND | D11: IND_Fin | E11: Fin | F11: {=_xll.FDS(B11,"FTAW_NUMBER_IDX(0,0,D,""CLOSE"")")} -> 128
B12: I20436 | C12: {=_xll.FDS(B12,"FG_COMPANY_NAME")} -> FTSE World Europe / Health Care - IND | D12: IND_Health | E12: HealthCare | F12: {=_xll.FDS(B12,"FTAW_NUMBER_IDX(0,0,D,""CLOSE"")")} -> 49
B13: I00073 | C13: {=_xll.FDS(B13,"FG_COMPANY_NAME")} -> FTSE World Europe / Industrials - IND | D13: IND_Indus | E13: Indus | F13: {=_xll.FDS(B13,"FTAW_NUMBER_IDX(0,0,D,""CLOSE"")")} -> 132
B14: I20433 | C14: {=_xll.FDS(B14,"FG_COMPANY_NAME")} -> FTSE World Europe / Energy - IND | D14: IND_Oil | E14: Oil | F14: {=_xll.FDS(B14,"FTAW_NUMBER_IDX(0,0,D,""CLOSE"")")} -> 23
B15: I20448 | C15: {=_xll.FDS(B15,"FG_COMPANY_NAME")} -> FTSE World Europe / Technology - IND | D15: IND_Tech | E15: Tech | F15: {=_xll.FDS(B15,"FTAW_NUMBER_IDX(0,0,D,""CLOSE"")")} -> 24
B16: I20443 | C16: {=_xll.FDS(B16,"FG_COMPANY_NAME")} -> FTSE World Europe / Telecommunications - IND | D16: IND_Telco | E16: Telco | F16: {=_xll.FDS(B16,"FTAW_NUMBER_IDX(0,0,D,""CLOSE"")")} -> 23
B17: I00577 | C17: {=_xll.FDS(B17,"FG_COMPANY_NAME")} -> FTSE World Europe / Utilities - IND | D17: IND_Utili | E17: Utili | F17: {=_xll.FDS(B17,"FTAW_NUMBER_IDX(0,0,D,""CLOSE"")")} -> 39
B18: I00901 | C18: {=_xll.FDS(B18,"FG_COMPANY_NAME")} -> FTSE World Europe / Travel and Leisure - SEC | D18: IND_Travel | E18: Travel & leisure | F18: {=_xll.FDS(B18,"FTAW_NUMBER_IDX(0,0,D,""CLOSE"")")} -> 14
B19: I00937 | C19: {=_xll.FDS(B19,"FG_COMPANY_NAME")} -> FTSE World Europe / Media - SEC | D19: IND_Media | E19: Media | F19: {=_xll.FDS(B19,"FTAW_NUMBER_IDX(0,0,D,""CLOSE"")")} -> 7
B20: I00649 | C20: {=_xll.FDS(B20,"FG_COMPANY_NAME")} -> FTSE World Europe / Automobiles and Parts - SEC | D20: IND_Auto | E20: Auto | F20: {=_xll.FDS(B20,"FTAW_NUMBER_IDX(0,0,D,""CLOSE"")")} -> 17

Sheet Returns_EQ
A1: StartDate: | B1: 36494 | D1: CUMRET TIME SERIES
A2: EndDate: | B2: =TODAY() -> 46321 | D2: EQUITY
B4: =IND_Bench -> 181085 | C4: =IND_Mat -> I00037 | D4: =IND_ConsGd -> I00109 | E4: =IND_PersGoods -> I20438 | F4: =IND_Fin -> I00253 | G4: =IND_Health -> I20436 | H4: =IND_Indus -> I00073 | I4: =IND_Oil -> I20433 | J4: =IND_Tech -> I20448 | K4: =IND_Telco -> I20443 | L4: =IND_Utili -> I00577 | M4: =Ind_Travel -> I00901 | N4: =Ind_Media -> I00937 | O4: {=IND_Auto} -> I00649
B5: {=_xll.FDS(B4,"FG_COMPANY_NAME")} -> FTSE World Europe | C5: {=_xll.FDS(C4,"FG_COMPANY_NAME")} -> FTSE World Europe / Basic Materials - IND | D5: {=_xll.FDS(D4,"FG_COMPANY_NAME")} -> FTSE World Europe / Consumer Staples - IND | E5: {=_xll.FDS(E4,"FG_COMPANY_NAME")} -> FTSE World Europe / Personal Goods - SEC | F5: {=_xll.FDS(F4,"FG_COMPANY_NAME")} -> FTSE World Europe / Financials - IND | G5: {=_xll.FDS(G4,"FG_COMPANY_NAME")} -> FTSE World Europe / Health Care - IND | H5: {=_xll.FDS(H4,"FG_COMPANY_NAME")} -> FTSE World Europe / Industrials - IND | I5: {=_xll.FDS(I4,"FG_COMPANY_NAME")} -> FTSE World Europe / Energy - IND | ... O5: {=_xll.FDS(O4,"FG_COMPANY_NAME")} -> FTSE World Europe / Automobiles and Parts - SEC
B6: PX_LAST
A7: {=_xll.FDS(B4,"JULIAN(FG_TOTAL_RET_IDX(0,-20AY,M,EUR).dates)")} -> 46295 | B7: {=_xll.FDS(B4,"FG_TOTAL_RET_IDX(0,-20AY,M,EUR)")} -> 2754.36 | C7: {=_xll.FDS(C4,"FG_TOTAL_RET_IDX(0,-20AY,M,EUR)")} -> 2997.4655 | D7: {=_xll.FDS(D4,"FG_TOTAL_RET_IDX(0,-20AY,M,EUR)")} -> 3696.854 | E7: {=_xll.FDS(E4,"FG_TOTAL_RET_IDX(0,-20AY,M,EUR)")} -> 12469.292 | F7: {=_xll.FDS(F4,"FG_TOTAL_RET_IDX(0,-20AY,M,EUR)")} -> 2026.0789 | G7: {=_xll.FDS(G4,"FG_TOTAL_RET_IDX(0,-20AY,M,EUR)")} -> 3580.0213 | H7: {=_xll.FDS(H4,"FG_TOTAL_RET_IDX(0,-20AY,M,EUR)")} -> 3693.7532 | I7: {=_xll.FDS(I4,"FG_TOTAL_RET_IDX(0,-20AY,M,EUR)")} -> 5489.6236 | ... O7: {=_xll.FDS(O4,"FG_TOTAL_RET_IDX(0,-20AY,M,EUR)")} -> 820.67868
A8: 46265 | B8: 2825.5075 | C8: 3134.7921 | D8: 3819.6449 | E8: 13549.596 | F8: 2087.6489 | G8: 3690.9727 | H8: 3838.6633 | I8: 5312.3883 | J8: 749.10393 | K8: 1136.2984 | L8: 6704.2006 | M8: 1665.4474 | N8: 1668.2993 | O8: 901.76276
A9: 46234 | B9: 2811.2472 | C9: 2938.2818 | D9: 3966.6345 | E9: 13796.799 | F9: 2064.8267 | G9: 3723.0895 | H9: 3825.5512 | I9: 5312.5759 | J9: 722.41908 | K9: 1108.5592 | L9: 6825.4911 | M9: 1659.1791 | N9: 1611.4803 | O9: 878.49601
A10: 46203 | B10: 2777.6709 | C10: 2874.5906 | D10: 3886.05 | E10: 13845.621 | F10: 1954.8118 | G10: 3776.0111 | H10: 3801.0465 | I10: 4819.2266 | J10: 800.47175 | K10: 1133.2348 | L10: 6905.7988 | M10: 1743.6938 | N10: 1636.0631 | O10: 842.86453
A11: 46171 | B11: 2699.1581 | C11: 3007.2845 | D11: 3716.9173 | E11: 13509.827 | F11: 1848.4868 | G11: 3611.9132 | H11: 3753.9118 | I11: 5076.3325 | J11: 732.13979 | K11: 1250.494 | L11: 6589.8374 | M11: 1605.9745 | N11: 1610.5157 | O11: 927.44539
A12: 46142 | B12: 2616.4729 | C12: 2857.9808 | D12: 3695.0246 | E12: 12566.467 | F12: 1782.6055 | G12: 3538.4825 | H12: 3627.4718 | I12: 5421.3365 | J12: 653.00474 | K12: 1196.7438 | L12: 6889.2027 | M12: 1473.7685 | N12: 1515.3035 | O12: 883.28693
