Workbook
Name Annee_Bench: Output!$N$416:INDEX(Output!$N:$N,415+COUNT(Output!$M$416:$M$10000))
Name Annee_Bottom: Output!$Q$416:INDEX(Output!$Q:$Q,415+COUNT(Output!$M$416:$M$10000))
Name Annee_Date: Output!$M$416:INDEX(Output!$M:$M,415+COUNT(Output!$M$416:$M$10000))
Name Annee_Ptf: Output!$O$416:INDEX(Output!$O:$O,415+COUNT(Output!$M$416:$M$10000))
Name Annee_Top: Output!$P$416:INDEX(Output!$P:$P,415+COUNT(Output!$M$416:$M$10000))
Name Courbe_Bench: Output!$E$416:INDEX(Output!$E:$E,415+COUNT(Output!$D$416:$D$10000))
Name Courbe_Bottom: Output!$H$416:INDEX(Output!$H:$H,415+COUNT(Output!$D$416:$D$10000))
Name Courbe_Date: Output!$D$416:INDEX(Output!$D:$D,415+COUNT(Output!$D$416:$D$10000))
Name Courbe_LS: Output!$I$416:INDEX(Output!$I:$I,415+COUNT(Output!$D$416:$D$10000))
Name Courbe_Ptf: Output!$F$416:INDEX(Output!$F:$F,415+COUNT(Output!$D$416:$D$10000))
Name Courbe_Top: Output!$G$416:INDEX(Output!$G:$G,415+COUNT(Output!$D$416:$D$10000))
Name DateExport: Config!$C$34
Name delta_Wi: Config!$C$30
Name ExportFile: Config!$C$36
Name ImportFile: Config!$C$35
Name IND_Bench: Config!$B$7
Name IND_ConsGd: Config!$B$9
Name IND_Fin: Config!$B$11
Name IND_Health: Config!$B$12
Name IND_Indus: Config!$B$13
Name IND_Mat: Config!$B$8
Name Ind_Media: Config!$B$19
Name IND_Oil: Config!$B$14
Name Ind_Retail: Config!$B$10
Name IND_Tech: Config!$B$15
Name IND_Telco: Config!$B$16
Name Ind_Travel: Config!$B$18
Name IND_Utili: Config!$B$17
Name nb_Bottom: Config!$C$25
Name nb_Long: Config!$C$27
Name nb_Short: Config!$C$28
Name nb_Top: Config!$C$24
Name RFolder: Config!$C$37
Name RFunction: Config!$C$38

Sheet Dashboard
I4: SCORECARD | BN4: Date: | BO4: =Output!B2 -> 46295 | BP4: =Output!B9 -> Oct-2026 | BQ4: =Output!B10 -> Sept-2026
I5: US SECTORS
R6: S | BP6: =Output!B11 -> Sectors Ranking Oct-2026 | BV6: =Output!B12 -> Sectors Ranking Sept-2026
CC7: Last Month Allocation Performance
I8: Low leverage rank | J8: Net debt to EBITDA | M8: FCF to Total Debt | P8: Margin rank | Q8: Operating margin | T8: Net margin | W8: EBITDA margin | Z8: Valuation rank | AA8: PFCF | AD8: EV / EBITDA | AG8: Price to sales | AJ8: Momentum rank | AK8: Perf 6M-1M | AM8: Perf 12M-1M | AO8: Earnings revision ratio | AR8: Growth rank | AS8: EPS 12M growth forecast | AV8: Sales 12M growth forecast | AY8: EBITDA 12M growth forecast | BB8: Cash Flow 12M growth forecast | BE8: Low volatility rank | BF8: Vol 6M | BH8: Vol downside 18M | BJ8: =Output!B13 -> Macro rank - Currently in Expansion | BK8: Rate signal - Bonus Leverage & Value
J9: vs. moy secteurs perc. 5y | K9: vs. moy secteurs histo 5y | L9: metric | M9: vs. moy secteurs perc. 5y | N9: vs. moy secteurs histo 5y | O9: metric | Q9: vs. moy secteurs perc. 5y | R9: vs. moy secteurs histo 5y | S9: metric | T9: vs. moy secteurs perc. 5y | U9: vs. moy secteurs histo 5y | V9: metric | W9: vs. moy secteurs perc. 5y | X9: vs. moy secteurs histo 5y | Y9: metric | AA9: vs. moy secteurs perc. 5y | AB9: vs. moy secteurs histo 5y | AC9: metric | AD9: vs. moy secteurs perc. 5y | AE9: vs. moy secteurs histo 5y | AF9: metric | AG9: vs. moy secteurs perc. 5y | AH9: vs. moy secteurs histo 5y | AI9: metric | AK9: rank (rank) | AL9: Perf | AM9: rank (rank) | AN9: Perf | AO9: rank (rank) | AP9: Ratio histo 5y | AQ9: Ratio | AS9: vs. moy secteurs perc. 5y | AT9: vs. moy secteurs histo 5y | AU9: metric | AV9: vs. moy secteurs perc. 5y | AW9: vs. moy secteurs histo 5y | AX9: metric | AY9: vs. moy secteurs perc. 5y | AZ9: vs. moy secteurs histo 5y | BA9: metric | BB9: vs. moy secteurs perc. 5y | BC9: vs. moy secteurs histo 5y | BD9: metric | BF9: rank (rank) | BG9: Vol | BH9: rank (rank) | BI9: Vol | BN9: Nb Top 3 pillars | BO9: Nb Worst 3 pillars | BP9: Global - Weighted Score | BQ9: Reco | BR9: Δ Reco | BU9: Previous nb piliers Top 3 | BV9: Previous nb piliers Worst 3 | BW9: Previous global - Weighted Score | BX9: Previous Reco | BY9: =Output!BU1 -> Sept-2026 EQ Performance | BZ9: =Output!BV1 -> Sept-2026 XSRet vs WIUSAU Index | CD9: Last Month EQ Performance
H10: Materials | I10: =Output!E2 -> 7 | J10: =Output!F2 -> 4.8019126 | L10: =Output!H2 -> 1.22262 | M10: =Output!I2 -> 4.2076503 | O10: =Output!K2 -> 22.028238 | P10: =Output!L2 -> 5 | Q10: =Output!M2 -> 6.4480874 | S10: =Output!O2 -> 19.657374 | T10: =Output!P2 -> 4.4672131 | V10: =Output!R2 -> 12.336806 | W10: =Output!S2 -> 5.5327869 | Y10: =Output!U2 -> 27.295065 | Z10: =Output!V2 -> 11 | AA10: =Output!W2 -> 0.6557377 | AC10: =Output!Y2 -> 12.53727 | AD10: =Output!Z2 -> 0.32786885 | AF10: =Output!AB2 -> 10.69341 | AG10: =Output!AC2 -> 0.49180328 | AI10: =Output!AE2 -> 3.0101644 | AJ10: =Output!AF2 -> 3 | AK10: =Output!AG2 -> 8 | AL10: =Output!AH2 -> 0.099930284 | AM10: =Output!AI2 -> 10 | AN10: =Output!AJ2 -> 0.27859081 | AO10: =Output!AK2 -> 9 | AQ10: =Output!AM2 -> 0.30769231 | AR10: =Output!AN2 -> 2 | AS10: =Output!AO2 -> 8.1967213 | AU10: =Output!AQ2 -> 19.596372 | AV10: =Output!AR2 -> 8.6885246 | AX10: =Output!AT2 -> 6.8923117 | AY10: =Output!AU2 -> 8.0327869 | BA10: =Output!AW2 -> 14.662707 | BB10: =Output!AX2 -> 9.0163934 | BD10: =Output!AZ2 -> 22.047794 | BE10: =Output!BA2 -> 1 | BF10: =Output!BB2 -> 9.3442623 | BG10: =Output!BC2 -> 0.17282112 | BH10: =Output!BD2 -> 9.1803279 | BI10: =Output!BE2 -> 0.086038617 | BJ10: =Output!BF2 -> 3 | BK10: =Output!B6 -> On | BM10: Materials | BN10: =Output!BJ2 -> 4 | BO10: =Output!BK2 -> 2 | BP10: =Output!BL2 -> 8.5 | BQ10: =Output!BM2 -> Positive | BR10: =Output!BN2 -> 1 | BU10: =Output!BQ2 -> 2 | BV10: =Output!BR2 -> 1 | BW10: =Output!BS2 -> 6.5 | BX10: =Output!BT2 -> Neutral | BY10: =Output!BU2 -> -0.054387894 | BZ10: =Output!BV2 -> -0.049961435 | CC10: Long Portfolio | CD10: =Output!B15 -> -0.021838073
H11: Consumer Staples | I11: =Output!E3 -> 8 | J11: =Output!F3 -> 2.4795082 | L11: =Output!H3 -> 1.9202542 | M11: =Output!I3 -> 6.4412568 | O11: =Output!K3 -> 25.178694 | P11: =Output!L3 -> 12 | Q11: =Output!M3 -> 0.49863388 | S11: =Output!O3 -> 6.9512161 | T11: =Output!P3 -> 0.49863388 | V11: =Output!R3 -> 4.979818 | W11: =Output!S3 -> 0.49863388 | Y11: =Output!U3 -> 8.4210974 | Z11: =Output!V3 -> 6 | AA11: =Output!W3 -> 3.7704918 | AC11: =Output!Y3 -> 14.235069 | AD11: =Output!Z3 -> 3.2786885 | AF11: =Output!AB3 -> 12.611009 | AG11: =Output!AC3 -> 7.8688525 | AI11: =Output!AE3 -> 0.91152254 | AJ11: =Output!AF3 -> 10 | AK11: =Output!AG3 -> 5 | AL11: =Output!AH3 -> 0.057409307 | AM11: =Output!AI3 -> 6 | AN11: =Output!AJ3 -> 0.10520092 | AO11: =Output!AK3 -> 2 | AQ11: =Output!AM3 -> -0.038461538 | AR11: =Output!AN3 -> 8 | AS11: =Output!AO3 -> 7.8688525 | AU11: =Output!AQ3 -> 6.9321977 | AV11: =Output!AR3 -> 2.1311475 | AX11: =Output!AT3 -> 4.4229456 | AY11: =Output!AU3 -> 1.9672131 | BA11: =Output!AW3 -> 5.7536922 | BB11: =Output!AX3 -> 3.442623 | BD11: =Output!AZ3 -> 9.7312479 | BE11: =Output!BA3 -> 12 | BF11: =Output!BB3 -> 4.5901639 | BG11: =Output!BC3 -> 0.15794132 | BH11: =Output!BD3 -> 0.98360656 | BI11: =Output!BE3 -> 0.094598589 | BJ11: =Output!BF3 -> 12 | BK11: A sector that is at least 3 times in worst 3 sectors (resp. top 3) of different pillars can not have a positive recommendation (resp. negative). If two sectors are as many times in the top or worst 3, we differentiate them by their mean score. If rate signal is on, value and leverage pillars count twice. Negative recommendation doesn't include margin pillar. | BM11: Consumer Staples | BN11: =Output!BJ3 -> 0 | BO11: =Output!BK3 -> 3 | BP11: =Output!BL3 -> 3.6666667 | BQ11: =Output!BM3 -> Negative | BR11: =Output!BN3 -> 0 | BU11: =Output!BQ3 -> 0 | BV11: =Output!BR3 -> 2 | BW11: =Output!BS3 -> 4.1666667 | BX11: =Output!BT3 -> Negative | BY11: =Output!BU3 -> -0.036884392 | BZ11: =Output!BV3 -> -0.032457934 | CC11: Short Portfolio | CD11: =Output!B16 -> 0.046805463
H12: Retail | I12: =Output!E4 -> 10 | J12: =Output!F4 -> 4.3306011 | L12: =Output!H4 -> 0.49591342 | M12: =Output!I4 -> 2.397541 | O12: =Output!K4 -> 17.857379 | P12: =Output!L4 -> 11 | Q12: =Output!M4 -> 1.8989071 | S12: =Output!O4 -> 8.9815098 | T12: =Output!P4 -> 3.1284153 | V12: =Output!R4 -> 7.0708821 | W12: =Output!S4 -> 2.1448087 | Y12: =Output!U4 -> 13.587507 | Z12: =Output!V4 -> 2 | AA12: =Output!W4 -> 10 | AC12: =Output!Y4 -> 13.787961 | AD12: =Output!Z4 -> 10 | AF12: =Output!AB4 -> 11.773436 | AG12: =Output!AC4 -> 9.1803279 | AI12: =Output!AE4 -> 1.8559352 | AJ12: =Output!AF4 -> 8 | AK12: =Output!AG4 -> 6 | AL12: =Output!AH4 -> 0.079188564 | AM12: =Output!AI4 -> 4 | AN12: =Output!AJ4 -> 0.081707795 | AO12: =Output!AK4 -> 8 | AQ12: =Output!AM4 -> 0.2 | AR12: =Output!AN4 -> 3 | AS12: =Output!AO4 -> 2.4590164 | AU12: =Output!AQ4 -> 5.5615651 | AV12: =Output!AR4 -> 5.4098361 | AX12: =Output!AT4 -> 8.8864034 | AY12: =Output!AU4 -> 10 | BA12: =Output!AW4 -> 21.205741 | BB12: =Output!AX4 -> 3.6065574 | BD12: =Output!AZ4 -> 19.614034 | BE12: =Output!BA4 -> 8 | BF12: =Output!BB4 -> 0.6557377 | BG12: =Output!BC4 -> 0.26849553 | BH12: =Output!BD4 -> 7.3770492 | BI12: =Output!BE4 -> 0.084264252 | BJ12: =Output!BF4 -> 5 | BM12: Retail | BN12: =Output!BJ4 -> 3 | BO12: =Output!BK4 -> 2 | BP12: =Output!BL4 -> 7 | BQ12: =Output!BM4 -> Neutral | BR12: =Output!BN4 -> -1 | BU12: =Output!BQ4 -> 3 | BV12: =Output!BR4 -> 2 | BW12: =Output!BS4 -> 7.8333333 | BX12: =Output!BT4 -> Positive | BY12: =Output!BU4 -> -0.043559021 | BZ12: =Output!BV4 -> -0.039132563 | CC12: L/S Portfolio | CD12: =Output!B17 -> 0.02496739
H13: Financials | I13: =Output!E5 -> 1 | J13: =Output!F5 -> 9.0163934 | L13: =Output!H5 -> -2.0866902 | M13: =Output!I5 -> 6.6734973 | O13: =Output!K5 -> 22.209445 | P13: =Output!L5 -> 2 | Q13: =Output!M5 -> 7.9439891 | S13: =Output!O5 -> 21.658118 | T13: =Output!P5 -> 7.9439891 | V13: =Output!R5 -> 16.054846 | W13: =Output!S5 -> 5.1297814 | Y13: =Output!U5 -> 28.346714 | Z13: =Output!V5 -> 8 | AA13: =Output!W5 -> n.a. | AC13: =Output!Y5 -> n.a. | AD13: =Output!Z5 -> n.a. | AF13: =Output!AB5 -> n.a. | AG13: =Output!AC5 -> 5.7377049 | AI13: =Output!AE5 -> 2.8520047 | AJ13: =Output!AF5 -> 6 | AK13: =Output!AG5 -> 11 | AL13: =Output!AH5 -> 0.14490912 | AM13: =Output!AI5 -> 5 | AN13: =Output!AJ5 -> 0.089314593 | AO13: =Output!AK5 -> 5 | AQ13: =Output!AM5 -> 0.014925373 | AR13: =Output!AN5 -> 6 | AS13: =Output!AO5 -> 5.9016393 | AU13: =Output!AQ5 -> 9.7731301 | AV13: =Output!AR5 -> 2.4590164 | AX13: =Output!AT5 -> 6.0163324 | AY13: =Output!AU5 -> n.a. | BA13: =Output!AW5 -> n.a. | BB13: =Output!AX5 -> n.a. | BD13: =Output!AZ5 -> n.a. | BE13: =Output!BA5 -> 3 | BF13: =Output!BB5 -> 7.0491803 | BG13: =Output!BC5 -> 0.17070161 | BH13: =Output!BD5 -> 7.3770492 | BI13: =Output!BE5 -> 0.071893946 | BJ13: =Output!BF5 -> 3 | BM13: Financials | BN13: =Output!BJ5 -> 5 | BO13: =Output!BK5 -> 0 | BP13: =Output!BL5 -> 8.5 | BQ13: =Output!BM5 -> Positive | BR13: =Output!BN5 -> 0 | BU13: =Output!BQ5 -> 4 | BV13: =Output!BR5 -> 1 | BW13: =Output!BS5 -> 8.1666667 | BX13: =Output!BT5 -> Positive | BY13: =Output!BU5 -> -0.074213842 | BZ13: =Output!BV5 -> -0.069787384 | CC13: Ptf dev secto | CD13: =Output!B18 -> 0.00036872701
H14: HealthCare | I14: =Output!E6 -> 9 | J14: =Output!F6 -> 2.1653005 | L14: =Output!H6 -> 1.7058441 | M14: =Output!I6 -> 6.0519126 | O14: =Output!K6 -> 27.543317 | P14: =Output!L6 -> 8 | Q14: =Output!M6 -> 1.9057377 | S14: =Output!O6 -> 12.913112 | T14: =Output!P6 -> 1.7418033 | V14: =Output!R6 -> 9.2893927 | W14: =Output!S6 -> 8.5040984 | Y14: =Output!U6 -> 32.941353 | Z14: =Output!V6 -> 10 | AA14: =Output!W6 -> 0.16393443 | AC14: =Output!Y6 -> 16.987361 | AD14: =Output!Z6 -> 0.16393443 | AF14: =Output!AB6 -> 15.705992 | AG14: =Output!AC6 -> 6.0655738 | AI14: =Output!AE6 -> 2.4448214 | AJ14: =Output!AF6 -> 4 | AK14: =Output!AG6 -> 10 | AL14: =Output!AH6 -> 0.14390425 | AM14: =Output!AI6 -> 9 | AN14: =Output!AJ6 -> 0.22268254 | AO14: =Output!AK6 -> 3 | AQ14: =Output!AM6 -> 0 | AR14: =Output!AN6 -> 4 | AS14: =Output!AO6 -> 9.1803279 | AU14: =Output!AQ6 -> 17.856892 | AV14: =Output!AR6 -> 0.98360656 | AX14: =Output!AT6 -> 4.5266928 | AY14: =Output!AU6 -> 6.557377 | BA14: =Output!AW6 -> 14.497431 | BB14: =Output!AX6 -> 6.8852459 | BD14: =Output!AZ6 -> 15.896039 | BE14: =Output!BA6 -> 11 | BF14: =Output!BB6 -> 5.2459016 | BG14: =Output!BC6 -> 0.16169832 | BH14: =Output!BD6 -> 1.147541 | BI14: =Output!BE6 -> 0.086891746 | BJ14: =Output!BF6 -> 9 | BM14: HealthCare | BN14: =Output!BJ6 -> 0 | BO14: =Output!BK6 -> 3 | BP14: =Output!BL6 -> 5.1666667 | BQ14: =Output!BM6 -> Neutral | BR14: =Output!BN6 -> 0 | BU14: =Output!BQ6 -> 0 | BV14: =Output!BR6 -> 1 | BW14: =Output!BS6 -> 5 | BX14: =Output!BT6 -> Neutral | BY14: =Output!BU6 -> -0.0067022413 | BZ14: =Output!BV6 -> -0.0022757826 | CC14: S&P 500 | CD14: =Output!B19 -> -0.0044264587
H15: Industrials | I15: =Output!E7 -> 6 | J15: =Output!F7 -> 2.6502732 | L15: =Output!H7 -> 1.7344032 | M15: =Output!I7 -> 8.6680328 | O15: =Output!K7 -> 26.948095 | P15: =Output!L7 -> 10 | Q15: =Output!M7 -> 2.1653005 | S15: =Output!O7 -> 16.237674 | T15: =Output!P7 -> 4.3101093 | V15: =Output!R7 -> 12.887893 | W15: =Output!S7 -> 1.3319672 | Y15: =Output!U7 -> 21.062697 | Z15: =Output!V7 -> 7 | AA15: =Output!W7 -> 1.6393443 | AC15: =Output!Y7 -> 17.405303 | AD15: =Output!Z7 -> 1.3114754 | AF15: =Output!AB7 -> 15.327033 | AG15: =Output!AC7 -> 7.5409836 | AI15: =Output!AE7 -> 2.9930543 | AJ15: =Output!AF7 -> 6 | AK15: =Output!AG7 -> 7 | AL15: =Output!AH7 -> 0.093829499 | AM15: =Output!AI7 -> 7 | AN15: =Output!AJ7 -> 0.11693454 | AO15: =Output!AK7 -> 7 | AQ15: =Output!AM7 -> 0.096774194 | AR15: =Output!AN7 -> 9 | AS15: =Output!AO7 -> 8.1967213 | AU15: =Output!AQ7 -> 13.931877 | AV15: =Output!AR7 -> 5.4098361 | AX15: =Output!AT7 -> 7.9835015 | AY15: =Output!AU7 -> 2.4590164 | BA15: =Output!AW7 -> 11.738682 | BB15: =Output!AX7 -> 2.1311475 | BD15: =Output!AZ7 -> 14.563399 | BE15: =Output!BA7 -> 9 | BF15: =Output!BB7 -> 5.7377049 | BG15: =Output!BC7 -> 0.18457319 | BH15: =Output!BD7 -> 1.4754098 | BI15: =Output!BE7 -> 0.099040037 | BJ15: =Output!BF7 -> 8 | BM15: Industrials | BN15: =Output!BJ7 -> 0 | BO15: =Output!BK7 -> 0 | BP15: =Output!BL7 -> 5.5 | BQ15: =Output!BM7 -> Neutral | BR15: =Output!BN7 -> 0 | BU15: =Output!BQ7 -> 0 | BV15: =Output!BR7 -> 0 | BW15: =Output!BS7 -> 6 | BX15: =Output!BT7 -> Neutral | BY15: =Output!BU7 -> -0.048431204 | BZ15: =Output!BV7 -> -0.044004745
H16: Energy | I16: =Output!E8 -> 5 | J16: =Output!F8 -> 5.6352459 | L16: =Output!H8 -> 1.0167123 | M16: =Output!I8 -> 6.7964481 | O16: =Output!K8 -> 36.24289 | P16: =Output!L8 -> 9 | Q16: =Output!M8 -> 3.7978142 | S16: =Output!O8 -> 13.425094 | T16: =Output!P8 -> 3.6338798 | V16: =Output!R8 -> 9.7795478 | W16: =Output!S8 -> 3.6338798 | Y16: =Output!U8 -> 21.631408 | Z16: =Output!V8 -> 9 | AA16: =Output!W8 -> 1.4754098 | AC16: =Output!Y8 -> 7.3348122 | AD16: =Output!Z8 -> 0.98360656 | AF16: =Output!AB8 -> 6.8885213 | AG16: =Output!AC8 -> 4.4262295 | AI16: =Output!AE8 -> 1.5599016 | AJ16: =Output!AF8 -> 3 | AK16: =Output!AG8 -> 3 | AL16: =Output!AH8 -> 0.021864807 | AM16: =Output!AI8 -> 12 | AN16: =Output!AJ8 -> 0.42613895 | AO16: =Output!AK8 -> 12 | AQ16: =Output!AM8 -> 0.5 | AR16: =Output!AN8 -> 7 | AS16: =Output!AO8 -> 9.0163934 | AU16: =Output!AQ8 -> 14.60133 | AV16: =Output!AR8 -> 2.7868852 | AX16: =Output!AT8 -> 1.1215868 | AY16: =Output!AU8 -> 3.442623 | BA16: =Output!AW8 -> 8.1029064 | BB16: =Output!AX8 -> 4.9180328 | BD16: =Output!AZ8 -> 9.8949627 | BE16: =Output!BA8 -> 6 | BF16: =Output!BB8 -> 3.9344262 | BG16: =Output!BC8 -> 0.26727375 | BH16: =Output!BD8 -> 5.4098361 | BI16: =Output!BE8 -> 0.14596108 | BJ16: =Output!BF8 -> 4 | BM16: Energy | BN16: =Output!BJ8 -> 1 | BO16: =Output!BK8 -> 0 | BP16: =Output!BL8 -> 7.3333333 | BQ16: =Output!BM8 -> Neutral | BR16: =Output!BN8 -> 0 | BU16: =Output!BQ8 -> 2 | BV16: =Output!BR8 -> 0 | BW16: =Output!BS8 -> 8.5 | BX16: =Output!BT8 -> Neutral | BY16: =Output!BU8 -> -0.029401703 | BZ16: =Output!BV8 -> -0.024975244
H17: Tech | I17: =Output!E9 -> 4 | J17: =Output!F9 -> 5.6489071 | L17: =Output!H9 -> 0.10783016 | M17: =Output!I9 -> 6.8852459 | O17: =Output!K9 -> 64.397494 | P17: =Output!L9 -> 1 | Q17: =Output!M9 -> 10 | S17: =Output!O9 -> 34.782338 | T17: =Output!P9 -> 10 | V17: =Output!R9 -> 30.22492 | W17: =Output!S9 -> 10 | Y17: =Output!U9 -> 41.002375 | Z17: =Output!V9 -> 3 | AA17: =Output!W9 -> 8.3783784 | AC17: =Output!Y9 -> 18.31349 | AD17: =Output!Z9 -> 8.3783784 | AF17: =Output!AB9 -> 15.584779 | AG17: =Output!AC9 -> 3.6065574 | AI17: =Output!AE9 -> 7.5240099 | AJ17: =Output!AF9 -> 1 | AK17: =Output!AG9 -> 12 | AL17: =Output!AH9 -> 0.40754468 | AM17: =Output!AI9 -> 11 | AN17: =Output!AJ9 -> 0.33255594 | AO17: =Output!AK9 -> 11 | AQ17: =Output!AM9 -> 0.41558442 | AR17: =Output!AN9 -> 1 | AS17: =Output!AO9 -> 9.8360656 | AU17: =Output!AQ9 -> 36.001467 | AV17: =Output!AR9 -> 10 | AX17: =Output!AT9 -> 29.560464 | AY17: =Output!AU9 -> 10 | BA17: =Output!AW9 -> 38.714997 | BB17: =Output!AX9 -> 10 | BD17: =Output!AZ9 -> 40.42734 | BE17: =Output!BA9 -> 10 | BF17: =Output!BB9 -> 0.81967213 | BG17: =Output!BC9 -> 0.31534498 | BH17: =Output!BD9 -> 6.2295082 | BI17: =Output!BE9 -> 0.10283097 | BJ17: =Output!BF9 -> 1 | BM17: Tech | BN17: =Output!BJ9 -> 6 | BO17: =Output!BK9 -> 1 | BP17: =Output!BL9 -> 9.6666667 | BQ17: =Output!BM9 -> Positive | BR17: =Output!BN9 -> 0 | BU17: =Output!BQ9 -> 5 | BV17: =Output!BR9 -> 0 | BW17: =Output!BS9 -> 9.6666667 | BX17: =Output!BT9 -> Positive | BY17: =Output!BU9 -> 0.052258645 | BZ17: =Output!BV9 -> 0.056685103
H18: Teleco | I18: =Output!E10 -> 11 | J18: =Output!F10 -> 1.2431694 | L18: =Output!H10 -> 2.5053768 | M18: =Output!I10 -> 1.489071 | O18: =Output!K10 -> 16.521243 | P18: =Output!L10 -> 7 | Q18: =Output!M10 -> 4.3306011 | S18: =Output!O10 -> 21.28983 | T18: =Output!P10 -> 4.2486339 | V18: =Output!R10 -> 14.124129 | W18: =Output!S10 -> 4.2486339 | Y18: =Output!U10 -> 33.946443 | Z18: =Output!V10 -> 12 | AA18: =Output!W10 -> 0.16393443 | AC18: =Output!Y10 -> 8.3836912 | AD18: =Output!Z10 -> 0.16393443 | AF18: =Output!AB10 -> 9.0730263 | AG18: =Output!AC10 -> 0.16393443 | AI18: =Output!AE10 -> 2.4858615 | AJ18: =Output!AF10 -> 7 | AK18: =Output!AG10 -> 9 | AL18: =Output!AH10 -> 0.10659809 | AM18: =Output!AI10 -> 8 | AN18: =Output!AJ10 -> 0.14705402 | AO18: =Output!AK10 -> 3 | AQ18: =Output!AM10 -> 0 | AR18: =Output!AN10 -> 5 | AS18: =Output!AO10 -> 10 | AU18: =Output!AQ10 -> 11.360303 | AV18: =Output!AR10 -> 4.7540984 | AX18: =Output!AT10 -> 4.0875964 | AY18: =Output!AU10 -> 3.7704918 | BA18: =Output!AW10 -> 6.1977528 | BB18: =Output!AX10 -> 7.2131148 | BD18: =Output!AZ10 -> 9.3484409 | BE18: =Output!BA10 -> 5 | BF18: =Output!BB10 -> 3.1147541 | BG18: =Output!BC10 -> 0.1867086 | BH18: =Output!BD10 -> 6.8852459 | BI18: =Output!BE10 -> 0.062384629 | BJ18: =Output!BF10 -> 11 | BM18: Teleco | BN18: =Output!BJ10 -> 0 | BO18: =Output!BK10 -> 5 | BP18: =Output!BL10 -> 4.5 | BQ18: =Output!BM10 -> Negative | BR18: =Output!BN10 -> 0 | BU18: =Output!BQ10 -> 0 | BV18: =Output!BR10 -> 3 | BW18: =Output!BS10 -> 4.5 | BX18: =Output!BT10 -> Negative | BY18: =Output!BU10 -> -0.043942083 | BZ18: =Output!BV10 -> -0.039515624
H19: Utilities | I19: =Output!E11 -> 12 | J19: =Output!F11 -> 0.74453552 | L19: =Output!H11 -> 5.5479955 | M19: =Output!I11 -> 0.49863388 | O19: =Output!K11 -> -4.7788353 | P19: =Output!L11 -> 4 | Q19: =Output!M11 -> 6.1270492 | S19: =Output!O11 -> 21.232479 | T19: =Output!P11 -> 4.6448087 | V19: =Output!R11 -> 13.297373 | W19: =Output!S11 -> 6.7964481 | Y19: =Output!U11 -> 37.04345 | Z19: =Output!V11 -> 5 | AA19: =Output!W11 -> 6.557377 | AC19: =Output!Y11 -> 7.9412878 | AD19: =Output!Z11 -> 6.3934426 | AF19: =Output!AB11 -> 10.88924 | AG19: =Output!AC11 -> 10 | AI19: =Output!AE11 -> 2.4471488 | AJ19: =Output!AF11 -> 11 | AK19: =Output!AG11 -> 1 | AL19: =Output!AH11 -> -0.088632992 | AM19: =Output!AI11 -> 2 | AN19: =Output!AJ11 -> -0.0265588 | AO19: =Output!AK11 -> 6 | AQ19: =Output!AM11 -> 0.032258065 | AR19: =Output!AN11 -> 10 | AS19: =Output!AO11 -> 6.8852459 | AU19: =Output!AQ11 -> 9.49338 | AV19: =Output!AR11 -> 3.1147541 | AX19: =Output!AT11 -> 5.8426547 | AY19: =Output!AU11 -> 2.1311475 | BA19: =Output!AW11 -> 10.967616 | BB19: =Output!AX11 -> 1.6393443 | BD19: =Output!AZ11 -> 8.1241154 | BE19: =Output!BA11 -> 2 | BF19: =Output!BB11 -> 8.6885246 | BG19: =Output!BC11 -> 0.12102276 | BH19: =Output!BD11 -> 6.0655738 | BI19: =Output!BE11 -> 0.07092775 | BJ19: =Output!BF11 -> 11 | BM19: Utilities | BN19: =Output!BJ11 -> 1 | BO19: =Output!BK11 -> 5 | BP19: =Output!BL11 -> 4.5 | BQ19: =Output!BM11 -> Negative | BR19: =Output!BN11 -> 0 | BU19: =Output!BQ11 -> 0 | BV19: =Output!BR11 -> 4 | BW19: =Output!BS11 -> 3.8333333 | BX19: =Output!BT11 -> Negative | BY19: =Output!BU11 -> -0.059589914 | BZ19: =Output!BV11 -> -0.055163455
H20: Travel & leisure | I20: =Output!E12 -> 2 | J20: =Output!F12 -> 7.2540984 | L20: =Output!H12 -> 1.6952167 | M20: =Output!I12 -> 6.5983607 | O20: =Output!K12 -> 22.719799 | P20: =Output!L12 -> 6 | Q20: =Output!M12 -> 5.1297814 | S20: =Output!O12 -> 18.920226 | T20: =Output!P12 -> 6.2090164 | V20: =Output!R12 -> 13.612803 | W20: =Output!S12 -> 3.8046448 | Y20: =Output!U12 -> 24.042664 | Z20: =Output!V12 -> 1 | AA20: =Output!W12 -> 9.8360656 | AC20: =Output!Y12 -> 12.713618 | AD20: =Output!Z12 -> 10 | AF20: =Output!AB12 -> 11.235713 | AG20: =Output!AC12 -> 10 | AI20: =Output!AE12 -> 2.7514969 | AJ20: =Output!AF12 -> 12 | AK20: =Output!AG12 -> 4 | AL20: =Output!AH12 -> 0.050646403 | AM20: =Output!AI12 -> 3 | AN20: =Output!AJ12 -> 0.021117731 | AO20: =Output!AK12 -> 1 | AQ20: =Output!AM12 -> -0.21052632 | AR20: =Output!AN12 -> 11 | AS20: =Output!AO12 -> 4.5901639 | AU20: =Output!AQ12 -> 14.977821 | AV20: =Output!AR12 -> 0.32786885 | AX20: =Output!AT12 -> 6.7978974 | AY20: =Output!AU12 -> 0.98360656 | BA20: =Output!AW12 -> 10.162244 | BB20: =Output!AX12 -> 0.98360656 | BD20: =Output!AZ12 -> 12.014106 | BE20: =Output!BA12 -> 8 | BF20: =Output!BB12 -> 7.704918 | BG20: =Output!BC12 -> 0.17450673 | BH20: =Output!BD12 -> 0.32786885 | BI20: =Output!BE12 -> 0.1167738 | BJ20: =Output!BF12 -> 7 | BM20: Travel & leisure | BN20: =Output!BJ12 -> 0 | BO20: =Output!BK12 -> 0 | BP20: =Output!BL12 -> 6.1666667 | BQ20: =Output!BM12 -> Neutral | BR20: =Output!BN12 -> 0 | BU20: =Output!BQ12 -> 0 | BV20: =Output!BR12 -> 0 | BW20: =Output!BS12 -> 6.5 | BX20: =Output!BT12 -> Neutral | BY20: =Output!BU12 -> -0.095295803 | BZ20: =Output!BV12 -> -0.090869344
H21: Media | I21: =Output!E13 -> 3 | J21: =Output!F13 -> 6.7759563 | L21: =Output!H13 -> 1.0694065 | M21: =Output!I13 -> 7.0218579 | O21: =Output!K13 -> 26.131654 | P21: =Output!L13 -> 3 | Q21: =Output!M13 -> 7.3360656 | S21: =Output!O13 -> 17.178344 | T21: =Output!P13 -> 6.0177596 | V21: =Output!R13 -> 11.411406 | W21: =Output!S13 -> 7.431694 | Y21: =Output!U13 -> 29.294221 | Z21: =Output!V13 -> 4 | AA21: =Output!W13 -> 9.1803279 | AC21: =Output!Y13 -> 13.834502 | AD21: =Output!Z13 -> 9.0163934 | AF21: =Output!AB13 -> 11.969054 | AG21: =Output!AC13 -> 5.9016393 | AI21: =Output!AE13 -> 2.5892003 | AJ21: =Output!AF13 -> 10 | AK21: =Output!AG13 -> 2 | AL21: =Output!AH13 -> -0.03633281 | AM21: =Output!AI13 -> 1 | AN21: =Output!AJ13 -> -0.18719948 | AO21: =Output!AK13 -> 10 | AQ21: =Output!AM13 -> 0.36363636 | AR21: =Output!AN13 -> 12 | AS21: =Output!AO13 -> 3.6065574 | AU21: =Output!AQ13 -> 16.867662 | AV21: =Output!AR13 -> 0.16393443 | AX21: =Output!AT13 -> 6.6243557 | AY21: =Output!AU13 -> 0.16393443 | BA21: =Output!AW13 -> 12.536011 | BB21: =Output!AX13 -> 0.16393443 | BD21: =Output!AZ13 -> 6.6976182 | BE21: =Output!BA13 -> 4 | BF21: =Output!BB13 -> 6.8852459 | BG21: =Output!BC13 -> 0.24715147 | BH21: =Output!BD13 -> 7.0491803 | BI21: =Output!BE13 -> 0.11285839 | BJ21: =Output!BF13 -> 6 | BM21: Media | BN21: =Output!BJ13 -> 3 | BO21: =Output!BK13 -> 2 | BP21: =Output!BL13 -> 6.5 | BQ21: =Output!BM13 -> Neutral | BR21: =Output!BN13 -> 0 | BU21: =Output!BQ13 -> 3 | BV21: =Output!BR13 -> 2 | BW21: =Output!BS13 -> 6 | BX21: =Output!BT13 -> Neutral | BY21: =Output!BU13 -> -0.082060778 | BZ21: =Output!BV13 -> -0.07763432
H26: =TEXT(Output!B2,"[$-040C]mmm-yyyy")&" Commentaire : " -> sept.-2026 Commentaire :

Sheet Output
A1: Marché | B1: US | D1: Secteur | E1: Leverage | F1: Score net debt ebitda | H1: net debt ebitda | I1: Score fcf total debt | K1: fcf total debt | L1: Margin | M1: Score operating margin | O1: operating margin | P1: Score net margin | R1: net margin | S1: Score ebitda margin | U1: ebitda margin | V1: Value | W1: Score price fcf | Y1: price fcf | Z1: Score ev ebitda | AB1: ev ebitda | AC1: Score price sales | AE1: price sales | AF1: Momentum | AG1: Score momentum 6m 1m | AH1: momentum 6m 1m | AI1: Score momentum 12m 1m | AJ1: momentum 12m 1m | AK1: Score earnings revision ratio | AM1: earnings revision ratio | AN1: Growth | AO1: Score eps growth | AQ1: eps growth | AR1: Score sales growth | AT1: sales growth | AU1: Score ebitda growth | AW1: ebitda growth | AX1: Score cash flow growth | AZ1: cash flow growth | BA1: Volatility | BB1: Score volatility 6m | BC1: volatility 6m | BD1: Score downside volatility 18m | BE1: downside volatility 18m | BF1: Macro | BI1: Secteur | BJ1: Votes Top | BK1: Votes Worst | BL1: Score global | BM1: Reco | BN1: Variation reco | BQ1: Votes Top précédents | BR1: Votes Worst précédents | BS1: Score précédent | BT1: Reco précédente | BU1: Sept-2026 EQ Performance | BV1: Sept-2026 XSRet vs WIUSAU Index
A2: Date modèle | B2: 46295 | D2: Materials | E2: 7 | F2: 4.8019126 | H2: 1.22262 | I2: 4.2076503 | K2: 22.028238 | L2: 5 | M2: 6.4480874 | O2: 19.657374 | P2: 4.4672131 | R2: 12.336806 | S2: 5.5327869 | U2: 27.295065 | V2: 11 | W2: 0.6557377 | Y2: 12.53727 | Z2: 0.32786885 | AB2: 10.69341 | AC2: 0.49180328 | AE2: 3.0101644 | AF2: 3 | AG2: 8 | AH2: 0.099930284 | AI2: 10 | AJ2: 0.27859081 | AK2: 9 | AM2: 0.30769231 | AN2: 2 | AO2: 8.1967213 | AQ2: 19.596372 | AR2: 8.6885246 | AT2: 6.8923117 | AU2: 8.0327869 | AW2: 14.662707 | AX2: 9.0163934 | AZ2: 22.047794 | BA2: 1 | BB2: 9.3442623 | BC2: 0.17282112 | BD2: 9.1803279 | BE2: 0.086038617 | BF2: 3 | BI2: Materials | BJ2: 4 | BK2: 2 | BL2: 8.5 | BM2: Positive | BN2: 1 | BQ2: 2 | BR2: 1 | BS2: 6.5 | BT2: Neutral | BU2: -0.054387894 | BV2: -0.049961435
A3: Derniers piliers | B3: 46295 | D3: ConsStaples | E3: 8 | F3: 2.4795082 | H3: 1.9202542 | I3: 6.4412568 | K3: 25.178694 | L3: 12 | M3: 0.49863388 | O3: 6.9512161 | P3: 0.49863388 | R3: 4.979818 | S3: 0.49863388 | U3: 8.4210974 | V3: 6 | W3: 3.7704918 | Y3: 14.235069 | Z3: 3.2786885 | AB3: 12.611009 | AC3: 7.8688525 | AE3: 0.91152254 | AF3: 10 | AG3: 5 | AH3: 0.057409307 | AI3: 6 | AJ3: 0.10520092 | AK3: 2 | AM3: -0.038461538 | AN3: 8 | AO3: 7.8688525 | AQ3: 6.9321977 | AR3: 2.1311475 | AT3: 4.4229456 | AU3: 1.9672131 | AW3: 5.7536922 | AX3: 3.442623 | AZ3: 9.7312479 | BA3: 12 | BB3: 4.5901639 | BC3: 0.15794132 | BD3: 0.98360656 | BE3: 0.094598589 | BF3: 12 | BI3: ConsStaples | BJ3: 0 | BK3: 3 | BL3: 3.6666667 | BM3: Negative | BN3: 0 | BQ3: 0 | BR3: 2 | BS3: 4.1666667 | BT3: Negative | BU3: -0.036884392 | BV3: -0.032457934
A4: Allocation | B4: 46296 | D4: Retail | E4: 10 | F4: 4.3306011 | H4: 0.49591342 | I4: 2.397541 | K4: 17.857379 | L4: 11 | M4: 1.8989071 | O4: 8.9815098 | P4: 3.1284153 | R4: 7.0708821 | S4: 2.1448087 | U4: 13.587507 | V4: 2 | W4: 10 | Y4: 13.787961 | Z4: 10 | AB4: 11.773436 | AC4: 9.1803279 | AE4: 1.8559352 | AF4: 8 | AG4: 6 | AH4: 0.079188564 | AI4: 4 | AJ4: 0.081707795 | AK4: 8 | AM4: 0.2 | AN4: 3 | AO4: 2.4590164 | AQ4: 5.5615651 | AR4: 5.4098361 | AT4: 8.8864034 | AU4: 10 | AW4: 21.205741 | AX4: 3.6065574 | AZ4: 19.614034 | BA4: 8 | BB4: 0.6557377 | BC4: 0.26849553 | BD4: 7.3770492 | BE4: 0.084264252 | BF4: 5 | BI4: Retail | BJ4: 3 | BK4: 2 | BL4: 7 | BM4: Neutral | BN4: -1 | BQ4: 3 | BR4: 2 | BS4: 7.8333333 | BT4: Positive | BU4: -0.043559021 | BV4: -0.039132563
A5: Cycle | B5: E | D5: Fin | E5: 1 | F5: 9.0163934 | H5: -2.0866902 | I5: 6.6734973 | K5: 22.209445 | L5: 2 | M5: 7.9439891 | O5: 21.658118 | P5: 7.9439891 | R5: 16.054846 | S5: 5.1297814 | U5: 28.346714 | V5: 8 | W5: n.a. | Y5: n.a. | Z5: n.a. | AB5: n.a. | AC5: 5.7377049 | AE5: 2.8520047 | AF5: 6 | AG5: 11 | AH5: 0.14490912 | AI5: 5 | AJ5: 0.089314593 | AK5: 5 | AM5: 0.014925373 | AN5: 6 | AO5: 5.9016393 | AQ5: 9.7731301 | AR5: 2.4590164 | AT5: 6.0163324 | AU5: n.a. | AW5: n.a. | AX5: n.a. | AZ5: n.a. | BA5: 3 | BB5: 7.0491803 | BC5: 0.17070161 | BD5: 7.3770492 | BE5: 0.071893946 | BF5: 3 | BI5: Fin | BJ5: 5 | BK5: 0 | BL5: 8.5 | BM5: Positive | BN5: 0 | BQ5: 4 | BR5: 1 | BS5: 8.1666667 | BT5: Positive | BU5: -0.074213842 | BV5: -0.069787384
A6: Signal taux | B6: On | D6: HealthCare | E6: 9 | F6: 2.1653005 | H6: 1.7058441 | I6: 6.0519126 | K6: 27.543317 | L6: 8 | M6: 1.9057377 | O6: 12.913112 | P6: 1.7418033 | R6: 9.2893927 | S6: 8.5040984 | U6: 32.941353 | V6: 10 | W6: 0.16393443 | Y6: 16.987361 | Z6: 0.16393443 | AB6: 15.705992 | AC6: 6.0655738 | AE6: 2.4448214 | AF6: 4 | AG6: 10 | AH6: 0.14390425 | AI6: 9 | AJ6: 0.22268254 | AK6: 3 | AM6: 0 | AN6: 4 | AO6: 9.1803279 | AQ6: 17.856892 | AR6: 0.98360656 | AT6: 4.5266928 | AU6: 6.557377 | AW6: 14.497431 | AX6: 6.8852459 | AZ6: 15.896039 | BA6: 11 | BB6: 5.2459016 | BC6: 0.16169832 | BD6: 1.147541 | BE6: 0.086891746 | BF6: 9 | BI6: HealthCare | BJ6: 0 | BK6: 3 | BL6: 5.1666667 | BM6: Neutral | BN6: 0 | BQ6: 0 | BR6: 1 | BS6: 5 | BT6: Neutral | BU6: -0.0067022413 | BV6: -0.0022757826
A7: Derniers poids benchmark | B7: 46326 | D7: Indus | E7: 6 | F7: 2.6502732 | H7: 1.7344032 | I7: 8.6680328 | K7: 26.948095 | L7: 10 | M7: 2.1653005 | O7: 16.237674 | P7: 4.3101093 | R7: 12.887893 | S7: 1.3319672 | U7: 21.062697 | V7: 7 | W7: 1.6393443 | Y7: 17.405303 | Z7: 1.3114754 | AB7: 15.327033 | AC7: 7.5409836 | AE7: 2.9930543 | AF7: 6 | AG7: 7 | AH7: 0.093829499 | AI7: 7 | AJ7: 0.11693454 | AK7: 7 | AM7: 0.096774194 | AN7: 9 | AO7: 8.1967213 | AQ7: 13.931877 | AR7: 5.4098361 | AT7: 7.9835015 | AU7: 2.4590164 | AW7: 11.738682 | AX7: 2.1311475 | AZ7: 14.563399 | BA7: 9 | BB7: 5.7377049 | BC7: 0.18457319 | BD7: 1.4754098 | BE7: 0.099040037 | BF7: 8 | BI7: Indus | BJ7: 0 | BK7: 0 | BL7: 5.5 | BM7: Neutral | BN7: 0 | BQ7: 0 | BR7: 0 | BS7: 6 | BT7: Neutral | BU7: -0.048431204 | BV7: -0.044004745
A8: Derniers rendements | B8: 46295 | D8: Oil | E8: 5 | F8: 5.6352459 | H8: 1.0167123 | I8: 6.7964481 | K8: 36.24289 | L8: 9 | M8: 3.7978142 | O8: 13.425094 | P8: 3.6338798 | R8: 9.7795478 | S8: 3.6338798 | U8: 21.631408 | V8: 9 | W8: 1.4754098 | Y8: 7.3348122 | Z8: 0.98360656 | AB8: 6.8885213 | AC8: 4.4262295 | AE8: 1.5599016 | AF8: 3 | AG8: 3 | AH8: 0.021864807 | AI8: 12 | AJ8: 0.42613895 | AK8: 12 | AM8: 0.5 | AN8: 7 | AO8: 9.0163934 | AQ8: 14.60133 | AR8: 2.7868852 | AT8: 1.1215868 | AU8: 3.442623 | AW8: 8.1029064 | AX8: 4.9180328 | AZ8: 9.8949627 | BA8: 6 | BB8: 3.9344262 | BC8: 0.26727375 | BD8: 5.4098361 | BE8: 0.14596108 | BF8: 4 | BI8: Oil | BJ8: 1 | BK8: 0 | BL8: 7.3333333 | BM8: Neutral | BN8: 0 | BQ8: 2 | BR8: 0 | BS8: 8.5 | BT8: Neutral | BU8: -0.029401703 | BV8: -0.024975244
A9: Mois allocation | B9: Oct-2026 | D9: Tech | E9: 4 | F9: 5.6489071 | H9: 0.10783016 | I9: 6.8852459 | K9: 64.397494 | L9: 1 | M9: 10 | O9: 34.782338 | P9: 10 | R9: 30.22492 | S9: 10 | U9: 41.002375 | V9: 3 | W9: 8.3783784 | Y9: 18.31349 | Z9: 8.3783784 | AB9: 15.584779 | AC9: 3.6065574 | AE9: 7.5240099 | AF9: 1 | AG9: 12 | AH9: 0.40754468 | AI9: 11 | AJ9: 0.33255594 | AK9: 11 | AM9: 0.41558442 | AN9: 1 | AO9: 9.8360656 | AQ9: 36.001467 | AR9: 10 | AT9: 29.560464 | AU9: 10 | AW9: 38.714997 | AX9: 10 | AZ9: 40.42734 | BA9: 10 | BB9: 0.81967213 | BC9: 0.31534498 | BD9: 6.2295082 | BE9: 0.10283097 | BF9: 1 | BI9: Tech | BJ9: 6 | BK9: 1 | BL9: 9.6666667 | BM9: Positive | BN9: 0 | BQ9: 5 | BR9: 0 | BS9: 9.6666667 | BT9: Positive | BU9: 0.052258645 | BV9: 0.056685103
A10: Mois signal | B10: Sept-2026 | D10: Telco | E10: 11 | F10: 1.2431694 | H10: 2.5053768 | I10: 1.489071 | K10: 16.521243 | L10: 7 | M10: 4.3306011 | O10: 21.28983 | P10: 4.2486339 | R10: 14.124129 | S10: 4.2486339 | U10: 33.946443 | V10: 12 | W10: 0.16393443 | Y10: 8.3836912 | Z10: 0.16393443 | AB10: 9.0730263 | AC10: 0.16393443 | AE10: 2.4858615 | AF10: 7 | AG10: 9 | AH10: 0.10659809 | AI10: 8 | AJ10: 0.14705402 | AK10: 3 | AM10: 0 | AN10: 5 | AO10: 10 | AQ10: 11.360303 | AR10: 4.7540984 | AT10: 4.0875964 | AU10: 3.7704918 | AW10: 6.1977528 | AX10: 7.2131148 | AZ10: 9.3484409 | BA10: 5 | BB10: 3.1147541 | BC10: 0.1867086 | BD10: 6.8852459 | BE10: 0.062384629 | BF10: 11 | BI10: Telco | BJ10: 0 | BK10: 5 | BL10: 4.5 | BM10: Negative | BN10: 0 | BQ10: 0 | BR10: 3 | BS10: 4.5 | BT10: Negative | BU10: -0.043942083 | BV10: -0.039515624
A11: Classement courant | B11: Sectors Ranking Oct-2026 | D11: Utili | E11: 12 | F11: 0.74453552 | H11: 5.5479955 | I11: 0.49863388 | K11: -4.7788353 | L11: 4 | M11: 6.1270492 | O11: 21.232479 | P11: 4.6448087 | R11: 13.297373 | S11: 6.7964481 | U11: 37.04345 | V11: 5 | W11: 6.557377 | Y11: 7.9412878 | Z11: 6.3934426 | AB11: 10.88924 | AC11: 10 | AE11: 2.4471488 | AF11: 11 | AG11: 1 | AH11: -0.088632992 | AI11: 2 | AJ11: -0.0265588 | AK11: 6 | AM11: 0.032258065 | AN11: 10 | AO11: 6.8852459 | AQ11: 9.49338 | AR11: 3.1147541 | AT11: 5.8426547 | AU11: 2.1311475 | AW11: 10.967616 | AX11: 1.6393443 | AZ11: 8.1241154 | BA11: 2 | BB11: 8.6885246 | BC11: 0.12102276 | BD11: 6.0655738 | BE11: 0.07092775 | BF11: 11 | BI11: Utili | BJ11: 1 | BK11: 5 | BL11: 4.5 | BM11: Negative | BN11: 0 | BQ11: 0 | BR11: 4 | BS11: 3.8333333 | BT11: Negative | BU11: -0.059589914 | BV11: -0.055163455
A12: Classement précédent | B12: Sectors Ranking Sept-2026 | D12: Travel & leisure | E12: 2 | F12: 7.2540984 | H12: 1.6952167 | I12: 6.5983607 | K12: 22.719799 | L12: 6 | M12: 5.1297814 | O12: 18.920226 | P12: 6.2090164 | R12: 13.612803 | S12: 3.8046448 | U12: 24.042664 | V12: 1 | W12: 9.8360656 | Y12: 12.713618 | Z12: 10 | AB12: 11.235713 | AC12: 10 | AE12: 2.7514969 | AF12: 12 | AG12: 4 | AH12: 0.050646403 | AI12: 3 | AJ12: 0.021117731 | AK12: 1 | AM12: -0.21052632 | AN12: 11 | AO12: 4.5901639 | AQ12: 14.977821 | AR12: 0.32786885 | AT12: 6.7978974 | AU12: 0.98360656 | AW12: 10.162244 | AX12: 0.98360656 | AZ12: 12.014106 | BA12: 8 | BB12: 7.704918 | BC12: 0.17450673 | BD12: 0.32786885 | BE12: 0.1167738 | BF12: 7 | BI12: Travel & leisure | BJ12: 0 | BK12: 0 | BL12: 6.1666667 | BM12: Neutral | BN12: 0 | BQ12: 0 | BR12: 0 | BS12: 6.5 | BT12: Neutral | BU12: -0.095295803 | BV12: -0.090869344
A13: Classement macro | B13: Macro rank - Currently in Expansion | D13: Media | E13: 3 | F13: 6.7759563 | H13: 1.0694065 | I13: 7.0218579 | K13: 26.131654 | L13: 3 | M13: 7.3360656 | O13: 17.178344 | P13: 6.0177596 | R13: 11.411406 | S13: 7.431694 | U13: 29.294221 | V13: 4 | W13: 9.1803279 | Y13: 13.834502 | Z13: 9.0163934 | AB13: 11.969054 | AC13: 5.9016393 | AE13: 2.5892003 | AF13: 10 | AG13: 2 | AH13: -0.03633281 | AI13: 1 | AJ13: -0.18719948 | AK13: 10 | AM13: 0.36363636 | AN13: 12 | AO13: 3.6065574 | AQ13: 16.867662 | AR13: 0.16393443 | AT13: 6.6243557 | AU13: 0.16393443 | AW13: 12.536011 | AX13: 0.16393443 | AZ13: 6.6976182 | BA13: 4 | BB13: 6.8852459 | BC13: 0.24715147 | BD13: 7.0491803 | BE13: 0.11285839 | BF13: 6 | BI13: Media | BJ13: 3 | BK13: 2 | BL13: 6.5 | BM13: Neutral | BN13: 0 | BQ13: 3 | BR13: 2 | BS13: 6 | BT13: Neutral | BU13: -0.082060778 | BV13: -0.07763432
A14: Référence | B14: Bench
A15: Top | B15: -0.021838073
A16: Short | B16: 0.046805463
A17: Long / Short | B17: 0.02496739
A18: Portefeuille | B18: 0.00036872701
A19: Benchmark | B19: -0.0044264587
D22: US Reco | E22: 45870 | F22: 45901 | G22: 45931 | H22: 45962 | I22: 45992 | J22: 46023 | K22: 46054 | L22: 46082 | M22: 46113 | N22: 46143 | O22: 46174 | P22: 46204 | Q22: 46235 | R22: 46266 | S22: 46296 | W22: US equity sectors Performance
D23: Materials | E23: 0 | F23: -1 | G23: 0 | H23: 0 | I23: -1 | J23: -1 | K23: -1 | L23: -1 | M23: -1 | N23: -1 | O23: 0 | P23: 0 | Q23: 0 | R23: 0 | S23: 1 | W23: Materials | X23: ConsStaples | Y23: Retail | Z23: Fin | AA23: HealthCare | AB23: Indus | AC23: Oil | AD23: Tech | AE23: Telco | AF23: Utili | AG23: Travel & leisure | AH23: Media
D24: ConsStaples | E24: 0 | F24: -1 | G24: 1 | H24: 0 | I24: -1 | J24: 0 | K24: 0 | L24: -1 | M24: 0 | N24: -1 | O24: -1 | P24: -1 | Q24: 0 | R24: -1 | S24: -1 | V24: 1M | W24: -0.054387894 | X24: -0.036884392 | Y24: -0.043559021 | Z24: -0.074213842 | AA24: -0.0067022413 | AB24: -0.048431204 | AC24: -0.029401703 | AD24: 0.052258645 | AE24: -0.043942083 | AF24: -0.059589914 | AG24: -0.095295803 | AH24: -0.082060778
D25: Retail | E25: -1 | F25: 0 | G25: 0 | H25: 1 | I25: 1 | J25: 1 | K25: 0 | L25: 1 | M25: 1 | N25: 0 | O25: 0 | P25: 0 | Q25: 0 | R25: 1 | S25: 0 | V25: 3M | W25: 0.022004223 | X25: -0.01115737 | Y25: -0.011006285 | Z25: -0.010102395 | AA25: 0.063765978 | AB25: -0.06190348 | AC25: 0.16545088 | AD25: 0.069973117 | AE25: 0.0062520227 | AF25: -0.11929195 | AG25: -0.085463463 | AH25: 0.037707571
D26: Fin | E26: 1 | F26: 1 | G26: 1 | H26: 1 | I26: 1 | J26: 1 | K26: 1 | L26: 1 | M26: 1 | N26: 1 | O26: 1 | P26: 1 | Q26: 1 | R26: 1 | S26: 1 | V26: YTD | W26: 0.20541071 | X26: 0.087228865 | Y26: 0.014974824 | Z26: -0.010013544 | AA26: 0.094659587 | AB26: 0.043231188 | AC26: 0.3898813 | AD26: 0.25419521 | AE26: 0.16771374 | AF26: -0.056915906 | AG26: -0.092342557 | AH26: -0.16301121
D27: HealthCare | E27: 0 | F27: 0 | G27: -1 | H27: 0 | I27: 0 | J27: 0 | K27: 0 | L27: 0 | M27: 0 | N27: 0 | O27: 0 | P27: 0 | Q27: 0 | R27: 0 | S27: 0 | V27: 1Y | W27: 0.212058 | X27: 0.080928192 | Y27: 0.028165945 | Z27: 0.013429275 | AA27: 0.21959982 | AB27: 0.062532271 | AC27: 0.40668572 | AD27: 0.29408388 | AE27: 0.11531655 | AF27: -0.072420695 | AG27: -0.075556207 | AH27: -0.25897627
D28: Indus | E28: 0 | F28: 0 | G28: 0 | H28: -1 | I28: -1 | J28: -1 | K28: 0 | L28: 0 | M28: 0 | N28: -1 | O28: 0 | P28: -1 | Q28: 0 | R28: 0 | S28: 0 | V28: 3Y | W28: 0.49821157 | X28: 0.26368888 | Y28: 0.68488423 | Z28: 0.77351628 | AA28: 0.35713667 | AB28: 0.59130885 | AC28: 0.49387035 | AD28: 1.5938367 | AE28: 0.63564349 | AF28: 0.48205709 | AG28: 0.26472854 | AH28: 0.58533631
D29: Oil | E29: -1 | F29: -1 | G29: -1 | H29: -1 | I29: 0 | J29: -1 | K29: -1 | L29: 0 | M29: 0 | N29: 1 | O29: 0 | P29: 0 | Q29: -1 | R29: 0 | S29: 0 | V29: 5Y | W29: 0.60175942 | X29: 0.39610968 | Y29: 0.48958854 | Z29: 0.67544292 | AA29: 0.40138166 | AB29: 0.52281563 | AC29: 1.7207164 | AD29: 1.7811654 | AE29: 0.37843947 | AF29: 0.48404174 | AG29: 0.24155931 | AH29: -0.07980338
D30: Tech | E30: 1 | F30: 1 | G30: 1 | H30: 1 | I30: 1 | J30: 1 | K30: 1 | L30: 1 | M30: 1 | N30: 1 | O30: 1 | P30: 1 | Q30: 1 | R30: 1 | S30: 1
D31: Telco | E31: 1 | F31: 0 | G31: 0 | H31: -1 | I31: 0 | J31: 0 | K31: 0 | L31: 0 | M31: -1 | N31: 0 | O31: -1 | P31: -1 | Q31: -1 | R31: -1 | S31: -1
D32: Utili | E32: -1 | F32: 0 | G32: -1 | H32: 0 | I32: 0 | J32: 0 | K32: -1 | L32: -1 | M32: -1 | N32: 0 | O32: -1 | P32: 0 | Q32: -1 | R32: -1 | S32: -1
D33: Travel & leisure | E33: 0 | F33: 0 | G33: 0 | H33: 0 | I33: 0 | J33: 0 | K33: 0 | L33: 0 | M33: 0 | N33: 0 | O33: 0 | P33: 0 | Q33: 0 | R33: 0 | S33: 0
D34: Media | E34: 0 | F34: 1 | G34: 0 | H34: 0 | I34: 0 | J34: 0 | K34: 1 | L34: 0 | M34: 0 | N34: 0 | O34: 1 | P34: 1 | Q34: 1 | R34: 0 | S34: 0
D37: Variable | E37: Secteur | F37: 46295 | G37: 46265 | H37: 46234 | I37: 46203 | J37: 46173 | K37: 46142 | L37: 46112 | M37: 46081 | N37: 46053 | O37: 46022 | P37: 45991 | Q37: 45961 | R37: 45930 | S37: 45900 | T37: 45869 | U37: 45838 | V37: 45808 | W37: 45777 | X37: 45747 | Y37: 45716 | Z37: 45688 | AA37: 45657 | AB37: 45626 | AC37: 45596 | AD37: 45565 | AE37: 45535 | AF37: 45504 | AG37: 45473 | AH37: 45443 | AI37: 45412 | AJ37: 45382 | AK37: 45351 | AL37: 45322 | AM37: 45291 | AN37: 45260 | AO37: 45230 | AP37: 45199 | AQ37: 45169 | AR37: 45138 | AS37: 45107 | AT37: 45077 | AU37: 45046 | AV37: 45016 | AW37: 44985 | AX37: 44957 | AY37: 44926 | AZ37: 44895 | BA37: 44865 | BB37: 44834 | BC37: 44804 | BD37: 44773 | BE37: 44742 | BF37: 44712 | BG37: 44681 | BH37: 44651 | BI37: 44620 | BJ37: 44592 | BK37: 44561 | BL37: 44530 | BM37: 44500
D38: net_debt_ebitda | E38: Materials | F38: -0.1886202 | G38: -0.16656903 | H38: -0.14407259 | I38: -0.14333246 | J38: -0.14259649 | K38: -0.00050595779 | L38: 0.00079569051 | M38: -0.060725718 | N38: -0.095820443 | O38: -0.098133568 | P38: -0.095564738 | Q38: -0.035695971 | R38: -0.037418557 | S38: -0.11991504 | T38: -0.062352844 | U38: -0.066342639 | V38: -0.068328729 | W38: -0.24212693 | X38: -0.24439578 | Y38: -0.094247781 | Z38: -0.18267729 | AA38: -0.17201713 | AB38: -0.16674135 | AC38: -0.18160108 | AD38: -0.18892075 | AE38: -0.18684523 | AF38: -0.31122882 | AG38: -0.31499266 | AH38: -0.26697357 | AI38: -0.40446639 | AJ38: -0.40379739 | AK38: -0.40203954 | AL38: -0.50842786 | AM38: -0.51171699 | AN38: -0.509103 | AO38: -0.61073149 | AP38: -0.61039909 | AQ38: -0.68164145 | AR38: -0.83226261 | AS38: -0.84372812 | AT38: -0.83232673 | AU38: -0.96223965 | AV38: -0.96740042 | AW38: -0.97574544 | AX38: -1.1215382 | AY38: -1.129425 | AZ38: -1.1087628 | BA38: -1.1307898 | BB38: -1.1399409 | BC38: -1.1417231 | BD38: -1.1827264 | BE38: -1.1894902 | BF38: -1.1806219 | BG38: -1.0394366 | BH38: -1.0311144 | BI38: -1.009943 | BJ38: -1.0623405 | BK38: -1.0637501 | BL38: -1.0679769 | BM38: -1.193618
D39: net_debt_ebitda | E39: ConsStaples | F39: 0.50901394 | G39: 0.51303007 | H39: 0.50735014 | I39: 0.50572946 | J39: 0.51723143 | K39: 0.55873421 | L39: 0.54520613 | M39: 0.54788312 | N39: 0.69867216 | O39: 0.69628177 | P39: 0.71171689 | Q39: 0.74395303 | R39: 0.75446563 | S39: 0.64255636 | T39: 0.59656264 | U39: 0.58256649 | V39: 0.58838906 | W39: 0.49283813 | X39: 0.4821607 | Y39: 0.43707707 | Z39: 0.40294667 | AA39: 0.40154384 | AB39: 0.41666393 | AC39: 0.33165915 | AD39: 0.34379788 | AE39: 0.2989976 | AF39: 0.17948379 | AG39: 0.18228982 | AH39: 0.18208774 | AI39: 0.14481078 | AJ39: 0.13636133 | AK39: 0.12460735 | AL39: 0.17520076 | AM39: 0.16332954 | AN39: 0.16699828 | AO39: 0.16493624 | AP39: 0.20212414 | AQ39: 0.1273318 | AR39: 0.10568081 | AS39: 0.11490896 | AT39: 0.12023058 | AU39: 0.057115409 | AV39: 0.030369472 | AW39: 0.017374734 | AX39: -0.15059656 | AY39: -0.16332269 | AZ39: -0.14273463 | BA39: -0.1081705 | BB39: -0.11698021 | BC39: -0.13878219 | BD39: -0.17551542 | BE39: -0.17529628 | BF39: -0.16964135 | BG39: -0.15952683 | BH39: -0.1593386 | BI39: -0.1253832 | BJ39: -0.21675476 | BK39: -0.21703911 | BL39: -0.21581798 | BM39: -0.46343896
D40: net_debt_ebitda | E40: Retail | F40: -0.9153268 | G40: -0.88536835 | H40: -1.0024293 | I40: -1.0000459 | J40: -1.0040955 | K40: -1.0521065 | L40: -1.0515473 | M40: -1.0242029 | N40: -0.99330927 | O40: -0.98077691 | P40: -1.0445303 | Q40: -1.0674877 | R40: -1.0764109 | S40: -1.0913422 | T40: -1.0586786 | U40: -1.0584657 | V40: -1.0661104 | W40: -1.0717101 | X40: -1.0704964 | Y40: -1.0736624 | Z40: -1.0696266 | AA40: -1.0684357 | AB40: -1.0570889 | AC40: -1.046785 | AD40: -1.0603211 | AE40: -1.142092 | AF40: -1.1872412 | AG40: -1.1901721 | AH40: -1.1614228 | AI40: -1.1465167 | AJ40: -1.1867795 | AK40: -1.1450159 | AL40: -0.97232676 | AM40: -0.95928455 | AN40: -0.97277409 | AO40: -0.99225142 | AP40: -1.0114538 | AQ40: -1.0525555 | AR40: -1.046318 | AS40: -1.0629231 | AT40: -1.1097311 | AU40: -1.0768057 | AV40: -1.0782339 | AW40: -1.0255266 | AX40: -0.97877639 | AY40: -0.96704175 | AZ40: -1.0218702 | BA40: -1.0704458 | BB40: -1.1012367 | BC40: -1.130804 | BD40: -1.282958 | BE40: -1.2938003 | BF40: -1.4288119 | BG40: -1.5256111 | BH40: -1.5326979 | BI40: -1.5618381 | BJ40: -1.6227903 | BK40: -1.6160009 | BL40: -1.6634396 | BM40: -2.0477631
D41: net_debt_ebitda | E41: Fin | F41: -3.4979304 | G41: -3.6012179 | H41: -3.854494 | I41: -3.8559633 | J41: -3.83894 | K41: -3.7953749 | L41: -3.7997552 | M41: -3.7671223 | N41: -3.6272973 | O41: -3.6385274 | P41: -3.6233693 | Q41: -3.6366741 | R41: -3.6470905 | S41: -2.521433 | T41: -2.4869207 | U41: -2.4284502 | V41: -2.5021162 | W41: -2.3425056 | X41: -2.335032 | Y41: -2.3326482 | Z41: -2.4130504 | AA41: -2.3867641 | AB41: -2.5011118 | AC41: -2.2397563 | AD41: -2.2100308 | AE41: -2.1766398 | AF41: -1.2875748 | AG41: -1.289795 | AH41: -1.2703375 | AI41: -0.86636719 | AJ41: -0.86353895 | AK41: -0.87548747 | AL41: -0.73366844 | AM41: -0.73588137 | AN41: -0.7386563 | AO41: -0.62080882 | AP41: -0.61905526 | AQ41: 0.063151996 | AR41: 0.45268269 | AS41: 0.45694098 | AT41: 0.42009745 | AU41: 0.28362486 | AV41: 0.2809545 | AW41: 0.28207701 | AX41: 0.53474391 | AY41: 0.58164205 | AZ41: 0.44426515 | BA41: 0.57370196 | BB41: 0.56773761 | BC41: 0.58497625 | BD41: 0.7819976 | BE41: 0.83972166 | BF41: 0.77517265 | BG41: -0.2214089 | BH41: -0.20854306 | BI41: -0.11658157 | BJ41: -0.39182812 | BK41: -0.39170033 | BL41: -0.41551637 | BM41: -0.54955353
D42: net_debt_ebitda | E42: HealthCare | F42: 0.29460385 | G42: 0.28815496 | H42: 0.20519457 | I42: 0.20051305 | J42: 0.2005427 | K42: 0.095534184 | L42: 0.088137543 | M42: 0.08919031 | N42: 0.057560532 | O42: 0.054270754 | P42: 0.059274515 | Q42: 0.17771945 | R42: 0.17508546 | S42: 0.097437773 | T42: 0.077823697 | U42: 0.070571452 | V42: 0.081341938 | W42: 0.062566916 | X42: 0.057989536 | Y42: 0.034820714 | Z42: 0.1639829 | AA42: 0.15584557 | AB42: 0.17762351 | AC42: 0.23203157 | AD42: 0.22235357 | AE42: 0.18985745 | AF42: 0.1486736 | AG42: 0.14356589 | AH42: 0.15963199 | AI42: -0.032448091 | AJ42: -0.019887465 | AK42: -0.011074874 | AL42: -0.36807668 | AM42: -0.37343733 | AN42: -0.36030809 | AO42: -0.41284233 | AP42: -0.43383197 | AQ42: -0.47132293 | AR42: -0.6591661 | AS42: -0.671534 | AT42: -0.66140751 | AU42: -0.7329649 | AV42: -0.73947623 | AW42: -0.75562623 | AX42: -0.88511346 | AY42: -0.88485992 | AZ42: -0.86872951 | BA42: -0.83675384 | BB42: -0.84678009 | BC42: -0.86467454 | BD42: -0.80058889 | BE42: -0.8112418 | BF42: -0.79274891 | BG42: -0.72935271 | BH42: -0.72061611 | BI42: -0.71420194 | BJ42: -0.89572636 | BK42: -0.89871676 | BL42: -0.89583354 | BM42: -1.0702527
D43: net_debt_ebitda | E43: Indus | F43: 0.32316294 | G43: 0.33990022 | H43: 0.39323236 | I43: 0.38292046 | J43: 0.36734842 | K43: 0.28924947 | L43: 0.29963172 | M43: 0.35526308 | N43: 0.42897319 | O43: 0.42807276 | P43: 0.42544221 | Q43: 0.43031137 | R43: 0.44770761 | S43: 0.32536985 | T43: 0.28306304 | U43: 0.27286085 | V43: 0.28285635 | W43: 0.179721 | X43: 0.18464426 | Y43: 0.15113506 | Z43: 0.1511582 | AA43: 0.14176181 | AB43: 0.14301503 | AC43: 0.11494305 | AD43: 0.12481852 | AE43: 0.083474507 | AF43: -0.035448188 | AG43: -0.033687022 | AH43: -0.023274184 | AI43: -0.064122513 | AJ43: -0.072750828 | AK43: -0.070841753 | AL43: -0.064856192 | AM43: -0.079700467 | AN43: -0.1018135 | AO43: -0.16371283 | AP43: -0.16650101 | AQ43: -0.22104383 | AR43: -0.20602547 | AS43: -0.20755703 | AT43: -0.20848813 | AU43: -0.17848689 | AV43: -0.18075521 | AW43: -0.18954589 | AX43: -0.14474118 | AY43: -0.1671636 | AZ43: -0.13269222 | BA43: -0.16255759 | BB43: -0.16902794 | BC43: -0.19462957 | BD43: -0.28995851 | BE43: -0.28912332 | BF43: -0.28680106 | BG43: -0.29978862 | BH43: -0.2899714 | BI43: -0.283123 | BJ43: -0.37832615 | BK43: -0.38241539 | BL43: -0.37693085 | BM43: -0.65600567
D44: net_debt_ebitda | E44: Oil | F44: -0.39452795 | G44: -0.40439958 | H44: -0.11459055 | I44: -0.11887452 | J44: -0.12169714 | K44: -0.044724178 | L44: -0.047521704 | M44: -0.05460077 | N44: -0.032960452 | O44: -0.035989975 | P44: -0.038154621 | Q44: -0.11978825 | R44: -0.12434161 | S44: -0.23559575 | T44: -0.28580747 | U44: -0.29731913 | V44: -0.29301167 | W44: -0.35247035 | X44: -0.35352195 | Y44: -0.45300774 | Z44: -0.58600131 | AA44: -0.58464979 | AB44: -0.57217068 | AC44: -0.73498762 | AD44: -0.74512258 | AE44: -0.78639858 | AF44: -0.92791759 | AG44: -0.9312497 | AH44: -0.91485313 | AI44: -1.0144151 | AJ44: -1.0147372 | AK44: -1.0150973 | AL44: -1.0584529 | AM44: -1.0625992 | AN44: -1.070738 | AO44: -1.1932435 | AP44: -1.208659 | AQ44: -1.2750111 | AR44: -1.4549895 | AS44: -1.4699415 | AT44: -1.4723614 | AU44: -1.4383888 | AV44: -1.4458393 | AW44: -1.4765944 | AX44: -1.4315054 | AY44: -1.4390982 | AZ44: -1.4180016 | BA44: -1.3101305 | BB44: -1.3216611 | BC44: -1.3408481 | BD44: -1.0753002 | BE44: -1.0895868 | BF44: -1.0753618 | BG44: -0.7215256 | BH44: -0.7161404 | BI44: -0.69454673 | BJ44: -0.36194168 | BK44: -0.36134134 | BL44: -0.35149676 | BM44: -0.0039491088
...

Sheet Reco_histo
A1: Date | B1: Top | N1: Worst
A2: Date | B2: Materials | C2: ConsStaples | D2: Retail | E2: Fin | F2: HealthCare | G2: Indus | H2: Oil | I2: Tech | J2: Telco | K2: Utili | L2: Travel & leisure | M2: Media | N2: Materials | O2: ConsStaples | P2: Retail | Q2: Fin | R2: HealthCare | S2: Indus | T2: Oil | U2: Tech | V2: Telco | W2: Utili | X2: Travel & leisure | Y2: Media
A3: 40235 | B3: 0 | C3: 0 | D3: 0 | E3: 0 | F3: 1 | G3: 0 | H3: 0 | I3: 1 | J3: 0 | K3: 0 | L3: 0 | M3: 0 | N3: 0 | O3: 0 | P3: 1 | Q3: 0 | R3: 0 | S3: 0 | T3: 0 | U3: 0 | V3: 1 | W3: 1 | X3: 0 | Y3: 0
A4: 40268 | B4: 0 | C4: 0 | D4: 1 | E4: 0 | F4: 1 | G4: 0 | H4: 0 | I4: 1 | J4: 0 | K4: 0 | L4: 0 | M4: 0 | N4: 0 | O4: 0 | P4: 0 | Q4: 1 | R4: 0 | S4: 0 | T4: 0 | U4: 0 | V4: 1 | W4: 1 | X4: 0 | Y4: 0
A5: 40298 | B5: 0 | C5: 1 | D5: 0 | E5: 0 | F5: 1 | G5: 0 | H5: 0 | I5: 1 | J5: 0 | K5: 0 | L5: 0 | M5: 0 | N5: 0 | O5: 0 | P5: 0 | Q5: 1 | R5: 0 | S5: 1 | T5: 0 | U5: 0 | V5: 0 | W5: 1 | X5: 0 | Y5: 0
A6: 40326 | B6: 0 | C6: 0 | D6: 0 | E6: 0 | F6: 0 | G6: 0 | H6: 0 | I6: 1 | J6: 0 | K6: 0 | L6: 0 | M6: 1 | N6: 0 | O6: 0 | P6: 0 | Q6: 0 | R6: 0 | S6: 1 | T6: 0 | U6: 0 | V6: 1 | W6: 1 | X6: 0 | Y6: 0
A7: 40359 | B7: 0 | C7: 1 | D7: 0 | E7: 0 | F7: 0 | G7: 0 | H7: 0 | I7: 1 | J7: 0 | K7: 0 | L7: 0 | M7: 1 | N7: 0 | O7: 0 | P7: 0 | Q7: 0 | R7: 0 | S7: 1 | T7: 0 | U7: 0 | V7: 1 | W7: 1 | X7: 0 | Y7: 0
A8: 40389 | B8: 0 | C8: 1 | D8: 1 | E8: 0 | F8: 0 | G8: 0 | H8: 0 | I8: 1 | J8: 0 | K8: 0 | L8: 0 | M8: 0 | N8: 0 | O8: 0 | P8: 0 | Q8: 0 | R8: 0 | S8: 1 | T8: 1 | U8: 0 | V8: 0 | W8: 1 | X8: 0 | Y8: 0
A9: 40421 | B9: 0 | C9: 1 | D9: 0 | E9: 0 | F9: 0 | G9: 0 | H9: 0 | I9: 1 | J9: 0 | K9: 0 | L9: 0 | M9: 0 | N9: 0 | O9: 0 | P9: 0 | Q9: 1 | R9: 0 | S9: 0 | T9: 0 | U9: 0 | V9: 1 | W9: 1 | X9: 0 | Y9: 0
A10: 40451 | B10: 0 | C10: 1 | D10: 0 | E10: 0 | F10: 0 | G10: 0 | H10: 0 | I10: 0 | J10: 0 | K10: 0 | L10: 0 | M10: 1 | N10: 0 | O10: 0 | P10: 0 | Q10: 0 | R10: 0 | S10: 1 | T10: 1 | U10: 0 | V10: 0 | W10: 1 | X10: 0 | Y10: 0
A11: 40480 | B11: 0 | C11: 1 | D11: 0 | E11: 0 | F11: 0 | G11: 0 | H11: 0 | I11: 1 | J11: 0 | K11: 0 | L11: 0 | M11: 0 | N11: 0 | O11: 0 | P11: 0 | Q11: 1 | R11: 0 | S11: 0 | T11: 1 | U11: 0 | V11: 0 | W11: 1 | X11: 0 | Y11: 0
A12: 40512 | B12: 0 | C12: 1 | D12: 0 | E12: 0 | F12: 0 | G12: 0 | H12: 0 | I12: 1 | J12: 1 | K12: 0 | L12: 0 | M12: 0 | N12: 0 | O12: 0 | P12: 0 | Q12: 0 | R12: 0 | S12: 1 | T12: 1 | U12: 0 | V12: 0 | W12: 1 | X12: 0 | Y12: 0
A13: 40543 | B13: 0 | C13: 1 | D13: 0 | E13: 0 | F13: 0 | G13: 0 | H13: 0 | I13: 1 | J13: 0 | K13: 0 | L13: 0 | M13: 1 | N13: 1 | O13: 0 | P13: 0 | Q13: 0 | R13: 0 | S13: 0 | T13: 0 | U13: 0 | V13: 1 | W13: 1 | X13: 0 | Y13: 0
A14: 40574 | B14: 0 | C14: 1 | D14: 0 | E14: 0 | F14: 0 | G14: 0 | H14: 0 | I14: 1 | J14: 0 | K14: 0 | L14: 0 | M14: 0 | N14: 0 | O14: 0 | P14: 0 | Q14: 1 | R14: 0 | S14: 1 | T14: 0 | U14: 0 | V14: 0 | W14: 1 | X14: 0 | Y14: 0
... A203: 46295 | B203: 1 | C203: 0 | D203: 0 | E203: 1 | F203: 0 | G203: 0 | H203: 0 | I203: 1 | J203: 0 | K203: 0 | L203: 0 | M203: 0 | N203: 0 | O203: 0 | P203: 0 | Q203: 0 | R203: 1 | S203: 0 | T203: 0 | U203: 0 | V203: 1 | W203: 1 | X203: 0 | Y203: 0

Sheet Config
B4: FACTSET Ids | C4: INDEX NAME | D4: Named Range | E4: Secto Name
B7: SP50 | C7: {=_xll.FDS(B7,"FG_COMPANY_NAME")} -> S&P 500 | D7: IND_Bench | F7: Nb of Const
B8: I00072 | C8: {=_xll.FDS(B8,"FG_COMPANY_NAME")} -> FTSE US / Basic Materials - IND | D8: IND_Mat | E8: Materials | F8: {=_xll.FDS(B8,"FTAW_NUMBER_IDX(0,0,D,""CLOSE"")")} -> 14
B9: I00144 | C9: {=_xll.FDS(B9,"FG_COMPANY_NAME")} -> FTSE US / Consumer Staples - IND | D9: IND_ConsGd | E9: ConsStaples | F9: {=_xll.FDS(B9,"FTAW_NUMBER_IDX(0,0,D,""CLOSE"")")} -> 26
B10: I01044 | C10: {=_xll.FDS(B10,"FG_COMPANY_NAME")} -> FTSE US / Retailers - SEC | D10: IND_Retail | E10: Retail | F10: {=_xll.FDS(B10,"FTAW_NUMBER_IDX(0,0,D,""CLOSE"")")} -> 20
B11: I00288 | C11: {=_xll.FDS(B11,"FG_COMPANY_NAME")} -> FTSE US / Financials - IND | D11: IND_Fin | E11: Fin | F11: {=_xll.FDS(B11,"FTAW_NUMBER_IDX(0,0,D,""CLOSE"")")} -> 68
B12: I21862 | C12: {=_xll.FDS(B12,"FG_COMPANY_NAME")} -> FTSE US / Health Care - IND | D12: IND_Health | E12: HealthCare | F12: {=_xll.FDS(B12,"FTAW_NUMBER_IDX(0,0,D,""CLOSE"")")} -> 48
B13: I00108 | C13: {=_xll.FDS(B13,"FG_COMPANY_NAME")} -> FTSE US / Industrials - IND | D13: IND_Indus | E13: Indus | F13: {=_xll.FDS(B13,"FTAW_NUMBER_IDX(0,0,D,""CLOSE"")")} -> 93
B14: I21852 | C14: {=_xll.FDS(B14,"FG_COMPANY_NAME")} -> FTSE US / Energy - IND | D14: IND_Oil | E14: Oil | F14: {=_xll.FDS(B14,"FTAW_NUMBER_IDX(0,0,D,""CLOSE"")")} -> 22
B15: I21904 | C15: {=_xll.FDS(B15,"FG_COMPANY_NAME")} -> FTSE US / Technology - IND | D15: IND_Tech | E15: Tech | F15: {=_xll.FDS(B15,"FTAW_NUMBER_IDX(0,0,D,""CLOSE"")")} -> 77
B16: I21881 | C16: {=_xll.FDS(B16,"FG_COMPANY_NAME")} -> FTSE US / Telecommunications - IND | D16: IND_Telco | E16: Telco | F16: {=_xll.FDS(B16,"FTAW_NUMBER_IDX(0,0,D,""CLOSE"")")} -> 12
B17: I00612 | C17: {=_xll.FDS(B17,"FG_COMPANY_NAME")} -> FTSE US / Utilities - IND | D17: IND_Utili | E17: Utili | F17: {=_xll.FDS(B17,"FTAW_NUMBER_IDX(0,0,D,""CLOSE"")")} -> 31
B18: I00936 | C18: {=_xll.FDS(B18,"FG_COMPANY_NAME")} -> FTSE US / Travel and Leisure - SEC | D18: IND_Travel | E18: Travel & leisure | F18: {=_xll.FDS(B18,"FTAW_NUMBER_IDX(0,0,D,""CLOSE"")")} -> 19
B19: I00972 | C19: {=_xll.FDS(B19,"FG_COMPANY_NAME")} -> FTSE US / Media - SEC | D19: IND_Media | E19: Media | F19: {=_xll.FDS(B19,"FTAW_NUMBER_IDX(0,0,D,""CLOSE"")")} -> 10

Sheet Returns_EQ
A1: StartDate: | B1: 36494 | D1: CUMRET TIME SERIES
A2: EndDate: | B2: =TODAY() -> 46321 | D2: EQUITY
B4: =IND_Bench -> SP50 | C4: =IND_Mat -> I00072 | D4: =IND_ConsGd -> I00144 | E4: =Ind_Retail -> I01044 | F4: =IND_Fin -> I00288 | G4: =IND_Health -> I21862 | H4: =IND_Indus -> I00108 | I4: =IND_Oil -> I21852 | J4: =IND_Tech -> I21904 | K4: =IND_Telco -> I21881 | L4: =IND_Utili -> I00612 | M4: =Ind_Travel -> I00936 | N4: =Ind_Media -> I00972
B5: WIUSAU Index | C5: {=_xll.FDS(C4,"FG_COMPANY_NAME")} -> FTSE US / Basic Materials - IND | D5: {=_xll.FDS(D4,"FG_COMPANY_NAME")} -> FTSE US / Consumer Staples - IND | E5: {=_xll.FDS(E4,"FG_COMPANY_NAME")} -> FTSE US / Retailers - SEC | F5: {=_xll.FDS(F4,"FG_COMPANY_NAME")} -> FTSE US / Financials - IND | G5: {=_xll.FDS(G4,"FG_COMPANY_NAME")} -> FTSE US / Health Care - IND | H5: {=_xll.FDS(H4,"FG_COMPANY_NAME")} -> FTSE US / Industrials - IND | I5: {=_xll.FDS(I4,"FG_COMPANY_NAME")} -> FTSE US / Energy - IND | J5: {=_xll.FDS(J4,"FG_COMPANY_NAME")} -> FTSE US / Technology - IND | ... N5: {=_xll.FDS(N4,"FG_COMPANY_NAME")} -> FTSE US / Media - SEC
B6: PX_LAST
A7: {=_xll.FDS(B4,"JULIAN(FG_TOTAL_RET_IDX(0,-20AY,M,USD).dates)")} -> 46295 | B7: {=_xll.BDH(B$5,B$6,$A7)} -> 3225.27 | C7: {=_xll.FDS(C4,"FG_TOTAL_RET_IDX(0,-20AY,M,USD)")} -> 3558.324 | D7: {=_xll.FDS(D4,"FG_TOTAL_RET_IDX(0,-20AY,M,USD)")} -> 5474.6365 | E7: {=_xll.FDS(E4,"FG_TOTAL_RET_IDX(0,-20AY,M,USD)")} -> 14229.157 | F7: {=_xll.FDS(F4,"FG_TOTAL_RET_IDX(0,-20AY,M,USD)")} -> 4570.9913 | G7: {=_xll.FDS(G4,"FG_TOTAL_RET_IDX(0,-20AY,M,USD)")} -> 8436.0269 | H7: {=_xll.FDS(H4,"FG_TOTAL_RET_IDX(0,-20AY,M,USD)")} -> 6895.6731 | I7: {=_xll.FDS(I4,"FG_TOTAL_RET_IDX(0,-20AY,M,USD)")} -> 5015.2666 | J7: {=_xll.FDS(J4,"FG_TOTAL_RET_IDX(0,-20AY,M,USD)")} -> 14299.439 | ... N7: {=_xll.FDS(N4,"FG_TOTAL_RET_IDX(0,-20AY,M,USD)")} -> 2946.7882
A8: 46265 | B8: {=_xll.BDH(B$5,B$6,$A8)} -> 3239.61 | C8: 3762.9848 | D8: 5684.2984 | E8: 14877.193 | F8: 4937.4159 | G8: 8492.9486 | H8: 7246.6364 | I8: 5167.1909 | J8: 13589.282 | K8: 1970.7942 | L8: 4646.6035 | M8: 5400.4193 | N8: 3210.2215
A9: 46234 | B9: {=_xll.BDH(B$5,B$6,$A9)} -> 3152.52 | C9: 3471.3642 | D9: 5690.6344 | E9: 15453.72 | F9: 4883.2421 | G9: 8083.0739 | H9: 7355.5349 | I9: 4830.8882 | J9: 12967.483 | K9: 1877.7157 | L9: 4863.5017 | M9: 5452.2449 | N9: 2891.0719
A10: 46203 | B10: {=_xll.BDH(B$5,B$6,$A10)} -> 3156.52 | C10: 3481.7116 | D10: 5536.4082 | E10: 14387.51 | F10: 4617.6405 | G10: 7930.3409 | H10: 7350.7074 | I10: 4303.2845 | J10: 13364.297 | K10: 1872.4865 | L10: 4961.5906 | M10: 5342.3585 | N10: 2839.7096
A11: 46171 | B11: {=_xll.BDH(B$5,B$6,$A11)} -> 3187.85 | C11: 3522.3061 | D11: 5382.1341 | E11: 15354.887 | F11: 4421.5689 | G11: 7453.811 | H11: 6978.0371 | I11: 4531.4938 | J11: 13852.972 | K11: 1989.346 | L11: 4819.3727 | M11: 5153.8873 | N11: 3178.6035
A12: 46142 | B12: {=_xll.BDH(B$5,B$6,$A12)} -> 3027.81 | C12: 3457.2837 | D12: 5413.206 | E12: 15667.723 | F12: 4472.3023 | G12: 7253.1549 | H12: 7016.5757 | I12: 4785.7397 | J12: 12257.178 | K12: 1875.229 | L12: 5093.2443 | M12: 5224.7371 | N12: 3294.4772
A13: 46112 | B13: {=_xll.BDH(B$5,B$6,$A13)} -> 2742.79 | C13: 3374.8673 | D13: 5277.8575 | E13: 13642.816 | F13: 4249.3372 | G13: 7312.5039 | H13: 6538.6756 | I13: 4955.075 | J13: 10281.511 | K13: 1743.9377 | L13: 5000.9301 | M13: 5072.0153 | N13: 3296.7314
A14: 46080 | B14: {=_xll.BDH(B$5,B$6,$A14)} -> 2888.81 | C14: 3597.4535 | D14: 5841.2879 | E14: 14082.455 | F14: 4394.745 | G14: 7919.2561 | H14: 7102.7584 | I14: 4487.9213 | J14: 10804.749 | K14: 1791.7456 | L14: 5167.3238 | M14: 5441.16 | N14: 3406.7778
A15: 46052 | B15: {=_xll.BDH(B$5,B$6,$A15)} -> 2918.3 | C15: 3257.2615 | D15: 5370.1272 | E15: 14713.59 | F15: 4566.1287 | G15: 7685.0313 | H15: 6814.8819 | I15: 4109.6829 | J15: 11379.16 | K15: 1695.6762 | L15: 4694.3859 | M15: 5421.5162 | N15: 3247.1842
A16: 46022 | B16: {=_xll.BDH(B$5,B$6,$A16)} -> 2885.85 | C16: 2951.9598 | D16: 5035.4039 | E16: 14019.222 | F16: 4617.2261 | G16: 7706.5299 | H16: 6609.9184 | I16: 3608.4136 | J16: 11401.287 | K16: 1613.5747 | L16: 4633.4286 | M16: 5382.848 | N16: 3520.7021
A17: 45989 | B17: {=_xll.BDH(B$5,B$6,$A17)} -> 2889.9 | C17: 2850.7925 | D17: 5158.742 | E17: 14203.757 | F17: 4487.3493 | G17: 7808.6314 | H17: 6479.8317 | I17: 3609.423 | J17: 11461.272 | K17: 1609.0313 | L17: 4865.6454 | M17: 5189.6749 | N17: 3626.8337
A18: 45961 | B18: {=_xll.BDH(B$5,B$6,$A18)} -> 2891.33 | C18: 2753.8575 | D18: 4950.7425 | E18: 14362.542 | F18: 4368.8437 | G18: 7153.6004 | H18: 6511.6907 | I18: 3527.5518 | J18: 11728.024 | K18: 1627.2263 | L18: 4761.4598 | M18: 5050.5235 | N18: 3810.4342
A19: 45930 | B19: {=_xll.BDH(B$5,B$6,$A19)} -> 2827.68 | C19: 2935.7704 | D19: 5064.755 | E19: 13839.359 | F19: 4510.4196 | G19: 6917.045 | H19: 6489.8481 | I19: 3565.3071 | J19: 11049.855 | K19: 1689.3799 | L19: 4710.8779 | M19: 5285.1045 | N19: 3976.6448
... A246: 39021 | B246: {=_xll.BDH(B$5,B$6,$A246)} -> 571.29 | C246: 669.21 | D246: 893.92 | E246: 1138.21 | F246: 1342.54 | G246: 1127.66 | H246: 1005.84 | I246: 1353.33 | J246: 556.44 | K246: 649.09 | L246: 966.14 | M246: 766.03 | N246: 665.54

Sheet Leverage_FMA
A1: Time frame | AD1: Net Debt to EBITDA
A2: 60 | AD2: FMA_NDEBT_EBITDA
AD3: Historical Ratio
